Traceback (most recent call last):
  File "<stdin>", line 2, in <module>
NameError: name 'Raise' is not defined

~~~~~~~~~~~~~~~ 2022/06/25 09:41:28 ~~~~~~~~~~~~~~~
Traceback (most recent call last):
  File "c:\Users\admin\PycharmProjects\pyscrape\tagalog-pinoydictionary-scrape.py", line 94, in <module>
    getContent(bs)
  File "c:\Users\admin\PycharmProjects\pyscrape\tagalog-pinoydictionary-scrape.py", line 49, in getContent
    conjugationsRaw = conjRegex.search(definition.get_text()).group(1)
AttributeError: 'str' object has no attribute 'get_text'

~~~~~~~~~~~~~~~ 2022/06/25 09:41:29 ~~~~~~~~~~~~~~~
Traceback (most recent call last):
  File "c:\Users\admin\PycharmProjects\pyscrape\tagalog-pinoydictionary-scrape.py", line 94, in <module>
    getContent(bs)
  File "c:\Users\admin\PycharmProjects\pyscrape\tagalog-pinoydictionary-scrape.py", line 49, in getContent
    conjugationsRaw = conjRegex.search(definition.get_text()).group(1)
AttributeError: 'str' object has no attribute 'get_text'

~~~~~~~~~~~~~~~ 2022/06/25 09:41:30 ~~~~~~~~~~~~~~~
Traceback (most recent call last):
  File "c:\Users\admin\PycharmProjects\pyscrape\tagalog-pinoydictionary-scrape.py", line 94, in <module>
    getContent(bs)
  File "c:\Users\admin\PycharmProjects\pyscrape\tagalog-pinoydictionary-scrape.py", line 49, in getContent
    conjugationsRaw = conjRegex.search(definition.get_text()).group(1)
AttributeError: 'str' object has no attribute 'get_text'

~~~~~~~~~~~~~~~ 2022/06/25 09:41:32 ~~~~~~~~~~~~~~~
Traceback (most recent call last):
  File "c:\Users\admin\PycharmProjects\pyscrape\tagalog-pinoydictionary-scrape.py", line 94, in <module>
    getContent(bs)
  File "c:\Users\admin\PycharmProjects\pyscrape\tagalog-pinoydictionary-scrape.py", line 49, in getContent
    conjugationsRaw = conjRegex.search(definition.get_text()).group(1)
AttributeError: 'str' object has no attribute 'get_text'

~~~~~~~~~~~~~~~ 2022/06/25 09:41:33 ~~~~~~~~~~~~~~~
Traceback (most recent call last):
  File "c:\Users\admin\PycharmProjects\pyscrape\tagalog-pinoydictionary-scrape.py", line 94, in <module>
    getContent(bs)
  File "c:\Users\admin\PycharmProjects\pyscrape\tagalog-pinoydictionary-scrape.py", line 49, in getContent
    conjugationsRaw = conjRegex.search(definition.get_text()).group(1)
AttributeError: 'str' object has no attribute 'get_text'

~~~~~~~~~~~~~~~ 2022/06/25 09:41:33 ~~~~~~~~~~~~~~~
Traceback (most recent call last):
  File "c:\Users\admin\PycharmProjects\pyscrape\tagalog-pinoydictionary-scrape.py", line 93, in <module>
    bs = getPage(url)
  File "c:\Users\admin\PycharmProjects\pyscrape\tagalog-pinoydictionary-scrape.py", line 22, in getPage
    req = requests.get(url)
  File "c:\Users\admin\PycharmProjects\pyscrape\venv\lib\site-packages\requests\api.py", line 73, in get
    return request("get", url, params=params, **kwargs)
  File "c:\Users\admin\PycharmProjects\pyscrape\venv\lib\site-packages\requests\api.py", line 59, in request
    return session.request(method=method, url=url, **kwargs)
  File "c:\Users\admin\PycharmProjects\pyscrape\venv\lib\site-packages\requests\sessions.py", line 587, in request
    resp = self.send(prep, **send_kwargs)
  File "c:\Users\admin\PycharmProjects\pyscrape\venv\lib\site-packages\requests\sessions.py", line 701, in send
    r = adapter.send(request, **kwargs)
  File "c:\Users\admin\PycharmProjects\pyscrape\venv\lib\site-packages\requests\adapters.py", line 489, in send
    resp = conn.urlopen(
  File "c:\Users\admin\PycharmProjects\pyscrape\venv\lib\site-packages\urllib3\connectionpool.py", line 703, in urlopen
    httplib_response = self._make_request(
  File "c:\Users\admin\PycharmProjects\pyscrape\venv\lib\site-packages\urllib3\connectionpool.py", line 449, in _make_request
    six.raise_from(e, None)
  File "<string>", line 3, in raise_from
  File "c:\Users\admin\PycharmProjects\pyscrape\venv\lib\site-packages\urllib3\connectionpool.py", line 444, in _make_request
    httplib_response = conn.getresponse()
  File "C:\Users\admin\AppData\Local\Programs\Python\Python39\lib\http\client.py", line 1347, in getresponse
    response.begin()
  File "C:\Users\admin\AppData\Local\Programs\Python\Python39\lib\http\client.py", line 307, in begin
    version, status, reason = self._read_status()
  File "C:\Users\admin\AppData\Local\Programs\Python\Python39\lib\http\client.py", line 268, in _read_status
    line = str(self.fp.readline(_MAXLINE + 1), "iso-8859-1")
  File "C:\Users\admin\AppData\Local\Programs\Python\Python39\lib\socket.py", line 704, in readinto
    return self._sock.recv_into(b)
  File "C:\Users\admin\AppData\Local\Programs\Python\Python39\lib\ssl.py", line 1241, in recv_into
    return self.read(nbytes, buffer)
  File "C:\Users\admin\AppData\Local\Programs\Python\Python39\lib\ssl.py", line 1099, in read
    return self._sslobj.read(len, buffer)
KeyboardInterrupt

~~~~~~~~~~~~~~~ 2022/06/25 09:41:35 ~~~~~~~~~~~~~~~
Traceback (most recent call last):
  File "c:\Users\admin\PycharmProjects\pyscrape\tagalog-pinoydictionary-scrape.py", line 94, in <module>
    getContent(bs)
  File "c:\Users\admin\PycharmProjects\pyscrape\tagalog-pinoydictionary-scrape.py", line 49, in getContent
    conjugationsRaw = conjRegex.search(definition.get_text()).group(1)
AttributeError: 'str' object has no attribute 'get_text'

~~~~~~~~~~~~~~~ 2022/06/25 09:41:36 ~~~~~~~~~~~~~~~
Traceback (most recent call last):
  File "c:\Users\admin\PycharmProjects\pyscrape\tagalog-pinoydictionary-scrape.py", line 94, in <module>
    getContent(bs)
  File "c:\Users\admin\PycharmProjects\pyscrape\tagalog-pinoydictionary-scrape.py", line 49, in getContent
    conjugationsRaw = conjRegex.search(definition.get_text()).group(1)
AttributeError: 'str' object has no attribute 'get_text'

~~~~~~~~~~~~~~~ 2022/06/25 09:41:37 ~~~~~~~~~~~~~~~
Traceback (most recent call last):
  File "c:\Users\admin\PycharmProjects\pyscrape\tagalog-pinoydictionary-scrape.py", line 94, in <module>
    getContent(bs)
  File "c:\Users\admin\PycharmProjects\pyscrape\tagalog-pinoydictionary-scrape.py", line 49, in getContent
    conjugationsRaw = conjRegex.search(definition.get_text()).group(1)
AttributeError: 'str' object has no attribute 'get_text'

~~~~~~~~~~~~~~~ 2022/06/25 09:41:38 ~~~~~~~~~~~~~~~
Traceback (most recent call last):
  File "c:\Users\admin\PycharmProjects\pyscrape\tagalog-pinoydictionary-scrape.py", line 94, in <module>
    getContent(bs)
  File "c:\Users\admin\PycharmProjects\pyscrape\tagalog-pinoydictionary-scrape.py", line 49, in getContent
    conjugationsRaw = conjRegex.search(definition.get_text()).group(1)
AttributeError: 'str' object has no attribute 'get_text'

~~~~~~~~~~~~~~~ 2022/06/25 09:41:38 ~~~~~~~~~~~~~~~
Traceback (most recent call last):
  File "c:\Users\admin\PycharmProjects\pyscrape\tagalog-pinoydictionary-scrape.py", line 94, in <module>
    getContent(bs)
  File "c:\Users\admin\PycharmProjects\pyscrape\tagalog-pinoydictionary-scrape.py", line 49, in getContent
    conjugationsRaw = conjRegex.search(definition.get_text()).group(1)
AttributeError: 'str' object has no attribute 'get_text'

~~~~~~~~~~~~~~~ 2022/06/25 09:41:39 ~~~~~~~~~~~~~~~
Traceback (most recent call last):
  File "c:\Users\admin\PycharmProjects\pyscrape\tagalog-pinoydictionary-scrape.py", line 94, in <module>
    getContent(bs)
  File "c:\Users\admin\PycharmProjects\pyscrape\tagalog-pinoydictionary-scrape.py", line 49, in getContent
    conjugationsRaw = conjRegex.search(definition.get_text()).group(1)
AttributeError: 'str' object has no attribute 'get_text'

~~~~~~~~~~~~~~~ 2022/06/25 09:41:40 ~~~~~~~~~~~~~~~
Traceback (most recent call last):
  File "c:\Users\admin\PycharmProjects\pyscrape\tagalog-pinoydictionary-scrape.py", line 94, in <module>
    getContent(bs)
  File "c:\Users\admin\PycharmProjects\pyscrape\tagalog-pinoydictionary-scrape.py", line 49, in getContent
    conjugationsRaw = conjRegex.search(definition.get_text()).group(1)
AttributeError: 'str' object has no attribute 'get_text'

~~~~~~~~~~~~~~~ 2022/06/25 09:41:41 ~~~~~~~~~~~~~~~
Traceback (most recent call last):
  File "c:\Users\admin\PycharmProjects\pyscrape\tagalog-pinoydictionary-scrape.py", line 94, in <module>
    getContent(bs)
  File "c:\Users\admin\PycharmProjects\pyscrape\tagalog-pinoydictionary-scrape.py", line 49, in getContent
    conjugationsRaw = conjRegex.search(definition.get_text()).group(1)
AttributeError: 'str' object has no attribute 'get_text'

~~~~~~~~~~~~~~~ 2022/06/25 09:41:42 ~~~~~~~~~~~~~~~
Traceback (most recent call last):
  File "c:\Users\admin\PycharmProjects\pyscrape\tagalog-pinoydictionary-scrape.py", line 94, in <module>
    getContent(bs)
  File "c:\Users\admin\PycharmProjects\pyscrape\tagalog-pinoydictionary-scrape.py", line 49, in getContent
    conjugationsRaw = conjRegex.search(definition.get_text()).group(1)
AttributeError: 'str' object has no attribute 'get_text'

~~~~~~~~~~~~~~~ 2022/06/25 09:41:42 ~~~~~~~~~~~~~~~
Traceback (most recent call last):
  File "c:\Users\admin\PycharmProjects\pyscrape\tagalog-pinoydictionary-scrape.py", line 94, in <module>
    getContent(bs)
  File "c:\Users\admin\PycharmProjects\pyscrape\tagalog-pinoydictionary-scrape.py", line 49, in getContent
    conjugationsRaw = conjRegex.search(definition.get_text()).group(1)
AttributeError: 'str' object has no attribute 'get_text'

~~~~~~~~~~~~~~~ 2022/06/25 09:41:43 ~~~~~~~~~~~~~~~
Traceback (most recent call last):
  File "c:\Users\admin\PycharmProjects\pyscrape\tagalog-pinoydictionary-scrape.py", line 94, in <module>
    getContent(bs)
  File "c:\Users\admin\PycharmProjects\pyscrape\tagalog-pinoydictionary-scrape.py", line 49, in getContent
    conjugationsRaw = conjRegex.search(definition.get_text()).group(1)
AttributeError: 'str' object has no attribute 'get_text'

~~~~~~~~~~~~~~~ 2022/06/25 09:41:44 ~~~~~~~~~~~~~~~
Traceback (most recent call last):
  File "c:\Users\admin\PycharmProjects\pyscrape\tagalog-pinoydictionary-scrape.py", line 94, in <module>
    getContent(bs)
  File "c:\Users\admin\PycharmProjects\pyscrape\tagalog-pinoydictionary-scrape.py", line 49, in getContent
    conjugationsRaw = conjRegex.search(definition.get_text()).group(1)
AttributeError: 'str' object has no attribute 'get_text'

~~~~~~~~~~~~~~~ 2022/06/25 09:41:45 ~~~~~~~~~~~~~~~
Traceback (most recent call last):
  File "c:\Users\admin\PycharmProjects\pyscrape\tagalog-pinoydictionary-scrape.py", line 94, in <module>
    getContent(bs)
  File "c:\Users\admin\PycharmProjects\pyscrape\tagalog-pinoydictionary-scrape.py", line 49, in getContent
    conjugationsRaw = conjRegex.search(definition.get_text()).group(1)
AttributeError: 'str' object has no attribute 'get_text'

~~~~~~~~~~~~~~~ 2022/06/25 09:41:46 ~~~~~~~~~~~~~~~
Traceback (most recent call last):
  File "c:\Users\admin\PycharmProjects\pyscrape\tagalog-pinoydictionary-scrape.py", line 94, in <module>
    getContent(bs)
  File "c:\Users\admin\PycharmProjects\pyscrape\tagalog-pinoydictionary-scrape.py", line 49, in getContent
    conjugationsRaw = conjRegex.search(definition.get_text()).group(1)
AttributeError: 'str' object has no attribute 'get_text'

~~~~~~~~~~~~~~~ 2022/06/25 09:41:47 ~~~~~~~~~~~~~~~
Traceback (most recent call last):
  File "c:\Users\admin\PycharmProjects\pyscrape\tagalog-pinoydictionary-scrape.py", line 94, in <module>
    getContent(bs)
  File "c:\Users\admin\PycharmProjects\pyscrape\tagalog-pinoydictionary-scrape.py", line 49, in getContent
    conjugationsRaw = conjRegex.search(definition.get_text()).group(1)
AttributeError: 'str' object has no attribute 'get_text'

~~~~~~~~~~~~~~~ 2022/06/25 09:41:47 ~~~~~~~~~~~~~~~
Traceback (most recent call last):
  File "c:\Users\admin\PycharmProjects\pyscrape\tagalog-pinoydictionary-scrape.py", line 94, in <module>
    getContent(bs)
  File "c:\Users\admin\PycharmProjects\pyscrape\tagalog-pinoydictionary-scrape.py", line 49, in getContent
    conjugationsRaw = conjRegex.search(definition.get_text()).group(1)
AttributeError: 'str' object has no attribute 'get_text'

~~~~~~~~~~~~~~~ 2022/06/25 09:41:49 ~~~~~~~~~~~~~~~
Traceback (most recent call last):
  File "c:\Users\admin\PycharmProjects\pyscrape\tagalog-pinoydictionary-scrape.py", line 94, in <module>
    getContent(bs)
  File "c:\Users\admin\PycharmProjects\pyscrape\tagalog-pinoydictionary-scrape.py", line 49, in getContent
    conjugationsRaw = conjRegex.search(definition.get_text()).group(1)
AttributeError: 'str' object has no attribute 'get_text'

~~~~~~~~~~~~~~~ 2022/06/25 09:42:00 ~~~~~~~~~~~~~~~
Traceback (most recent call last):
  File "c:\Users\admin\PycharmProjects\pyscrape\tagalog-pinoydictionary-scrape.py", line 94, in <module>
    getContent(bs)
  File "c:\Users\admin\PycharmProjects\pyscrape\tagalog-pinoydictionary-scrape.py", line 49, in getContent
    conjugationsRaw = conjRegex.search(definition).group(1)
AttributeError: 'NoneType' object has no attribute 'group'

~~~~~~~~~~~~~~~ 2022/06/25 09:42:01 ~~~~~~~~~~~~~~~
Traceback (most recent call last):
  File "c:\Users\admin\PycharmProjects\pyscrape\tagalog-pinoydictionary-scrape.py", line 94, in <module>
    getContent(bs)
  File "c:\Users\admin\PycharmProjects\pyscrape\tagalog-pinoydictionary-scrape.py", line 49, in getContent
    conjugationsRaw = conjRegex.search(definition).group(1)
AttributeError: 'NoneType' object has no attribute 'group'

~~~~~~~~~~~~~~~ 2022/06/25 09:42:02 ~~~~~~~~~~~~~~~
Traceback (most recent call last):
  File "c:\Users\admin\PycharmProjects\pyscrape\tagalog-pinoydictionary-scrape.py", line 94, in <module>
    getContent(bs)
  File "c:\Users\admin\PycharmProjects\pyscrape\tagalog-pinoydictionary-scrape.py", line 49, in getContent
    conjugationsRaw = conjRegex.search(definition).group(1)
AttributeError: 'NoneType' object has no attribute 'group'

~~~~~~~~~~~~~~~ 2022/06/25 09:42:03 ~~~~~~~~~~~~~~~
Traceback (most recent call last):
  File "c:\Users\admin\PycharmProjects\pyscrape\tagalog-pinoydictionary-scrape.py", line 94, in <module>
    getContent(bs)
  File "c:\Users\admin\PycharmProjects\pyscrape\tagalog-pinoydictionary-scrape.py", line 49, in getContent
    conjugationsRaw = conjRegex.search(definition).group(1)
AttributeError: 'NoneType' object has no attribute 'group'

~~~~~~~~~~~~~~~ 2022/06/25 09:42:03 ~~~~~~~~~~~~~~~
Traceback (most recent call last):
  File "c:\Users\admin\PycharmProjects\pyscrape\tagalog-pinoydictionary-scrape.py", line 93, in <module>
    bs = getPage(url)
  File "c:\Users\admin\PycharmProjects\pyscrape\tagalog-pinoydictionary-scrape.py", line 22, in getPage
    req = requests.get(url)
  File "c:\Users\admin\PycharmProjects\pyscrape\venv\lib\site-packages\requests\api.py", line 73, in get
    return request("get", url, params=params, **kwargs)
  File "c:\Users\admin\PycharmProjects\pyscrape\venv\lib\site-packages\requests\api.py", line 59, in request
    return session.request(method=method, url=url, **kwargs)
  File "c:\Users\admin\PycharmProjects\pyscrape\venv\lib\site-packages\requests\sessions.py", line 587, in request
    resp = self.send(prep, **send_kwargs)
  File "c:\Users\admin\PycharmProjects\pyscrape\venv\lib\site-packages\requests\sessions.py", line 701, in send
    r = adapter.send(request, **kwargs)
  File "c:\Users\admin\PycharmProjects\pyscrape\venv\lib\site-packages\requests\adapters.py", line 489, in send
    resp = conn.urlopen(
  File "c:\Users\admin\PycharmProjects\pyscrape\venv\lib\site-packages\urllib3\connectionpool.py", line 703, in urlopen
    httplib_response = self._make_request(
  File "c:\Users\admin\PycharmProjects\pyscrape\venv\lib\site-packages\urllib3\connectionpool.py", line 386, in _make_request
    self._validate_conn(conn)
  File "c:\Users\admin\PycharmProjects\pyscrape\venv\lib\site-packages\urllib3\connectionpool.py", line 1040, in _validate_conn
    conn.connect()
  File "c:\Users\admin\PycharmProjects\pyscrape\venv\lib\site-packages\urllib3\connection.py", line 414, in connect
    self.sock = ssl_wrap_socket(
  File "c:\Users\admin\PycharmProjects\pyscrape\venv\lib\site-packages\urllib3\util\ssl_.py", line 402, in ssl_wrap_socket
    context.load_verify_locations(ca_certs, ca_cert_dir, ca_cert_data)
KeyboardInterrupt

~~~~~~~~~~~~~~~ 2022/06/25 09:42:04 ~~~~~~~~~~~~~~~
Traceback (most recent call last):
  File "c:\Users\admin\PycharmProjects\pyscrape\tagalog-pinoydictionary-scrape.py", line 94, in <module>
    getContent(bs)
  File "c:\Users\admin\PycharmProjects\pyscrape\tagalog-pinoydictionary-scrape.py", line 49, in getContent
    conjugationsRaw = conjRegex.search(definition).group(1)
AttributeError: 'NoneType' object has no attribute 'group'

~~~~~~~~~~~~~~~ 2022/06/25 09:42:05 ~~~~~~~~~~~~~~~
Traceback (most recent call last):
  File "c:\Users\admin\PycharmProjects\pyscrape\tagalog-pinoydictionary-scrape.py", line 94, in <module>
    getContent(bs)
  File "c:\Users\admin\PycharmProjects\pyscrape\tagalog-pinoydictionary-scrape.py", line 49, in getContent
    conjugationsRaw = conjRegex.search(definition).group(1)
AttributeError: 'NoneType' object has no attribute 'group'

~~~~~~~~~~~~~~~ 2022/06/25 09:42:06 ~~~~~~~~~~~~~~~
Traceback (most recent call last):
  File "c:\Users\admin\PycharmProjects\pyscrape\tagalog-pinoydictionary-scrape.py", line 94, in <module>
    getContent(bs)
  File "c:\Users\admin\PycharmProjects\pyscrape\tagalog-pinoydictionary-scrape.py", line 49, in getContent
    conjugationsRaw = conjRegex.search(definition).group(1)
AttributeError: 'NoneType' object has no attribute 'group'

~~~~~~~~~~~~~~~ 2022/06/25 09:42:07 ~~~~~~~~~~~~~~~
Traceback (most recent call last):
  File "c:\Users\admin\PycharmProjects\pyscrape\tagalog-pinoydictionary-scrape.py", line 93, in <module>
    bs = getPage(url)
  File "c:\Users\admin\PycharmProjects\pyscrape\tagalog-pinoydictionary-scrape.py", line 22, in getPage
    req = requests.get(url)
  File "c:\Users\admin\PycharmProjects\pyscrape\venv\lib\site-packages\requests\api.py", line 73, in get
    return request("get", url, params=params, **kwargs)
  File "c:\Users\admin\PycharmProjects\pyscrape\venv\lib\site-packages\requests\api.py", line 59, in request
    return session.request(method=method, url=url, **kwargs)
  File "c:\Users\admin\PycharmProjects\pyscrape\venv\lib\site-packages\requests\sessions.py", line 587, in request
    resp = self.send(prep, **send_kwargs)
  File "c:\Users\admin\PycharmProjects\pyscrape\venv\lib\site-packages\requests\sessions.py", line 701, in send
    r = adapter.send(request, **kwargs)
  File "c:\Users\admin\PycharmProjects\pyscrape\venv\lib\site-packages\requests\adapters.py", line 489, in send
    resp = conn.urlopen(
  File "c:\Users\admin\PycharmProjects\pyscrape\venv\lib\site-packages\urllib3\connectionpool.py", line 703, in urlopen
    httplib_response = self._make_request(
  File "c:\Users\admin\PycharmProjects\pyscrape\venv\lib\site-packages\urllib3\connectionpool.py", line 449, in _make_request
    six.raise_from(e, None)
  File "<string>", line 3, in raise_from
  File "c:\Users\admin\PycharmProjects\pyscrape\venv\lib\site-packages\urllib3\connectionpool.py", line 444, in _make_request
    httplib_response = conn.getresponse()
  File "C:\Users\admin\AppData\Local\Programs\Python\Python39\lib\http\client.py", line 1347, in getresponse
    response.begin()
  File "C:\Users\admin\AppData\Local\Programs\Python\Python39\lib\http\client.py", line 307, in begin
    version, status, reason = self._read_status()
  File "C:\Users\admin\AppData\Local\Programs\Python\Python39\lib\http\client.py", line 268, in _read_status
    line = str(self.fp.readline(_MAXLINE + 1), "iso-8859-1")
  File "C:\Users\admin\AppData\Local\Programs\Python\Python39\lib\socket.py", line 704, in readinto
    return self._sock.recv_into(b)
  File "C:\Users\admin\AppData\Local\Programs\Python\Python39\lib\ssl.py", line 1241, in recv_into
    return self.read(nbytes, buffer)
  File "C:\Users\admin\AppData\Local\Programs\Python\Python39\lib\ssl.py", line 1099, in read
    return self._sslobj.read(len, buffer)
KeyboardInterrupt

~~~~~~~~~~~~~~~ 2022/06/25 09:42:08 ~~~~~~~~~~~~~~~
Traceback (most recent call last):
  File "c:\Users\admin\PycharmProjects\pyscrape\tagalog-pinoydictionary-scrape.py", line 94, in <module>
    getContent(bs)
  File "c:\Users\admin\PycharmProjects\pyscrape\tagalog-pinoydictionary-scrape.py", line 49, in getContent
    conjugationsRaw = conjRegex.search(definition).group(1)
AttributeError: 'NoneType' object has no attribute 'group'

~~~~~~~~~~~~~~~ 2022/06/25 09:42:09 ~~~~~~~~~~~~~~~
Traceback (most recent call last):
  File "c:\Users\admin\PycharmProjects\pyscrape\tagalog-pinoydictionary-scrape.py", line 94, in <module>
    getContent(bs)
  File "c:\Users\admin\PycharmProjects\pyscrape\tagalog-pinoydictionary-scrape.py", line 49, in getContent
    conjugationsRaw = conjRegex.search(definition).group(1)
AttributeError: 'NoneType' object has no attribute 'group'

~~~~~~~~~~~~~~~ 2022/06/25 09:42:09 ~~~~~~~~~~~~~~~
Traceback (most recent call last):
  File "c:\Users\admin\PycharmProjects\pyscrape\tagalog-pinoydictionary-scrape.py", line 94, in <module>
    getContent(bs)
  File "c:\Users\admin\PycharmProjects\pyscrape\tagalog-pinoydictionary-scrape.py", line 49, in getContent
    conjugationsRaw = conjRegex.search(definition).group(1)
AttributeError: 'NoneType' object has no attribute 'group'

~~~~~~~~~~~~~~~ 2022/06/25 09:42:10 ~~~~~~~~~~~~~~~
Traceback (most recent call last):
  File "c:\Users\admin\PycharmProjects\pyscrape\tagalog-pinoydictionary-scrape.py", line 93, in <module>
    bs = getPage(url)
  File "c:\Users\admin\PycharmProjects\pyscrape\tagalog-pinoydictionary-scrape.py", line 22, in getPage
    req = requests.get(url)
  File "c:\Users\admin\PycharmProjects\pyscrape\venv\lib\site-packages\requests\api.py", line 73, in get
    return request("get", url, params=params, **kwargs)
  File "c:\Users\admin\PycharmProjects\pyscrape\venv\lib\site-packages\requests\api.py", line 59, in request
    return session.request(method=method, url=url, **kwargs)
  File "c:\Users\admin\PycharmProjects\pyscrape\venv\lib\site-packages\requests\sessions.py", line 587, in request
    resp = self.send(prep, **send_kwargs)
  File "c:\Users\admin\PycharmProjects\pyscrape\venv\lib\site-packages\requests\sessions.py", line 701, in send
    r = adapter.send(request, **kwargs)
  File "c:\Users\admin\PycharmProjects\pyscrape\venv\lib\site-packages\requests\adapters.py", line 489, in send
    resp = conn.urlopen(
  File "c:\Users\admin\PycharmProjects\pyscrape\venv\lib\site-packages\urllib3\connectionpool.py", line 703, in urlopen
    httplib_response = self._make_request(
  File "c:\Users\admin\PycharmProjects\pyscrape\venv\lib\site-packages\urllib3\connectionpool.py", line 449, in _make_request
    six.raise_from(e, None)
  File "<string>", line 3, in raise_from
  File "c:\Users\admin\PycharmProjects\pyscrape\venv\lib\site-packages\urllib3\connectionpool.py", line 444, in _make_request
    httplib_response = conn.getresponse()
  File "C:\Users\admin\AppData\Local\Programs\Python\Python39\lib\http\client.py", line 1347, in getresponse
    response.begin()
  File "C:\Users\admin\AppData\Local\Programs\Python\Python39\lib\http\client.py", line 307, in begin
    version, status, reason = self._read_status()
  File "C:\Users\admin\AppData\Local\Programs\Python\Python39\lib\http\client.py", line 268, in _read_status
    line = str(self.fp.readline(_MAXLINE + 1), "iso-8859-1")
  File "C:\Users\admin\AppData\Local\Programs\Python\Python39\lib\socket.py", line 704, in readinto
    return self._sock.recv_into(b)
  File "C:\Users\admin\AppData\Local\Programs\Python\Python39\lib\ssl.py", line 1241, in recv_into
    return self.read(nbytes, buffer)
  File "C:\Users\admin\AppData\Local\Programs\Python\Python39\lib\ssl.py", line 1099, in read
    return self._sslobj.read(len, buffer)
KeyboardInterrupt

~~~~~~~~~~~~~~~ 2022/06/25 09:42:11 ~~~~~~~~~~~~~~~
Traceback (most recent call last):
  File "c:\Users\admin\PycharmProjects\pyscrape\tagalog-pinoydictionary-scrape.py", line 94, in <module>
    getContent(bs)
  File "c:\Users\admin\PycharmProjects\pyscrape\tagalog-pinoydictionary-scrape.py", line 49, in getContent
    conjugationsRaw = conjRegex.search(definition).group(1)
AttributeError: 'NoneType' object has no attribute 'group'

~~~~~~~~~~~~~~~ 2022/06/25 09:42:12 ~~~~~~~~~~~~~~~
Traceback (most recent call last):
  File "c:\Users\admin\PycharmProjects\pyscrape\tagalog-pinoydictionary-scrape.py", line 93, in <module>
    bs = getPage(url)
  File "c:\Users\admin\PycharmProjects\pyscrape\tagalog-pinoydictionary-scrape.py", line 22, in getPage
    req = requests.get(url)
  File "c:\Users\admin\PycharmProjects\pyscrape\venv\lib\site-packages\requests\api.py", line 73, in get
    return request("get", url, params=params, **kwargs)
  File "c:\Users\admin\PycharmProjects\pyscrape\venv\lib\site-packages\requests\api.py", line 59, in request
    return session.request(method=method, url=url, **kwargs)
  File "c:\Users\admin\PycharmProjects\pyscrape\venv\lib\site-packages\requests\sessions.py", line 587, in request
    resp = self.send(prep, **send_kwargs)
  File "c:\Users\admin\PycharmProjects\pyscrape\venv\lib\site-packages\requests\sessions.py", line 701, in send
    r = adapter.send(request, **kwargs)
  File "c:\Users\admin\PycharmProjects\pyscrape\venv\lib\site-packages\requests\adapters.py", line 489, in send
    resp = conn.urlopen(
  File "c:\Users\admin\PycharmProjects\pyscrape\venv\lib\site-packages\urllib3\connectionpool.py", line 723, in urlopen
    response = self.ResponseCls.from_httplib(
  File "c:\Users\admin\PycharmProjects\pyscrape\venv\lib\site-packages\urllib3\response.py", line 600, in from_httplib
    headers = HTTPHeaderDict(headers.items())
  File "c:\Users\admin\PycharmProjects\pyscrape\venv\lib\site-packages\urllib3\_collections.py", line 148, in __init__
    self.extend(headers)
  File "c:\Users\admin\PycharmProjects\pyscrape\venv\lib\site-packages\urllib3\_collections.py", line 254, in extend
    self.add(key, value)
  File "c:\Users\admin\PycharmProjects\pyscrape\venv\lib\site-packages\urllib3\_collections.py", line 215, in add
    def add(self, key, val):
  File "_pydevd_bundle/pydevd_cython.pyx", line 1366, in _pydevd_bundle.pydevd_cython.SafeCallWrapper.__call__
  File "_pydevd_bundle/pydevd_cython.pyx", line 1667, in _pydevd_bundle.pydevd_cython.ThreadTracer.__call__
  File "c:\Users\admin\.vscode\extensions\ms-python.python-2022.8.0\pythonFiles\lib\python\debugpy\_vendored\pydevd\_pydev_bundle\pydev_is_thread_alive.py", line 9, in is_thread_alive
    def is_thread_alive(t):
KeyboardInterrupt

~~~~~~~~~~~~~~~ 2022/06/25 09:42:13 ~~~~~~~~~~~~~~~
Traceback (most recent call last):
  File "c:\Users\admin\PycharmProjects\pyscrape\tagalog-pinoydictionary-scrape.py", line 94, in <module>
    getContent(bs)
  File "c:\Users\admin\PycharmProjects\pyscrape\tagalog-pinoydictionary-scrape.py", line 49, in getContent
    conjugationsRaw = conjRegex.search(definition).group(1)
AttributeError: 'NoneType' object has no attribute 'group'

~~~~~~~~~~~~~~~ 2022/06/25 09:42:13 ~~~~~~~~~~~~~~~
Traceback (most recent call last):
  File "c:\Users\admin\PycharmProjects\pyscrape\tagalog-pinoydictionary-scrape.py", line 94, in <module>
    getContent(bs)
  File "c:\Users\admin\PycharmProjects\pyscrape\tagalog-pinoydictionary-scrape.py", line 49, in getContent
    conjugationsRaw = conjRegex.search(definition).group(1)
AttributeError: 'NoneType' object has no attribute 'group'

~~~~~~~~~~~~~~~ 2022/06/25 09:42:14 ~~~~~~~~~~~~~~~
Traceback (most recent call last):
  File "c:\Users\admin\PycharmProjects\pyscrape\tagalog-pinoydictionary-scrape.py", line 94, in <module>
    getContent(bs)
  File "c:\Users\admin\PycharmProjects\pyscrape\tagalog-pinoydictionary-scrape.py", line 49, in getContent
    conjugationsRaw = conjRegex.search(definition).group(1)
AttributeError: 'NoneType' object has no attribute 'group'

~~~~~~~~~~~~~~~ 2022/06/25 09:42:15 ~~~~~~~~~~~~~~~
Traceback (most recent call last):
  File "c:\Users\admin\PycharmProjects\pyscrape\tagalog-pinoydictionary-scrape.py", line 94, in <module>
    getContent(bs)
  File "c:\Users\admin\PycharmProjects\pyscrape\tagalog-pinoydictionary-scrape.py", line 49, in getContent
    conjugationsRaw = conjRegex.search(definition).group(1)
AttributeError: 'NoneType' object has no attribute 'group'

~~~~~~~~~~~~~~~ 2022/06/25 09:42:16 ~~~~~~~~~~~~~~~
Traceback (most recent call last):
  File "c:\Users\admin\PycharmProjects\pyscrape\tagalog-pinoydictionary-scrape.py", line 93, in <module>
    bs = getPage(url)
  File "c:\Users\admin\PycharmProjects\pyscrape\tagalog-pinoydictionary-scrape.py", line 22, in getPage
    req = requests.get(url)
  File "c:\Users\admin\PycharmProjects\pyscrape\venv\lib\site-packages\requests\api.py", line 73, in get
    return request("get", url, params=params, **kwargs)
  File "c:\Users\admin\PycharmProjects\pyscrape\venv\lib\site-packages\requests\api.py", line 59, in request
    return session.request(method=method, url=url, **kwargs)
  File "c:\Users\admin\PycharmProjects\pyscrape\venv\lib\site-packages\requests\sessions.py", line 587, in request
    resp = self.send(prep, **send_kwargs)
  File "c:\Users\admin\PycharmProjects\pyscrape\venv\lib\site-packages\requests\sessions.py", line 701, in send
    r = adapter.send(request, **kwargs)
  File "c:\Users\admin\PycharmProjects\pyscrape\venv\lib\site-packages\requests\adapters.py", line 489, in send
    resp = conn.urlopen(
  File "c:\Users\admin\PycharmProjects\pyscrape\venv\lib\site-packages\urllib3\connectionpool.py", line 703, in urlopen
    httplib_response = self._make_request(
  File "c:\Users\admin\PycharmProjects\pyscrape\venv\lib\site-packages\urllib3\connectionpool.py", line 449, in _make_request
    six.raise_from(e, None)
  File "<string>", line 3, in raise_from
  File "c:\Users\admin\PycharmProjects\pyscrape\venv\lib\site-packages\urllib3\connectionpool.py", line 444, in _make_request
    httplib_response = conn.getresponse()
  File "C:\Users\admin\AppData\Local\Programs\Python\Python39\lib\http\client.py", line 1347, in getresponse
    response.begin()
  File "C:\Users\admin\AppData\Local\Programs\Python\Python39\lib\http\client.py", line 307, in begin
    version, status, reason = self._read_status()
  File "C:\Users\admin\AppData\Local\Programs\Python\Python39\lib\http\client.py", line 268, in _read_status
    line = str(self.fp.readline(_MAXLINE + 1), "iso-8859-1")
  File "C:\Users\admin\AppData\Local\Programs\Python\Python39\lib\socket.py", line 704, in readinto
    return self._sock.recv_into(b)
  File "C:\Users\admin\AppData\Local\Programs\Python\Python39\lib\ssl.py", line 1241, in recv_into
    return self.read(nbytes, buffer)
  File "C:\Users\admin\AppData\Local\Programs\Python\Python39\lib\ssl.py", line 1099, in read
    return self._sslobj.read(len, buffer)
KeyboardInterrupt

~~~~~~~~~~~~~~~ 2022/06/25 09:42:17 ~~~~~~~~~~~~~~~
Traceback (most recent call last):
  File "c:\Users\admin\PycharmProjects\pyscrape\tagalog-pinoydictionary-scrape.py", line 94, in <module>
    getContent(bs)
  File "c:\Users\admin\PycharmProjects\pyscrape\tagalog-pinoydictionary-scrape.py", line 49, in getContent
    conjugationsRaw = conjRegex.search(definition).group(1)
AttributeError: 'NoneType' object has no attribute 'group'

~~~~~~~~~~~~~~~ 2022/06/25 09:42:18 ~~~~~~~~~~~~~~~
Traceback (most recent call last):
  File "c:\Users\admin\PycharmProjects\pyscrape\tagalog-pinoydictionary-scrape.py", line 94, in <module>
    getContent(bs)
  File "c:\Users\admin\PycharmProjects\pyscrape\tagalog-pinoydictionary-scrape.py", line 49, in getContent
    conjugationsRaw = conjRegex.search(definition).group(1)
AttributeError: 'NoneType' object has no attribute 'group'

~~~~~~~~~~~~~~~ 2022/06/25 09:43:10 ~~~~~~~~~~~~~~~
Traceback (most recent call last):
  File "c:\Users\admin\PycharmProjects\pyscrape\tagalog-pinoydictionary-scrape.py", line 94, in <module>
    getContent(bs)
  File "c:\Users\admin\PycharmProjects\pyscrape\tagalog-pinoydictionary-scrape.py", line 49, in getContent
    conjugationsRaw = conjRegex.search(definition).group(1)
AttributeError: 'NoneType' object has no attribute 'group'

~~~~~~~~~~~~~~~ 2022/06/25 09:43:11 ~~~~~~~~~~~~~~~
Traceback (most recent call last):
  File "c:\Users\admin\PycharmProjects\pyscrape\tagalog-pinoydictionary-scrape.py", line 94, in <module>
    getContent(bs)
  File "c:\Users\admin\PycharmProjects\pyscrape\tagalog-pinoydictionary-scrape.py", line 49, in getContent
    conjugationsRaw = conjRegex.search(definition).group(1)
AttributeError: 'NoneType' object has no attribute 'group'

~~~~~~~~~~~~~~~ 2022/06/25 09:43:12 ~~~~~~~~~~~~~~~
Traceback (most recent call last):
  File "c:\Users\admin\PycharmProjects\pyscrape\tagalog-pinoydictionary-scrape.py", line 94, in <module>
    getContent(bs)
  File "c:\Users\admin\PycharmProjects\pyscrape\tagalog-pinoydictionary-scrape.py", line 49, in getContent
    conjugationsRaw = conjRegex.search(definition).group(1)
AttributeError: 'NoneType' object has no attribute 'group'

~~~~~~~~~~~~~~~ 2022/06/25 09:43:13 ~~~~~~~~~~~~~~~
Traceback (most recent call last):
  File "c:\Users\admin\PycharmProjects\pyscrape\tagalog-pinoydictionary-scrape.py", line 94, in <module>
    getContent(bs)
  File "c:\Users\admin\PycharmProjects\pyscrape\tagalog-pinoydictionary-scrape.py", line 49, in getContent
    conjugationsRaw = conjRegex.search(definition).group(1)
AttributeError: 'NoneType' object has no attribute 'group'

~~~~~~~~~~~~~~~ 2022/06/25 09:43:14 ~~~~~~~~~~~~~~~
Traceback (most recent call last):
  File "c:\Users\admin\PycharmProjects\pyscrape\tagalog-pinoydictionary-scrape.py", line 94, in <module>
    getContent(bs)
  File "c:\Users\admin\PycharmProjects\pyscrape\tagalog-pinoydictionary-scrape.py", line 49, in getContent
    conjugationsRaw = conjRegex.search(definition).group(1)
AttributeError: 'NoneType' object has no attribute 'group'

~~~~~~~~~~~~~~~ 2022/06/25 09:44:07 ~~~~~~~~~~~~~~~
Traceback (most recent call last):
  File "c:\Users\admin\PycharmProjects\pyscrape\tagalog-pinoydictionary-scrape.py", line 93, in <module>
    bs = getPage(url)
  File "c:\Users\admin\PycharmProjects\pyscrape\tagalog-pinoydictionary-scrape.py", line 22, in getPage
    req = requests.get(url)
  File "c:\Users\admin\PycharmProjects\pyscrape\venv\lib\site-packages\requests\api.py", line 73, in get
    return request("get", url, params=params, **kwargs)
  File "c:\Users\admin\PycharmProjects\pyscrape\venv\lib\site-packages\requests\api.py", line 59, in request
    return session.request(method=method, url=url, **kwargs)
  File "c:\Users\admin\PycharmProjects\pyscrape\venv\lib\site-packages\requests\sessions.py", line 587, in request
    resp = self.send(prep, **send_kwargs)
  File "c:\Users\admin\PycharmProjects\pyscrape\venv\lib\site-packages\requests\sessions.py", line 701, in send
    r = adapter.send(request, **kwargs)
  File "c:\Users\admin\PycharmProjects\pyscrape\venv\lib\site-packages\requests\adapters.py", line 489, in send
    resp = conn.urlopen(
  File "c:\Users\admin\PycharmProjects\pyscrape\venv\lib\site-packages\urllib3\connectionpool.py", line 703, in urlopen
    httplib_response = self._make_request(
  File "c:\Users\admin\PycharmProjects\pyscrape\venv\lib\site-packages\urllib3\connectionpool.py", line 386, in _make_request
    self._validate_conn(conn)
  File "c:\Users\admin\PycharmProjects\pyscrape\venv\lib\site-packages\urllib3\connectionpool.py", line 1040, in _validate_conn
    conn.connect()
  File "c:\Users\admin\PycharmProjects\pyscrape\venv\lib\site-packages\urllib3\connection.py", line 358, in connect
    self.sock = conn = self._new_conn()
  File "c:\Users\admin\PycharmProjects\pyscrape\venv\lib\site-packages\urllib3\connection.py", line 174, in _new_conn
    conn = connection.create_connection(
  File "c:\Users\admin\PycharmProjects\pyscrape\venv\lib\site-packages\urllib3\util\connection.py", line 85, in create_connection
    sock.connect(sa)
KeyboardInterrupt

~~~~~~~~~~~~~~~ 2022/06/25 10:11:47 ~~~~~~~~~~~~~~~
Traceback (most recent call last):
  File "c:\Users\admin\PycharmProjects\pyscrape\tagalog-pinoydictionary-scrape.py", line 95, in <module>
    bs = getPage(url)
  File "c:\Users\admin\PycharmProjects\pyscrape\tagalog-pinoydictionary-scrape.py", line 23, in getPage
    req = requests.get(url)
  File "c:\Users\admin\PycharmProjects\pyscrape\venv\lib\site-packages\requests\api.py", line 73, in get
    return request("get", url, params=params, **kwargs)
  File "c:\Users\admin\PycharmProjects\pyscrape\venv\lib\site-packages\requests\api.py", line 59, in request
    return session.request(method=method, url=url, **kwargs)
  File "c:\Users\admin\PycharmProjects\pyscrape\venv\lib\site-packages\requests\sessions.py", line 587, in request
    resp = self.send(prep, **send_kwargs)
  File "c:\Users\admin\PycharmProjects\pyscrape\venv\lib\site-packages\requests\sessions.py", line 701, in send
    r = adapter.send(request, **kwargs)
  File "c:\Users\admin\PycharmProjects\pyscrape\venv\lib\site-packages\requests\adapters.py", line 489, in send
    resp = conn.urlopen(
  File "c:\Users\admin\PycharmProjects\pyscrape\venv\lib\site-packages\urllib3\connectionpool.py", line 703, in urlopen
    httplib_response = self._make_request(
  File "c:\Users\admin\PycharmProjects\pyscrape\venv\lib\site-packages\urllib3\connectionpool.py", line 449, in _make_request
    six.raise_from(e, None)
  File "<string>", line 3, in raise_from
  File "c:\Users\admin\PycharmProjects\pyscrape\venv\lib\site-packages\urllib3\connectionpool.py", line 444, in _make_request
    httplib_response = conn.getresponse()
  File "C:\Users\admin\AppData\Local\Programs\Python\Python39\lib\http\client.py", line 1347, in getresponse
    response.begin()
  File "C:\Users\admin\AppData\Local\Programs\Python\Python39\lib\http\client.py", line 307, in begin
    version, status, reason = self._read_status()
  File "C:\Users\admin\AppData\Local\Programs\Python\Python39\lib\http\client.py", line 268, in _read_status
    line = str(self.fp.readline(_MAXLINE + 1), "iso-8859-1")
  File "C:\Users\admin\AppData\Local\Programs\Python\Python39\lib\socket.py", line 704, in readinto
    return self._sock.recv_into(b)
  File "C:\Users\admin\AppData\Local\Programs\Python\Python39\lib\ssl.py", line 1241, in recv_into
    return self.read(nbytes, buffer)
  File "C:\Users\admin\AppData\Local\Programs\Python\Python39\lib\ssl.py", line 1099, in read
    return self._sslobj.read(len, buffer)
KeyboardInterrupt

~~~~~~~~~~~~~~~ 2022/06/25 10:12:27 ~~~~~~~~~~~~~~~
Traceback (most recent call last):
  File "c:\Users\admin\PycharmProjects\pyscrape\tagalog-pinoydictionary-scrape.py", line 96, in <module>
    bs = getPage(url)
  File "c:\Users\admin\PycharmProjects\pyscrape\tagalog-pinoydictionary-scrape.py", line 23, in getPage
    req = requests.get(url)
  File "c:\Users\admin\PycharmProjects\pyscrape\venv\lib\site-packages\requests\api.py", line 73, in get
    return request("get", url, params=params, **kwargs)
  File "c:\Users\admin\PycharmProjects\pyscrape\venv\lib\site-packages\requests\api.py", line 59, in request
    return session.request(method=method, url=url, **kwargs)
  File "c:\Users\admin\PycharmProjects\pyscrape\venv\lib\site-packages\requests\sessions.py", line 587, in request
    resp = self.send(prep, **send_kwargs)
  File "c:\Users\admin\PycharmProjects\pyscrape\venv\lib\site-packages\requests\sessions.py", line 701, in send
    r = adapter.send(request, **kwargs)
  File "c:\Users\admin\PycharmProjects\pyscrape\venv\lib\site-packages\requests\adapters.py", line 489, in send
    resp = conn.urlopen(
  File "c:\Users\admin\PycharmProjects\pyscrape\venv\lib\site-packages\urllib3\connectionpool.py", line 703, in urlopen
    httplib_response = self._make_request(
  File "c:\Users\admin\PycharmProjects\pyscrape\venv\lib\site-packages\urllib3\connectionpool.py", line 386, in _make_request
    self._validate_conn(conn)
  File "c:\Users\admin\PycharmProjects\pyscrape\venv\lib\site-packages\urllib3\connectionpool.py", line 1040, in _validate_conn
    conn.connect()
  File "c:\Users\admin\PycharmProjects\pyscrape\venv\lib\site-packages\urllib3\connection.py", line 414, in connect
    self.sock = ssl_wrap_socket(
  File "c:\Users\admin\PycharmProjects\pyscrape\venv\lib\site-packages\urllib3\util\ssl_.py", line 449, in ssl_wrap_socket
    ssl_sock = _ssl_wrap_socket_impl(
  File "c:\Users\admin\PycharmProjects\pyscrape\venv\lib\site-packages\urllib3\util\ssl_.py", line 493, in _ssl_wrap_socket_impl
    return ssl_context.wrap_socket(sock, server_hostname=server_hostname)
  File "C:\Users\admin\AppData\Local\Programs\Python\Python39\lib\ssl.py", line 500, in wrap_socket
    return self.sslsocket_class._create(
  File "C:\Users\admin\AppData\Local\Programs\Python\Python39\lib\ssl.py", line 1040, in _create
    self.do_handshake()
  File "C:\Users\admin\AppData\Local\Programs\Python\Python39\lib\ssl.py", line 1309, in do_handshake
    self._sslobj.do_handshake()
KeyboardInterrupt

~~~~~~~~~~~~~~~ 2022/06/25 10:13:16 ~~~~~~~~~~~~~~~
Traceback (most recent call last):
  File "c:\Users\admin\PycharmProjects\pyscrape\tagalog-pinoydictionary-scrape.py", line 97, in <module>
    bs = getPage(url)
  File "c:\Users\admin\PycharmProjects\pyscrape\tagalog-pinoydictionary-scrape.py", line 24, in getPage
    req = requests.get(url)
  File "c:\Users\admin\PycharmProjects\pyscrape\venv\lib\site-packages\requests\api.py", line 73, in get
    return request("get", url, params=params, **kwargs)
  File "c:\Users\admin\PycharmProjects\pyscrape\venv\lib\site-packages\requests\api.py", line 59, in request
    return session.request(method=method, url=url, **kwargs)
  File "c:\Users\admin\PycharmProjects\pyscrape\venv\lib\site-packages\requests\sessions.py", line 587, in request
    resp = self.send(prep, **send_kwargs)
  File "c:\Users\admin\PycharmProjects\pyscrape\venv\lib\site-packages\requests\sessions.py", line 701, in send
    r = adapter.send(request, **kwargs)
  File "c:\Users\admin\PycharmProjects\pyscrape\venv\lib\site-packages\requests\adapters.py", line 489, in send
    resp = conn.urlopen(
  File "c:\Users\admin\PycharmProjects\pyscrape\venv\lib\site-packages\urllib3\connectionpool.py", line 703, in urlopen
    httplib_response = self._make_request(
  File "c:\Users\admin\PycharmProjects\pyscrape\venv\lib\site-packages\urllib3\connectionpool.py", line 386, in _make_request
    self._validate_conn(conn)
  File "c:\Users\admin\PycharmProjects\pyscrape\venv\lib\site-packages\urllib3\connectionpool.py", line 1040, in _validate_conn
    conn.connect()
  File "c:\Users\admin\PycharmProjects\pyscrape\venv\lib\site-packages\urllib3\connection.py", line 414, in connect
    self.sock = ssl_wrap_socket(
  File "c:\Users\admin\PycharmProjects\pyscrape\venv\lib\site-packages\urllib3\util\ssl_.py", line 402, in ssl_wrap_socket
    context.load_verify_locations(ca_certs, ca_cert_dir, ca_cert_data)
KeyboardInterrupt

~~~~~~~~~~~~~~~ 2022/07/03 21:07:13 ~~~~~~~~~~~~~~~
Traceback (most recent call last):
  File "C:\Users\admin\PycharmProjects\hanapsalita-data\venv\lib\site-packages\mysql\connector\connection_cext.py", line 535, in cmd_query
    self._cmysql.query(query,
_mysql_connector.MySQLInterfaceError: You have an error in your SQL syntax; check the manual that corresponds to your MariaDB server version for the right syntax to use near ''tagalog_words' WHERE word='aalug-alog'' at line 1

During handling of the above exception, another exception occurred:

Traceback (most recent call last):
  File "C:\Users\admin\PycharmProjects\hanapsalita-data\tagalog-pinoydictionary-scrape.py", line 127, in <module>
    getContent(bs)
  File "C:\Users\admin\PycharmProjects\hanapsalita-data\tagalog-pinoydictionary-scrape.py", line 74, in getContent
    lastRowId = pushToDatabases(conn, cur, "tagalog_words", jsonDatabase, lastRowId, word, wordLength, category, alphaSorted,
  File "C:\Users\admin\PycharmProjects\hanapsalita-data\scrapeUtils.py", line 158, in pushToDatabases
    if not wordAlreadyStored(cur, table, word):
  File "C:\Users\admin\PycharmProjects\hanapsalita-data\scrapeUtils.py", line 89, in wordAlreadyStored
    cur.execute("SELECT * FROM %s WHERE word=%s", (table, word))
  File "C:\Users\admin\PycharmProjects\hanapsalita-data\venv\lib\site-packages\mysql\connector\cursor_cext.py", line 269, in execute
    result = self._cnx.cmd_query(stmt, raw=self._raw,
  File "C:\Users\admin\PycharmProjects\hanapsalita-data\venv\lib\site-packages\mysql\connector\connection_cext.py", line 540, in cmd_query
    raise errors.get_mysql_exception(exc.errno, msg=exc.msg,
mysql.connector.errors.ProgrammingError: 1064 (42000): You have an error in your SQL syntax; check the manual that corresponds to your MariaDB server version for the right syntax to use near ''tagalog_words' WHERE word='aalug-alog'' at line 1

~~~~~~~~~~~~~~~ 2022/07/03 21:31:24 ~~~~~~~~~~~~~~~
Traceback (most recent call last):
  File "C:\Users\admin\PycharmProjects\hanapsalita-data\tagalog-pinoydictionary-scrape.py", line 127, in <module>
    getContent(bs)
  File "C:\Users\admin\PycharmProjects\hanapsalita-data\tagalog-pinoydictionary-scrape.py", line 74, in getContent
    lastRowId = pushToDatabases(conn, cur, "tagalog_words", jsonDatabase, lastRowId, word, wordLength, category, alphaSorted,
  File "C:\Users\admin\PycharmProjects\hanapsalita-data\scrapeUtils.py", line 158, in pushToDatabases
    if not wordAlreadyStored(cur, table, word):
  File "C:\Users\admin\PycharmProjects\hanapsalita-data\scrapeUtils.py", line 89, in wordAlreadyStored
    cur.execute(f"SELECT * FROM {table} WHERE word=%s", word)
  File "C:\Users\admin\PycharmProjects\hanapsalita-data\venv\lib\site-packages\mysql\connector\cursor_cext.py", line 257, in execute
    prepared = self._cnx.prepare_for_mysql(params)
  File "C:\Users\admin\PycharmProjects\hanapsalita-data\venv\lib\site-packages\mysql\connector\connection_cext.py", line 698, in prepare_for_mysql
    raise errors.ProgrammingError(
mysql.connector.errors.ProgrammingError: Could not process parameters: str(aalug-alog), it must be of type list, tuple or dict

~~~~~~~~~~~~~~~ 2022/07/03 21:33:25 ~~~~~~~~~~~~~~~
Traceback (most recent call last):
  File "C:\Users\admin\PycharmProjects\hanapsalita-data\tagalog-pinoydictionary-scrape.py", line 127, in <module>
    getContent(bs)
  File "C:\Users\admin\PycharmProjects\hanapsalita-data\tagalog-pinoydictionary-scrape.py", line 74, in getContent
    lastRowId = pushToDatabases(conn, cur, "tagalog_words", jsonDatabase, lastRowId, word, wordLength, category, alphaSorted,
  File "C:\Users\admin\PycharmProjects\hanapsalita-data\scrapeUtils.py", line 158, in pushToDatabases
    if not wordAlreadyStored(cur, table, word):
  File "C:\Users\admin\PycharmProjects\hanapsalita-data\scrapeUtils.py", line 89, in wordAlreadyStored
    cur.execute("SELECT * FROM " + table + " WHERE word=%s", word)
  File "C:\Users\admin\PycharmProjects\hanapsalita-data\venv\lib\site-packages\mysql\connector\cursor_cext.py", line 257, in execute
    prepared = self._cnx.prepare_for_mysql(params)
  File "C:\Users\admin\PycharmProjects\hanapsalita-data\venv\lib\site-packages\mysql\connector\connection_cext.py", line 698, in prepare_for_mysql
    raise errors.ProgrammingError(
mysql.connector.errors.ProgrammingError: Could not process parameters: str(aalug-alog), it must be of type list, tuple or dict

~~~~~~~~~~~~~~~ 2022/07/03 21:33:47 ~~~~~~~~~~~~~~~
Traceback (most recent call last):
  File "C:\Users\admin\PycharmProjects\hanapsalita-data\tagalog-pinoydictionary-scrape.py", line 127, in <module>
    getContent(bs)
  File "C:\Users\admin\PycharmProjects\hanapsalita-data\tagalog-pinoydictionary-scrape.py", line 74, in getContent
    lastRowId = pushToDatabases(conn, cur, "tagalog_words", jsonDatabase, lastRowId, word, wordLength, category, alphaSorted,
  File "C:\Users\admin\PycharmProjects\hanapsalita-data\scrapeUtils.py", line 158, in pushToDatabases
    if not wordAlreadyStored(cur, table, word):
  File "C:\Users\admin\PycharmProjects\hanapsalita-data\scrapeUtils.py", line 89, in wordAlreadyStored
    cur.execute("SELECT * FROM " + table + " WHERE word=%s", (word))
  File "C:\Users\admin\PycharmProjects\hanapsalita-data\venv\lib\site-packages\mysql\connector\cursor_cext.py", line 257, in execute
    prepared = self._cnx.prepare_for_mysql(params)
  File "C:\Users\admin\PycharmProjects\hanapsalita-data\venv\lib\site-packages\mysql\connector\connection_cext.py", line 698, in prepare_for_mysql
    raise errors.ProgrammingError(
mysql.connector.errors.ProgrammingError: Could not process parameters: str(aalug-alog), it must be of type list, tuple or dict

~~~~~~~~~~~~~~~ 2022/07/03 21:34:39 ~~~~~~~~~~~~~~~
Traceback (most recent call last):
  File "C:\Users\admin\PycharmProjects\hanapsalita-data\venv\lib\site-packages\mysql\connector\connection_cext.py", line 535, in cmd_query
    self._cmysql.query(query,
_mysql_connector.MySQLInterfaceError: Duplicate entry '0' for key 'PRIMARY'

During handling of the above exception, another exception occurred:

Traceback (most recent call last):
  File "C:\Users\admin\PycharmProjects\hanapsalita-data\tagalog-pinoydictionary-scrape.py", line 127, in <module>
    getContent(bs)
  File "C:\Users\admin\PycharmProjects\hanapsalita-data\tagalog-pinoydictionary-scrape.py", line 74, in getContent
    lastRowId = pushToDatabases(conn, cur, "tagalog_words", jsonDatabase, lastRowId, word, wordLength, category, alphaSorted,
  File "C:\Users\admin\PycharmProjects\hanapsalita-data\scrapeUtils.py", line 159, in pushToDatabases
    lastRowID = pushToMySQL(conn, cur, lastRowId, word, wordLength, category, alphaSorted, alphaSortedNoDuplicates, startingsWithoutPunctuations, endingsWithoutPunctuations, constituentsRowsWithoutPunctuations)
  File "C:\Users\admin\PycharmProjects\hanapsalita-data\scrapeUtils.py", line 102, in pushToMySQL
    cur.execute(tagalogWordsSQL, tagalogWordsValues)
  File "C:\Users\admin\PycharmProjects\hanapsalita-data\venv\lib\site-packages\mysql\connector\cursor_cext.py", line 269, in execute
    result = self._cnx.cmd_query(stmt, raw=self._raw,
  File "C:\Users\admin\PycharmProjects\hanapsalita-data\venv\lib\site-packages\mysql\connector\connection_cext.py", line 540, in cmd_query
    raise errors.get_mysql_exception(exc.errno, msg=exc.msg,
mysql.connector.errors.IntegrityError: 1062 (23000): Duplicate entry '0' for key 'PRIMARY'

~~~~~~~~~~~~~~~ 2022/07/03 21:47:11 ~~~~~~~~~~~~~~~
Traceback (most recent call last):
  File "C:\Users\admin\PycharmProjects\hanapsalita-data\venv\lib\site-packages\mysql\connector\connection_cext.py", line 535, in cmd_query
    self._cmysql.query(query,
_mysql_connector.MySQLInterfaceError: Duplicate entry '0' for key 'PRIMARY'

During handling of the above exception, another exception occurred:

Traceback (most recent call last):
  File "C:\Users\admin\PycharmProjects\hanapsalita-data\tagalog-pinoydictionary-scrape.py", line 127, in <module>
    getContent(bs)
  File "C:\Users\admin\PycharmProjects\hanapsalita-data\tagalog-pinoydictionary-scrape.py", line 74, in getContent
    lastRowId = pushToDatabases(conn, cur, "tagalog_words", jsonDatabase, lastRowId, word, wordLength, category, alphaSorted,
  File "C:\Users\admin\PycharmProjects\hanapsalita-data\scrapeUtils.py", line 159, in pushToDatabases
    lastRowID = pushToMySQL(conn, cur, lastRowId, word, wordLength, category, alphaSorted, alphaSortedNoDuplicates, startingsWithoutPunctuations, endingsWithoutPunctuations, constituentsRowsWithoutPunctuations)
  File "C:\Users\admin\PycharmProjects\hanapsalita-data\scrapeUtils.py", line 102, in pushToMySQL
    cur.execute(tagalogWordsSQL, tagalogWordsValues)
  File "C:\Users\admin\PycharmProjects\hanapsalita-data\venv\lib\site-packages\mysql\connector\cursor_cext.py", line 269, in execute
    result = self._cnx.cmd_query(stmt, raw=self._raw,
  File "C:\Users\admin\PycharmProjects\hanapsalita-data\venv\lib\site-packages\mysql\connector\connection_cext.py", line 540, in cmd_query
    raise errors.get_mysql_exception(exc.errno, msg=exc.msg,
mysql.connector.errors.IntegrityError: 1062 (23000): Duplicate entry '0' for key 'PRIMARY'

~~~~~~~~~~~~~~~ 2022/07/03 21:54:54 ~~~~~~~~~~~~~~~
Traceback (most recent call last):
  File "C:/Users/admin/PycharmProjects/hanapsalita-data/tagalog-pinoydictionary-scrape.py", line 127, in <module>
    getContent(bs)
  File "C:/Users/admin/PycharmProjects/hanapsalita-data/tagalog-pinoydictionary-scrape.py", line 74, in getContent
    lastRowId = pushToDatabases(conn, cur, "tagalog_words", jsonDatabase, lastRowId, word, wordLength, category, alphaSorted,
  File "C:\Users\admin\PycharmProjects\hanapsalita-data\scrapeUtils.py", line 159, in pushToDatabases
    lastRowID = pushToMySQL(conn, cur, lastRowId, word, wordLength, category, alphaSorted, alphaSortedNoDuplicates, startingsWithoutPunctuations, endingsWithoutPunctuations, constituentsRowsWithoutPunctuations)
  File "C:\Users\admin\PycharmProjects\hanapsalita-data\scrapeUtils.py", line 104, in pushToMySQL
    if (lastRowId is not None) and ((lastRowId + 1) != lastRowId1):
  File "C:\Users\admin\PycharmProjects\hanapsalita-data\scrapeUtils.py", line 104, in pushToMySQL
    if (lastRowId is not None) and ((lastRowId + 1) != lastRowId1):
  File "_pydevd_bundle\pydevd_cython_win32_39_64.pyx", line 1179, in _pydevd_bundle.pydevd_cython_win32_39_64.SafeCallWrapper.__call__
  File "_pydevd_bundle\pydevd_cython_win32_39_64.pyx", line 620, in _pydevd_bundle.pydevd_cython_win32_39_64.PyDBFrame.trace_dispatch
  File "_pydevd_bundle\pydevd_cython_win32_39_64.pyx", line 1095, in _pydevd_bundle.pydevd_cython_win32_39_64.PyDBFrame.trace_dispatch
  File "_pydevd_bundle\pydevd_cython_win32_39_64.pyx", line 1057, in _pydevd_bundle.pydevd_cython_win32_39_64.PyDBFrame.trace_dispatch
  File "_pydevd_bundle\pydevd_cython_win32_39_64.pyx", line 317, in _pydevd_bundle.pydevd_cython_win32_39_64.PyDBFrame.do_wait_suspend
  File "C:\Program Files\JetBrains\PyCharm 2022.1\plugins\python\helpers\pydev\pydevd.py", line 1155, in do_wait_suspend
    self._do_wait_suspend(thread, frame, event, arg, suspend_type, from_this_thread)
  File "C:\Program Files\JetBrains\PyCharm 2022.1\plugins\python\helpers\pydev\pydevd.py", line 1170, in _do_wait_suspend
    time.sleep(0.01)
KeyboardInterrupt

~~~~~~~~~~~~~~~ 2022/07/03 21:55:43 ~~~~~~~~~~~~~~~
Traceback (most recent call last):
  File "C:\Users\admin\PycharmProjects\hanapsalita-data\venv\lib\site-packages\mysql\connector\connection_cext.py", line 535, in cmd_query
    self._cmysql.query(query,
_mysql_connector.MySQLInterfaceError: Duplicate entry '0' for key 'PRIMARY'

During handling of the above exception, another exception occurred:

Traceback (most recent call last):
  File "C:\Users\admin\PycharmProjects\hanapsalita-data\tagalog-pinoydictionary-scrape.py", line 127, in <module>
    getContent(bs)
  File "C:\Users\admin\PycharmProjects\hanapsalita-data\tagalog-pinoydictionary-scrape.py", line 74, in getContent
    lastRowId = pushToDatabases(conn, cur, "tagalog_words", jsonDatabase, lastRowId, word, wordLength, category, alphaSorted,
  File "C:\Users\admin\PycharmProjects\hanapsalita-data\scrapeUtils.py", line 159, in pushToDatabases
    lastRowID = pushToMySQL(conn, cur, lastRowId, word, wordLength, category, alphaSorted, alphaSortedNoDuplicates, startingsWithoutPunctuations, endingsWithoutPunctuations, constituentsRowsWithoutPunctuations)
  File "C:\Users\admin\PycharmProjects\hanapsalita-data\scrapeUtils.py", line 102, in pushToMySQL
    cur.execute(tagalogWordsSQL, tagalogWordsValues)
  File "C:\Users\admin\PycharmProjects\hanapsalita-data\venv\lib\site-packages\mysql\connector\cursor_cext.py", line 269, in execute
    result = self._cnx.cmd_query(stmt, raw=self._raw,
  File "C:\Users\admin\PycharmProjects\hanapsalita-data\venv\lib\site-packages\mysql\connector\connection_cext.py", line 540, in cmd_query
    raise errors.get_mysql_exception(exc.errno, msg=exc.msg,
mysql.connector.errors.IntegrityError: 1062 (23000): Duplicate entry '0' for key 'PRIMARY'

~~~~~~~~~~~~~~~ 2022/07/04 13:01:16 ~~~~~~~~~~~~~~~
Traceback (most recent call last):
  File "C:\Users\admin\PycharmProjects\hanapsalita-data\venv\lib\site-packages\mysql\connector\connection_cext.py", line 535, in cmd_query
    self._cmysql.query(query,
_mysql_connector.MySQLInterfaceError: Duplicate entry '0' for key 'PRIMARY'

During handling of the above exception, another exception occurred:

Traceback (most recent call last):
  File "C:\Users\admin\PycharmProjects\hanapsalita-data\tagalog-pinoydictionary-scrape.py", line 164, in <module>
    lastRowId = getContent(bs, lastRowId)
  File "C:\Users\admin\PycharmProjects\hanapsalita-data\tagalog-pinoydictionary-scrape.py", line 102, in getContent
    lastRowId = pushToDatabases(conn, cur, "tagalog_words", jsonDatabase, lastRowId, word, wordLength,
  File "C:\Users\admin\PycharmProjects\hanapsalita-data\scrapeUtils.py", line 180, in pushToDatabases
    lastRowID = pushToMySQL(conn, cur, lastRowId, word, wordLength, category, alphaSorted,
  File "C:\Users\admin\PycharmProjects\hanapsalita-data\scrapeUtils.py", line 116, in pushToMySQL
    cur.execute(tagalogWordsSQL, tagalogWordsValues)
  File "C:\Users\admin\PycharmProjects\hanapsalita-data\venv\lib\site-packages\mysql\connector\cursor_cext.py", line 269, in execute
    result = self._cnx.cmd_query(stmt, raw=self._raw,
  File "C:\Users\admin\PycharmProjects\hanapsalita-data\venv\lib\site-packages\mysql\connector\connection_cext.py", line 540, in cmd_query
    raise errors.get_mysql_exception(exc.errno, msg=exc.msg,
mysql.connector.errors.IntegrityError: 1062 (23000): Duplicate entry '0' for key 'PRIMARY'

~~~~~~~~~~~~~~~ 2022/07/04 13:04:23 ~~~~~~~~~~~~~~~
Traceback (most recent call last):
  File "C:\Users\admin\PycharmProjects\hanapsalita-data\venv\lib\site-packages\mysql\connector\connection_cext.py", line 535, in cmd_query
    self._cmysql.query(query,
_mysql_connector.MySQLInterfaceError: Duplicate entry '0' for key 'PRIMARY'

During handling of the above exception, another exception occurred:

Traceback (most recent call last):
  File "C:\Users\admin\PycharmProjects\hanapsalita-data\tagalog-pinoydictionary-scrape.py", line 164, in <module>
    lastRowId = getContent(bs, lastRowId)
  File "C:\Users\admin\PycharmProjects\hanapsalita-data\tagalog-pinoydictionary-scrape.py", line 102, in getContent
    lastRowId = pushToDatabases(conn, cur, "tagalog_words", jsonDatabase, lastRowId, word, wordLength,
  File "C:\Users\admin\PycharmProjects\hanapsalita-data\scrapeUtils.py", line 180, in pushToDatabases
    lastRowID = pushToMySQL(conn, cur, lastRowId, word, wordLength, category, alphaSorted,
  File "C:\Users\admin\PycharmProjects\hanapsalita-data\scrapeUtils.py", line 116, in pushToMySQL
    cur.execute(tagalogWordsSQL, tagalogWordsValues)
  File "C:\Users\admin\PycharmProjects\hanapsalita-data\venv\lib\site-packages\mysql\connector\cursor_cext.py", line 269, in execute
    result = self._cnx.cmd_query(stmt, raw=self._raw,
  File "C:\Users\admin\PycharmProjects\hanapsalita-data\venv\lib\site-packages\mysql\connector\connection_cext.py", line 540, in cmd_query
    raise errors.get_mysql_exception(exc.errno, msg=exc.msg,
mysql.connector.errors.IntegrityError: 1062 (23000): Duplicate entry '0' for key 'PRIMARY'

~~~~~~~~~~~~~~~ 2022/07/04 13:06:05 ~~~~~~~~~~~~~~~
Traceback (most recent call last):
  File "C:\Users\admin\PycharmProjects\hanapsalita-data\venv\lib\site-packages\mysql\connector\connection_cext.py", line 535, in cmd_query
    self._cmysql.query(query,
_mysql_connector.MySQLInterfaceError: Duplicate entry '0' for key 'PRIMARY'

During handling of the above exception, another exception occurred:

Traceback (most recent call last):
  File "C:/Users/admin/PycharmProjects/hanapsalita-data/tagalog-pinoydictionary-scrape.py", line 164, in <module>
    lastRowId = getContent(bs, lastRowId)
  File "C:/Users/admin/PycharmProjects/hanapsalita-data/tagalog-pinoydictionary-scrape.py", line 102, in getContent
    lastRowId = pushToDatabases(conn, cur, "tagalog_words", jsonDatabase, lastRowId, word, wordLength,
  File "C:\Users\admin\PycharmProjects\hanapsalita-data\scrapeUtils.py", line 180, in pushToDatabases
    lastRowID = pushToMySQL(conn, cur, lastRowId, word, wordLength, category, alphaSorted,
  File "C:\Users\admin\PycharmProjects\hanapsalita-data\scrapeUtils.py", line 116, in pushToMySQL
    cur.execute(tagalogWordsSQL, tagalogWordsValues)
  File "C:\Users\admin\PycharmProjects\hanapsalita-data\venv\lib\site-packages\mysql\connector\cursor_cext.py", line 269, in execute
    result = self._cnx.cmd_query(stmt, raw=self._raw,
  File "C:\Users\admin\PycharmProjects\hanapsalita-data\venv\lib\site-packages\mysql\connector\connection_cext.py", line 540, in cmd_query
    raise errors.get_mysql_exception(exc.errno, msg=exc.msg,
mysql.connector.errors.IntegrityError: 1062 (23000): Duplicate entry '0' for key 'PRIMARY'

~~~~~~~~~~~~~~~ 2022/07/04 13:06:43 ~~~~~~~~~~~~~~~
Traceback (most recent call last):
  File "C:\Users\admin\PycharmProjects\hanapsalita-data\venv\lib\site-packages\mysql\connector\connection_cext.py", line 535, in cmd_query
    self._cmysql.query(query,
_mysql_connector.MySQLInterfaceError: Duplicate entry '0' for key 'PRIMARY'

During handling of the above exception, another exception occurred:

Traceback (most recent call last):
  File "C:/Users/admin/PycharmProjects/hanapsalita-data/tagalog-pinoydictionary-scrape.py", line 164, in <module>
    lastRowId = getContent(bs, lastRowId)
  File "C:/Users/admin/PycharmProjects/hanapsalita-data/tagalog-pinoydictionary-scrape.py", line 102, in getContent
    lastRowId = pushToDatabases(conn, cur, "tagalog_words", jsonDatabase, lastRowId, word, wordLength,
  File "C:\Users\admin\PycharmProjects\hanapsalita-data\scrapeUtils.py", line 180, in pushToDatabases
    lastRowID = pushToMySQL(conn, cur, lastRowId, word, wordLength, category, alphaSorted,
  File "C:\Users\admin\PycharmProjects\hanapsalita-data\scrapeUtils.py", line 116, in pushToMySQL
    cur.execute(tagalogWordsSQL, tagalogWordsValues)
  File "C:\Users\admin\PycharmProjects\hanapsalita-data\venv\lib\site-packages\mysql\connector\cursor_cext.py", line 269, in execute
    result = self._cnx.cmd_query(stmt, raw=self._raw,
  File "C:\Users\admin\PycharmProjects\hanapsalita-data\venv\lib\site-packages\mysql\connector\connection_cext.py", line 540, in cmd_query
    raise errors.get_mysql_exception(exc.errno, msg=exc.msg,
mysql.connector.errors.IntegrityError: 1062 (23000): Duplicate entry '0' for key 'PRIMARY'

~~~~~~~~~~~~~~~ 2022/07/04 13:11:56 ~~~~~~~~~~~~~~~
Traceback (most recent call last):
  File "C:/Users/admin/PycharmProjects/hanapsalita-data/tagalog-pinoydictionary-scrape.py", line 155, in <module>
    lastPageNum = progressJson[letter]["lastPageNum"]
  File "C:/Users/admin/PycharmProjects/hanapsalita-data/tagalog-pinoydictionary-scrape.py", line 155, in <module>
    lastPageNum = progressJson[letter]["lastPageNum"]
  File "_pydevd_bundle\pydevd_cython_win32_39_64.pyx", line 1179, in _pydevd_bundle.pydevd_cython_win32_39_64.SafeCallWrapper.__call__
  File "_pydevd_bundle\pydevd_cython_win32_39_64.pyx", line 620, in _pydevd_bundle.pydevd_cython_win32_39_64.PyDBFrame.trace_dispatch
  File "_pydevd_bundle\pydevd_cython_win32_39_64.pyx", line 1095, in _pydevd_bundle.pydevd_cython_win32_39_64.PyDBFrame.trace_dispatch
  File "_pydevd_bundle\pydevd_cython_win32_39_64.pyx", line 1057, in _pydevd_bundle.pydevd_cython_win32_39_64.PyDBFrame.trace_dispatch
  File "_pydevd_bundle\pydevd_cython_win32_39_64.pyx", line 317, in _pydevd_bundle.pydevd_cython_win32_39_64.PyDBFrame.do_wait_suspend
  File "C:\Program Files\JetBrains\PyCharm 2022.1\plugins\python\helpers\pydev\pydevd.py", line 1155, in do_wait_suspend
    self._do_wait_suspend(thread, frame, event, arg, suspend_type, from_this_thread)
  File "C:\Program Files\JetBrains\PyCharm 2022.1\plugins\python\helpers\pydev\pydevd.py", line 1170, in _do_wait_suspend
    time.sleep(0.01)
KeyboardInterrupt

~~~~~~~~~~~~~~~ 2022/07/04 14:12:57 ~~~~~~~~~~~~~~~
Traceback (most recent call last):
  File "C:\Users\admin\PycharmProjects\hanapsalita-data\venv\lib\site-packages\mysql\connector\connection_cext.py", line 535, in cmd_query
    self._cmysql.query(query,
_mysql_connector.MySQLInterfaceError: Duplicate entry '0' for key 'PRIMARY'

During handling of the above exception, another exception occurred:

Traceback (most recent call last):
  File "C:/Users/admin/PycharmProjects/hanapsalita-data/tagalog-pinoydictionary-scrape.py", line 164, in <module>
    lastRowId = getContent(bs, lastRowId)
  File "C:/Users/admin/PycharmProjects/hanapsalita-data/tagalog-pinoydictionary-scrape.py", line 102, in getContent
    lastRowId = pushToDatabases(conn, cur, "tagalog_words", jsonDatabase, lastRowId, word, wordLength,
  File "C:\Users\admin\PycharmProjects\hanapsalita-data\scrapeUtils.py", line 180, in pushToDatabases
    lastRowID = pushToMySQL(conn, cur, lastRowId, word, wordLength, category, alphaSorted,
  File "C:\Users\admin\PycharmProjects\hanapsalita-data\scrapeUtils.py", line 116, in pushToMySQL
    cur.execute(tagalogWordsSQL, tagalogWordsValues)
  File "C:\Users\admin\PycharmProjects\hanapsalita-data\venv\lib\site-packages\mysql\connector\cursor_cext.py", line 269, in execute
    result = self._cnx.cmd_query(stmt, raw=self._raw,
  File "C:\Users\admin\PycharmProjects\hanapsalita-data\venv\lib\site-packages\mysql\connector\connection_cext.py", line 540, in cmd_query
    raise errors.get_mysql_exception(exc.errno, msg=exc.msg,
mysql.connector.errors.IntegrityError: 1062 (23000): Duplicate entry '0' for key 'PRIMARY'

~~~~~~~~~~~~~~~ 2022/07/04 14:28:37 ~~~~~~~~~~~~~~~
Traceback (most recent call last):
  File "C:/Users/admin/PycharmProjects/hanapsalita-data/tagalog-pinoydictionary-scrape.py", line 164, in <module>
    lastRowId = getContent(bs, lastRowId)
  File "C:/Users/admin/PycharmProjects/hanapsalita-data/tagalog-pinoydictionary-scrape.py", line 102, in getContent
    lastRowId = pushToDatabases(conn, cur, "tagalog_words", jsonDatabase, lastRowId, word, wordLength,
  File "C:\Users\admin\PycharmProjects\hanapsalita-data\scrapeUtils.py", line 180, in pushToDatabases
    lastRowID = pushToMySQL(conn, cur, lastRowId, word, wordLength, category, alphaSorted,
  File "C:\Users\admin\PycharmProjects\hanapsalita-data\scrapeUtils.py", line 119, in pushToMySQL
    raise Exception("`lastRowId + 1` and `lastRowId1` mismatch")
Exception: `lastRowId + 1` and `lastRowId1` mismatch

~~~~~~~~~~~~~~~ 2022/07/04 14:34:00 ~~~~~~~~~~~~~~~
Traceback (most recent call last):
  File "C:/Users/admin/PycharmProjects/hanapsalita-data/tagalog-pinoydictionary-scrape.py", line 164, in <module>
    lastRowId = getContent(bs, lastRowId)
  File "C:/Users/admin/PycharmProjects/hanapsalita-data/tagalog-pinoydictionary-scrape.py", line 102, in getContent
    lastRowId = pushToDatabases(conn, cur, "tagalog_words", jsonDatabase, lastRowId, word, wordLength,
  File "C:\Users\admin\PycharmProjects\hanapsalita-data\scrapeUtils.py", line 184, in pushToDatabases
    lastRowID = pushToMySQL(conn, cur, lastRowId, word, wordLength, category, alphaSorted,
  File "C:\Users\admin\PycharmProjects\hanapsalita-data\scrapeUtils.py", line 120, in pushToMySQL
    raise Exception("`lastRowId + 1` and `lastRowId1` mismatch")
Exception: `lastRowId + 1` and `lastRowId1` mismatch

~~~~~~~~~~~~~~~ 2022/07/04 15:17:56 ~~~~~~~~~~~~~~~
Traceback (most recent call last):
  File "C:/Users/admin/PycharmProjects/hanapsalita-data/tagalog-pinoydictionary-scrape.py", line 164, in <module>
    lastRowId = getContent(bs, lastRowId)
  File "C:/Users/admin/PycharmProjects/hanapsalita-data/tagalog-pinoydictionary-scrape.py", line 102, in getContent
    lastRowId = pushToDatabases(conn, cur, "tagalog_words", jsonDatabase, lastRowId, word, wordLength,
  File "C:\Users\admin\PycharmProjects\hanapsalita-data\scrapeUtils.py", line 184, in pushToDatabases
    lastRowID = pushToMySQL(conn, cur, lastRowId, word, wordLength, category, alphaSorted,
  File "C:\Users\admin\PycharmProjects\hanapsalita-data\scrapeUtils.py", line 120, in pushToMySQL
    raise Exception("`lastRowId + 1` and `lastRowId1` mismatch")
  File "C:\Users\admin\PycharmProjects\hanapsalita-data\scrapeUtils.py", line 120, in pushToMySQL
    raise Exception("`lastRowId + 1` and `lastRowId1` mismatch")
  File "_pydevd_bundle\pydevd_cython_win32_39_64.pyx", line 1179, in _pydevd_bundle.pydevd_cython_win32_39_64.SafeCallWrapper.__call__
  File "_pydevd_bundle\pydevd_cython_win32_39_64.pyx", line 620, in _pydevd_bundle.pydevd_cython_win32_39_64.PyDBFrame.trace_dispatch
  File "_pydevd_bundle\pydevd_cython_win32_39_64.pyx", line 1095, in _pydevd_bundle.pydevd_cython_win32_39_64.PyDBFrame.trace_dispatch
  File "_pydevd_bundle\pydevd_cython_win32_39_64.pyx", line 1057, in _pydevd_bundle.pydevd_cython_win32_39_64.PyDBFrame.trace_dispatch
  File "_pydevd_bundle\pydevd_cython_win32_39_64.pyx", line 317, in _pydevd_bundle.pydevd_cython_win32_39_64.PyDBFrame.do_wait_suspend
  File "C:\Program Files\JetBrains\PyCharm 2022.1\plugins\python\helpers\pydev\pydevd.py", line 1155, in do_wait_suspend
    self._do_wait_suspend(thread, frame, event, arg, suspend_type, from_this_thread)
  File "C:\Program Files\JetBrains\PyCharm 2022.1\plugins\python\helpers\pydev\pydevd.py", line 1170, in _do_wait_suspend
    time.sleep(0.01)
KeyboardInterrupt

~~~~~~~~~~~~~~~ 2022/07/04 15:38:48 ~~~~~~~~~~~~~~~
Traceback (most recent call last):
  File "C:\Users\admin\PycharmProjects\hanapsalita-data\venv\lib\site-packages\mysql\connector\connection_cext.py", line 535, in cmd_query
    self._cmysql.query(query,
_mysql_connector.MySQLInterfaceError: Duplicate entry '0' for key 'PRIMARY'

During handling of the above exception, another exception occurred:

Traceback (most recent call last):
  File "C:/Users/admin/PycharmProjects/hanapsalita-data/tagalog-pinoydictionary-scrape.py", line 164, in <module>
    lastRowId = getContent(bs, lastRowId)
  File "C:/Users/admin/PycharmProjects/hanapsalita-data/tagalog-pinoydictionary-scrape.py", line 102, in getContent
    lastRowId = pushToDatabases(conn, cur, "tagalog_words", jsonDatabase, lastRowId, word, wordLength,
  File "C:\Users\admin\PycharmProjects\hanapsalita-data\scrapeUtils.py", line 184, in pushToDatabases
    lastRowID = pushToMySQL(conn, cur, lastRowId, word, wordLength, category, alphaSorted,
  File "C:\Users\admin\PycharmProjects\hanapsalita-data\scrapeUtils.py", line 116, in pushToMySQL
    cur.execute(tagalogWordsSQL, tagalogWordsValues)
  File "C:\Users\admin\PycharmProjects\hanapsalita-data\venv\lib\site-packages\mysql\connector\cursor_cext.py", line 269, in execute
    result = self._cnx.cmd_query(stmt, raw=self._raw,
  File "C:\Users\admin\PycharmProjects\hanapsalita-data\venv\lib\site-packages\mysql\connector\connection_cext.py", line 540, in cmd_query
    raise errors.get_mysql_exception(exc.errno, msg=exc.msg,
mysql.connector.errors.IntegrityError: 1062 (23000): Duplicate entry '0' for key 'PRIMARY'

~~~~~~~~~~~~~~~ 2022/07/04 15:44:29 ~~~~~~~~~~~~~~~
Traceback (most recent call last):
  File "C:\Users\admin\PycharmProjects\hanapsalita-data\venv\lib\site-packages\mysql\connector\connection_cext.py", line 535, in cmd_query
    self._cmysql.query(query,
_mysql_connector.MySQLInterfaceError: Cannot add or update a child row: a foreign key constraint fails (`hanapsalita`.`tagalog_start`, CONSTRAINT `tagalog_start_id_fk` FOREIGN KEY (`id`) REFERENCES `tagalog_words` (`id`) ON DELETE CASCADE ON UPDATE CASCADE)

During handling of the above exception, another exception occurred:

Traceback (most recent call last):
  File "C:/Users/admin/PycharmProjects/hanapsalita-data/tagalog-pinoydictionary-scrape.py", line 164, in <module>
    lastRowId = getContent(bs, lastRowId)
  File "C:/Users/admin/PycharmProjects/hanapsalita-data/tagalog-pinoydictionary-scrape.py", line 102, in getContent
    lastRowId = pushToDatabases(conn, cur, "tagalog_words", jsonDatabase, lastRowId, word, wordLength,
  File "C:\Users\admin\PycharmProjects\hanapsalita-data\scrapeUtils.py", line 184, in pushToDatabases
    lastRowID = pushToMySQL(conn, cur, lastRowId, word, wordLength, category, alphaSorted,
  File "C:\Users\admin\PycharmProjects\hanapsalita-data\scrapeUtils.py", line 126, in pushToMySQL
    cur.execute(tagalogStartSQL, tagalogStartValues)
  File "C:\Users\admin\PycharmProjects\hanapsalita-data\venv\lib\site-packages\mysql\connector\cursor_cext.py", line 269, in execute
    result = self._cnx.cmd_query(stmt, raw=self._raw,
  File "C:\Users\admin\PycharmProjects\hanapsalita-data\venv\lib\site-packages\mysql\connector\connection_cext.py", line 540, in cmd_query
    raise errors.get_mysql_exception(exc.errno, msg=exc.msg,
mysql.connector.errors.IntegrityError: 1452 (23000): Cannot add or update a child row: a foreign key constraint fails (`hanapsalita`.`tagalog_start`, CONSTRAINT `tagalog_start_id_fk` FOREIGN KEY (`id`) REFERENCES `tagalog_words` (`id`) ON DELETE CASCADE ON UPDATE CASCADE)

~~~~~~~~~~~~~~~ 2022/07/04 15:52:35 ~~~~~~~~~~~~~~~
Traceback (most recent call last):
  File "C:/Users/admin/PycharmProjects/hanapsalita-data/tagalog-pinoydictionary-scrape.py", line 164, in <module>
    lastRowId = getContent(bs, lastRowId)
  File "C:/Users/admin/PycharmProjects/hanapsalita-data/tagalog-pinoydictionary-scrape.py", line 102, in getContent
    lastRowId = pushToDatabases(conn, cur, "tagalog_words", jsonDatabase, lastRowId, word, wordLength,
  File "C:\Users\admin\PycharmProjects\hanapsalita-data\scrapeUtils.py", line 184, in pushToDatabases
    lastRowID = pushToMySQL(conn, cur, lastRowId, word, wordLength, category, alphaSorted,
  File "C:\Users\admin\PycharmProjects\hanapsalita-data\scrapeUtils.py", line 157, in pushToMySQL
    raise Exception("`lastRowId3` and `lastRowId4` mismatch")
Exception: `lastRowId3` and `lastRowId4` mismatch

~~~~~~~~~~~~~~~ 2022/07/04 15:58:08 ~~~~~~~~~~~~~~~
Traceback (most recent call last):
  File "C:\Users\admin\PycharmProjects\hanapsalita-data\venv\lib\site-packages\mysql\connector\connection_cext.py", line 535, in cmd_query
    self._cmysql.query(query,
_mysql_connector.MySQLInterfaceError: Cannot add or update a child row: a foreign key constraint fails (`hanapsalita`.`tagalog_start`, CONSTRAINT `tagalog_start_id_fk` FOREIGN KEY (`id`) REFERENCES `tagalog_words` (`id`) ON DELETE CASCADE ON UPDATE CASCADE)

During handling of the above exception, another exception occurred:

Traceback (most recent call last):
  File "C:/Users/admin/PycharmProjects/hanapsalita-data/tagalog-pinoydictionary-scrape.py", line 164, in <module>
    lastRowId = getContent(bs, lastRowId)
  File "C:/Users/admin/PycharmProjects/hanapsalita-data/tagalog-pinoydictionary-scrape.py", line 102, in getContent
    lastRowId = pushToDatabases(conn, cur, "tagalog_words", jsonDatabase, lastRowId, word, wordLength,
  File "C:\Users\admin\PycharmProjects\hanapsalita-data\scrapeUtils.py", line 184, in pushToDatabases
    lastRowID = pushToMySQL(conn, cur, lastRowId, word, wordLength, category, alphaSorted,
  File "C:\Users\admin\PycharmProjects\hanapsalita-data\scrapeUtils.py", line 126, in pushToMySQL
    cur.execute(tagalogStartSQL, tagalogStartValues)
  File "C:\Users\admin\PycharmProjects\hanapsalita-data\venv\lib\site-packages\mysql\connector\cursor_cext.py", line 269, in execute
    result = self._cnx.cmd_query(stmt, raw=self._raw,
  File "C:\Users\admin\PycharmProjects\hanapsalita-data\venv\lib\site-packages\mysql\connector\connection_cext.py", line 540, in cmd_query
    raise errors.get_mysql_exception(exc.errno, msg=exc.msg,
mysql.connector.errors.IntegrityError: 1452 (23000): Cannot add or update a child row: a foreign key constraint fails (`hanapsalita`.`tagalog_start`, CONSTRAINT `tagalog_start_id_fk` FOREIGN KEY (`id`) REFERENCES `tagalog_words` (`id`) ON DELETE CASCADE ON UPDATE CASCADE)

~~~~~~~~~~~~~~~ 2022/07/04 16:00:50 ~~~~~~~~~~~~~~~
Traceback (most recent call last):
  File "C:\Users\admin\PycharmProjects\hanapsalita-data\venv\lib\site-packages\mysql\connector\connection_cext.py", line 535, in cmd_query
    self._cmysql.query(query,
_mysql_connector.MySQLInterfaceError: Cannot add or update a child row: a foreign key constraint fails (`hanapsalita`.`tagalog_start`, CONSTRAINT `tagalog_start_id_fk` FOREIGN KEY (`id`) REFERENCES `tagalog_words` (`id`) ON DELETE CASCADE ON UPDATE CASCADE)

During handling of the above exception, another exception occurred:

Traceback (most recent call last):
  File "C:/Users/admin/PycharmProjects/hanapsalita-data/tagalog-pinoydictionary-scrape.py", line 164, in <module>
    lastRowId = getContent(bs, lastRowId)
  File "C:/Users/admin/PycharmProjects/hanapsalita-data/tagalog-pinoydictionary-scrape.py", line 102, in getContent
    lastRowId = pushToDatabases(conn, cur, "tagalog_words", jsonDatabase, lastRowId, word, wordLength,
  File "C:\Users\admin\PycharmProjects\hanapsalita-data\scrapeUtils.py", line 184, in pushToDatabases
    lastRowID = pushToMySQL(conn, cur, lastRowId, word, wordLength, category, alphaSorted,
  File "C:\Users\admin\PycharmProjects\hanapsalita-data\scrapeUtils.py", line 126, in pushToMySQL
    cur.execute(tagalogStartSQL, tagalogStartValues)
  File "C:\Users\admin\PycharmProjects\hanapsalita-data\venv\lib\site-packages\mysql\connector\cursor_cext.py", line 269, in execute
    result = self._cnx.cmd_query(stmt, raw=self._raw,
  File "C:\Users\admin\PycharmProjects\hanapsalita-data\venv\lib\site-packages\mysql\connector\connection_cext.py", line 540, in cmd_query
    raise errors.get_mysql_exception(exc.errno, msg=exc.msg,
mysql.connector.errors.IntegrityError: 1452 (23000): Cannot add or update a child row: a foreign key constraint fails (`hanapsalita`.`tagalog_start`, CONSTRAINT `tagalog_start_id_fk` FOREIGN KEY (`id`) REFERENCES `tagalog_words` (`id`) ON DELETE CASCADE ON UPDATE CASCADE)

~~~~~~~~~~~~~~~ 2022/07/04 16:09:33 ~~~~~~~~~~~~~~~
Traceback (most recent call last):
  File "C:/Users/admin/PycharmProjects/hanapsalita-data/tagalog-pinoydictionary-scrape.py", line 164, in <module>
    lastRowId = getContent(bs, lastRowId)
  File "C:/Users/admin/PycharmProjects/hanapsalita-data/tagalog-pinoydictionary-scrape.py", line 102, in getContent
    lastRowId = pushToDatabases(conn, cur, "tagalog_words", jsonDatabase, lastRowId, word, wordLength,
  File "C:\Users\admin\PycharmProjects\hanapsalita-data\scrapeUtils.py", line 184, in pushToDatabases
    alphaSortedWithoutDashes, alphaSortedNoDuplicatesWithoutDashes)
  File "C:\Users\admin\PycharmProjects\hanapsalita-data\scrapeUtils.py", line 157, in pushToMySQL
  File "C:\Users\admin\PycharmProjects\hanapsalita-data\scrapeUtils.py", line 157, in pushToMySQL
  File "_pydevd_bundle\pydevd_cython_win32_39_64.pyx", line 1179, in _pydevd_bundle.pydevd_cython_win32_39_64.SafeCallWrapper.__call__
  File "_pydevd_bundle\pydevd_cython_win32_39_64.pyx", line 620, in _pydevd_bundle.pydevd_cython_win32_39_64.PyDBFrame.trace_dispatch
  File "_pydevd_bundle\pydevd_cython_win32_39_64.pyx", line 1095, in _pydevd_bundle.pydevd_cython_win32_39_64.PyDBFrame.trace_dispatch
  File "_pydevd_bundle\pydevd_cython_win32_39_64.pyx", line 1057, in _pydevd_bundle.pydevd_cython_win32_39_64.PyDBFrame.trace_dispatch
  File "_pydevd_bundle\pydevd_cython_win32_39_64.pyx", line 317, in _pydevd_bundle.pydevd_cython_win32_39_64.PyDBFrame.do_wait_suspend
  File "C:\Program Files\JetBrains\PyCharm 2022.1\plugins\python\helpers\pydev\pydevd.py", line 1155, in do_wait_suspend
    self._do_wait_suspend(thread, frame, event, arg, suspend_type, from_this_thread)
  File "C:\Program Files\JetBrains\PyCharm 2022.1\plugins\python\helpers\pydev\pydevd.py", line 1170, in _do_wait_suspend
    time.sleep(0.01)
KeyboardInterrupt

~~~~~~~~~~~~~~~ 2022/07/04 16:21:05 ~~~~~~~~~~~~~~~
Traceback (most recent call last):
  File "C:/Users/admin/PycharmProjects/hanapsalita-data/tagalog-pinoydictionary-scrape.py", line 164, in <module>
    lastRowId = getContent(bs, lastRowId)
  File "C:/Users/admin/PycharmProjects/hanapsalita-data/tagalog-pinoydictionary-scrape.py", line 102, in getContent
    lastRowId = pushToDatabases(conn, cur, "tagalog_words", jsonDatabase, lastRowId, word, wordLength,
  File "C:\Users\admin\PycharmProjects\hanapsalita-data\scrapeUtils.py", line 182, in pushToDatabases
    lastRowID = pushToMySQL(conn, cur, lastRowId, word, wordLength, category, alphaSorted,
  File "C:\Users\admin\PycharmProjects\hanapsalita-data\scrapeUtils.py", line 125, in pushToMySQL
    tagalogStartValues = [lastRowId1] + startingsWithoutPunctuations
TypeError: can only concatenate list (not "tuple") to list

~~~~~~~~~~~~~~~ 2022/07/04 16:24:31 ~~~~~~~~~~~~~~~
Traceback (most recent call last):
  File "C:\Users\admin\PycharmProjects\hanapsalita-data\venv\lib\site-packages\urllib3\connectionpool.py", line 703, in urlopen
    httplib_response = self._make_request(
  File "C:\Users\admin\PycharmProjects\hanapsalita-data\venv\lib\site-packages\urllib3\connectionpool.py", line 386, in _make_request
    self._validate_conn(conn)
  File "C:\Users\admin\PycharmProjects\hanapsalita-data\venv\lib\site-packages\urllib3\connectionpool.py", line 1040, in _validate_conn
    conn.connect()
  File "C:\Users\admin\PycharmProjects\hanapsalita-data\venv\lib\site-packages\urllib3\connection.py", line 414, in connect
    self.sock = ssl_wrap_socket(
  File "C:\Users\admin\PycharmProjects\hanapsalita-data\venv\lib\site-packages\urllib3\util\ssl_.py", line 449, in ssl_wrap_socket
    ssl_sock = _ssl_wrap_socket_impl(
  File "C:\Users\admin\PycharmProjects\hanapsalita-data\venv\lib\site-packages\urllib3\util\ssl_.py", line 493, in _ssl_wrap_socket_impl
    return ssl_context.wrap_socket(sock, server_hostname=server_hostname)
  File "C:\Users\admin\AppData\Local\Programs\Python\Python39\lib\ssl.py", line 500, in wrap_socket
    return self.sslsocket_class._create(
  File "C:\Users\admin\AppData\Local\Programs\Python\Python39\lib\ssl.py", line 1040, in _create
    self.do_handshake()
  File "C:\Users\admin\AppData\Local\Programs\Python\Python39\lib\ssl.py", line 1309, in do_handshake
    self._sslobj.do_handshake()
ConnectionResetError: [WinError 10054] An existing connection was forcibly closed by the remote host

During handling of the above exception, another exception occurred:

Traceback (most recent call last):
  File "C:\Users\admin\PycharmProjects\hanapsalita-data\venv\lib\site-packages\requests\adapters.py", line 489, in send
    resp = conn.urlopen(
  File "C:\Users\admin\PycharmProjects\hanapsalita-data\venv\lib\site-packages\urllib3\connectionpool.py", line 785, in urlopen
    retries = retries.increment(
  File "C:\Users\admin\PycharmProjects\hanapsalita-data\venv\lib\site-packages\urllib3\util\retry.py", line 550, in increment
    raise six.reraise(type(error), error, _stacktrace)
  File "C:\Users\admin\PycharmProjects\hanapsalita-data\venv\lib\site-packages\urllib3\packages\six.py", line 769, in reraise
    raise value.with_traceback(tb)
  File "C:\Users\admin\PycharmProjects\hanapsalita-data\venv\lib\site-packages\urllib3\connectionpool.py", line 703, in urlopen
    httplib_response = self._make_request(
  File "C:\Users\admin\PycharmProjects\hanapsalita-data\venv\lib\site-packages\urllib3\connectionpool.py", line 386, in _make_request
    self._validate_conn(conn)
  File "C:\Users\admin\PycharmProjects\hanapsalita-data\venv\lib\site-packages\urllib3\connectionpool.py", line 1040, in _validate_conn
    conn.connect()
  File "C:\Users\admin\PycharmProjects\hanapsalita-data\venv\lib\site-packages\urllib3\connection.py", line 414, in connect
    self.sock = ssl_wrap_socket(
  File "C:\Users\admin\PycharmProjects\hanapsalita-data\venv\lib\site-packages\urllib3\util\ssl_.py", line 449, in ssl_wrap_socket
    ssl_sock = _ssl_wrap_socket_impl(
  File "C:\Users\admin\PycharmProjects\hanapsalita-data\venv\lib\site-packages\urllib3\util\ssl_.py", line 493, in _ssl_wrap_socket_impl
    return ssl_context.wrap_socket(sock, server_hostname=server_hostname)
  File "C:\Users\admin\AppData\Local\Programs\Python\Python39\lib\ssl.py", line 500, in wrap_socket
    return self.sslsocket_class._create(
  File "C:\Users\admin\AppData\Local\Programs\Python\Python39\lib\ssl.py", line 1040, in _create
    self.do_handshake()
  File "C:\Users\admin\AppData\Local\Programs\Python\Python39\lib\ssl.py", line 1309, in do_handshake
    self._sslobj.do_handshake()
urllib3.exceptions.ProtocolError: ('Connection aborted.', ConnectionResetError(10054, 'An existing connection was forcibly closed by the remote host', None, 10054, None))

During handling of the above exception, another exception occurred:

Traceback (most recent call last):
  File "C:/Users/admin/PycharmProjects/hanapsalita-data/tagalog-pinoydictionary-scrape.py", line 139, in <module>
    bs = getPage(searchUrl + letter)
  File "C:/Users/admin/PycharmProjects/hanapsalita-data/tagalog-pinoydictionary-scrape.py", line 38, in getPage
    req = requests.get(url)
  File "C:\Users\admin\PycharmProjects\hanapsalita-data\venv\lib\site-packages\requests\api.py", line 73, in get
    return request("get", url, params=params, **kwargs)
  File "C:\Users\admin\PycharmProjects\hanapsalita-data\venv\lib\site-packages\requests\api.py", line 59, in request
    return session.request(method=method, url=url, **kwargs)
  File "C:\Users\admin\PycharmProjects\hanapsalita-data\venv\lib\site-packages\requests\sessions.py", line 587, in request
    resp = self.send(prep, **send_kwargs)
  File "C:\Users\admin\PycharmProjects\hanapsalita-data\venv\lib\site-packages\requests\sessions.py", line 701, in send
    r = adapter.send(request, **kwargs)
  File "C:\Users\admin\PycharmProjects\hanapsalita-data\venv\lib\site-packages\requests\adapters.py", line 547, in send
    raise ConnectionError(err, request=request)
requests.exceptions.ConnectionError: ('Connection aborted.', ConnectionResetError(10054, 'An existing connection was forcibly closed by the remote host', None, 10054, None))

~~~~~~~~~~~~~~~ 2022/07/04 16:27:11 ~~~~~~~~~~~~~~~
Traceback (most recent call last):
  File "C:/Users/admin/PycharmProjects/hanapsalita-data/tagalog-pinoydictionary-scrape.py", line 164, in <module>
    lastRowId = getContent(bs, lastRowId)
  File "C:/Users/admin/PycharmProjects/hanapsalita-data/tagalog-pinoydictionary-scrape.py", line 102, in getContent
    lastRowId = pushToDatabases(conn, cur, "tagalog_words", jsonDatabase, lastRowId, word, wordLength,
  File "C:\Users\admin\PycharmProjects\hanapsalita-data\scrapeUtils.py", line 182, in pushToDatabases
    lastRowID = pushToMySQL(conn, cur, lastRowId, word, wordLength, category, alphaSorted,
  File "C:\Users\admin\PycharmProjects\hanapsalita-data\scrapeUtils.py", line 130, in pushToMySQL
    raise Exception("`lastRowId1` and `lastRowId2` mismatch")
Exception: `lastRowId1` and `lastRowId2` mismatch

~~~~~~~~~~~~~~~ 2022/07/04 16:30:22 ~~~~~~~~~~~~~~~
Traceback (most recent call last):
  File "C:/Users/admin/PycharmProjects/hanapsalita-data/tagalog-pinoydictionary-scrape.py", line 164, in <module>
    lastRowId = getContent(bs, lastRowId)
  File "C:/Users/admin/PycharmProjects/hanapsalita-data/tagalog-pinoydictionary-scrape.py", line 102, in getContent
    lastRowId = pushToDatabases(conn, cur, "tagalog_words", jsonDatabase, lastRowId, word, wordLength,
  File "C:\Users\admin\PycharmProjects\hanapsalita-data\scrapeUtils.py", line 182, in pushToDatabases
    lastRowID = pushToMySQL(conn, cur, lastRowId, word, wordLength, category, alphaSorted,
  File "C:\Users\admin\PycharmProjects\hanapsalita-data\scrapeUtils.py", line 118, in pushToMySQL
    print(f"lastRowId1 = {lastRowId1}")
  File "C:\Users\admin\PycharmProjects\hanapsalita-data\scrapeUtils.py", line 118, in pushToMySQL
    print(f"lastRowId1 = {lastRowId1}")
  File "_pydevd_bundle\pydevd_cython_win32_39_64.pyx", line 1179, in _pydevd_bundle.pydevd_cython_win32_39_64.SafeCallWrapper.__call__
  File "_pydevd_bundle\pydevd_cython_win32_39_64.pyx", line 620, in _pydevd_bundle.pydevd_cython_win32_39_64.PyDBFrame.trace_dispatch
  File "_pydevd_bundle\pydevd_cython_win32_39_64.pyx", line 1095, in _pydevd_bundle.pydevd_cython_win32_39_64.PyDBFrame.trace_dispatch
  File "_pydevd_bundle\pydevd_cython_win32_39_64.pyx", line 1057, in _pydevd_bundle.pydevd_cython_win32_39_64.PyDBFrame.trace_dispatch
  File "_pydevd_bundle\pydevd_cython_win32_39_64.pyx", line 317, in _pydevd_bundle.pydevd_cython_win32_39_64.PyDBFrame.do_wait_suspend
  File "C:\Program Files\JetBrains\PyCharm 2022.1\plugins\python\helpers\pydev\pydevd.py", line 1155, in do_wait_suspend
    self._do_wait_suspend(thread, frame, event, arg, suspend_type, from_this_thread)
  File "C:\Program Files\JetBrains\PyCharm 2022.1\plugins\python\helpers\pydev\pydevd.py", line 1170, in _do_wait_suspend
    time.sleep(0.01)
KeyboardInterrupt

~~~~~~~~~~~~~~~ 2022/07/04 18:28:19 ~~~~~~~~~~~~~~~
Traceback (most recent call last):
  File "C:\Users\admin\PycharmProjects\hanapsalita-data\venv\lib\site-packages\mysql\connector\cursor_cext.py", line 66, in __call__
    return self.params[index]
IndexError: tuple index out of range

During handling of the above exception, another exception occurred:

Traceback (most recent call last):
  File "C:/Users/admin/PycharmProjects/hanapsalita-data/tagalog-pinoydictionary-scrape.py", line 164, in <module>
    lastRowId = getContent(bs, lastRowId)
  File "C:/Users/admin/PycharmProjects/hanapsalita-data/tagalog-pinoydictionary-scrape.py", line 117, in getContent
    lastRowId = pushToDatabases(conn, cur, "tagalog_words", jsonDatabase, lastRowId, conjugation,
  File "C:\Users\admin\PycharmProjects\hanapsalita-data\scrapeUtils.py", line 182, in pushToDatabases
    lastRowID = pushToMySQL(conn, cur, lastRowId, word, wordLength, category, alphaSorted,
  File "C:\Users\admin\PycharmProjects\hanapsalita-data\scrapeUtils.py", line 126, in pushToMySQL
    cur.execute(tagalogStartSQL, tagalogStartValues)
  File "C:\Users\admin\PycharmProjects\hanapsalita-data\venv\lib\site-packages\mysql\connector\cursor_cext.py", line 263, in execute
    stmt = RE_PY_PARAM.sub(psub, stmt)
  File "C:\Users\admin\PycharmProjects\hanapsalita-data\venv\lib\site-packages\mysql\connector\cursor_cext.py", line 68, in __call__
    raise errors.ProgrammingError(
mysql.connector.errors.ProgrammingError: Not enough parameters for the SQL statement

~~~~~~~~~~~~~~~ 2022/07/04 19:05:03 ~~~~~~~~~~~~~~~
Traceback (most recent call last):
  File "C:/Users/admin/PycharmProjects/hanapsalita-data/tagalog-pinoydictionary-scrape.py", line 165, in <module>
    lastRowId = getContent(bs, lastRowId)
  File "C:/Users/admin/PycharmProjects/hanapsalita-data/tagalog-pinoydictionary-scrape.py", line 103, in getContent
    lastRowId = pushToDatabases(conn, cur, "tagalog_words", jsonDatabase, wordsJsonFilename, lastRowId, word, wordLength,
  File "C:\Users\admin\PycharmProjects\hanapsalita-data\scrapeUtils.py", line 186, in pushToDatabases
  File "C:\Users\admin\PycharmProjects\hanapsalita-data\scrapeUtils.py", line 160, in pushToMySQL
    jsonDatabase["data"][word]["alpha_sorted_no_duplicates"] = alpha_sorted_no_duplicates
  File "C:\Users\admin\PycharmProjects\hanapsalita-data\scrapeUtils.py", line 160, in pushToMySQL
    jsonDatabase["data"][word]["alpha_sorted_no_duplicates"] = alpha_sorted_no_duplicates
  File "_pydevd_bundle\pydevd_cython_win32_39_64.pyx", line 1179, in _pydevd_bundle.pydevd_cython_win32_39_64.SafeCallWrapper.__call__
  File "_pydevd_bundle\pydevd_cython_win32_39_64.pyx", line 620, in _pydevd_bundle.pydevd_cython_win32_39_64.PyDBFrame.trace_dispatch
  File "_pydevd_bundle\pydevd_cython_win32_39_64.pyx", line 1095, in _pydevd_bundle.pydevd_cython_win32_39_64.PyDBFrame.trace_dispatch
  File "_pydevd_bundle\pydevd_cython_win32_39_64.pyx", line 1057, in _pydevd_bundle.pydevd_cython_win32_39_64.PyDBFrame.trace_dispatch
  File "_pydevd_bundle\pydevd_cython_win32_39_64.pyx", line 317, in _pydevd_bundle.pydevd_cython_win32_39_64.PyDBFrame.do_wait_suspend
  File "C:\Program Files\JetBrains\PyCharm 2022.1\plugins\python\helpers\pydev\pydevd.py", line 1155, in do_wait_suspend
    self._do_wait_suspend(thread, frame, event, arg, suspend_type, from_this_thread)
  File "C:\Program Files\JetBrains\PyCharm 2022.1\plugins\python\helpers\pydev\pydevd.py", line 1170, in _do_wait_suspend
    time.sleep(0.01)
KeyboardInterrupt

~~~~~~~~~~~~~~~ 2022/07/04 19:14:50 ~~~~~~~~~~~~~~~
Traceback (most recent call last):
  File "C:/Users/admin/PycharmProjects/hanapsalita-data/tagalog-pinoydictionary-scrape.py", line 165, in <module>
    bs = getPage(url)
  File "C:/Users/admin/PycharmProjects/hanapsalita-data/tagalog-pinoydictionary-scrape.py", line 99, in getContent
    if not wordAlreadyStored(cur, "tagalog_words", word):
  File "C:\Users\admin\PycharmProjects\hanapsalita-data\scrapeUtils.py", line 43, in getConstituents
    wordLength = len(word)
  File "C:\Users\admin\PycharmProjects\hanapsalita-data\scrapeUtils.py", line 43, in getConstituents
    wordLength = len(word)
  File "_pydevd_bundle\pydevd_cython_win32_39_64.pyx", line 1179, in _pydevd_bundle.pydevd_cython_win32_39_64.SafeCallWrapper.__call__
  File "_pydevd_bundle\pydevd_cython_win32_39_64.pyx", line 620, in _pydevd_bundle.pydevd_cython_win32_39_64.PyDBFrame.trace_dispatch
  File "_pydevd_bundle\pydevd_cython_win32_39_64.pyx", line 1095, in _pydevd_bundle.pydevd_cython_win32_39_64.PyDBFrame.trace_dispatch
  File "_pydevd_bundle\pydevd_cython_win32_39_64.pyx", line 1057, in _pydevd_bundle.pydevd_cython_win32_39_64.PyDBFrame.trace_dispatch
  File "_pydevd_bundle\pydevd_cython_win32_39_64.pyx", line 317, in _pydevd_bundle.pydevd_cython_win32_39_64.PyDBFrame.do_wait_suspend
  File "C:\Program Files\JetBrains\PyCharm 2022.1\plugins\python\helpers\pydev\pydevd.py", line 1155, in do_wait_suspend
    self._do_wait_suspend(thread, frame, event, arg, suspend_type, from_this_thread)
  File "C:\Program Files\JetBrains\PyCharm 2022.1\plugins\python\helpers\pydev\pydevd.py", line 1170, in _do_wait_suspend
    time.sleep(0.01)
KeyboardInterrupt

~~~~~~~~~~~~~~~ 2022/07/04 20:39:36 ~~~~~~~~~~~~~~~
Traceback (most recent call last):
  File "C:/Users/admin/PycharmProjects/hanapsalita-data/tagalog-pinoydictionary-scrape.py", line 153, in <module>
    if not lastPageNumRetrieved:  # if `bs` is already retrieved or not (i.e. defined or not)
  File "C:/Users/admin/PycharmProjects/hanapsalita-data/tagalog-pinoydictionary-scrape.py", line 153, in <module>
    if not lastPageNumRetrieved:  # if `bs` is already retrieved or not (i.e. defined or not)
  File "_pydevd_bundle\pydevd_cython_win32_39_64.pyx", line 1179, in _pydevd_bundle.pydevd_cython_win32_39_64.SafeCallWrapper.__call__
  File "_pydevd_bundle\pydevd_cython_win32_39_64.pyx", line 620, in _pydevd_bundle.pydevd_cython_win32_39_64.PyDBFrame.trace_dispatch
  File "_pydevd_bundle\pydevd_cython_win32_39_64.pyx", line 1095, in _pydevd_bundle.pydevd_cython_win32_39_64.PyDBFrame.trace_dispatch
  File "_pydevd_bundle\pydevd_cython_win32_39_64.pyx", line 1057, in _pydevd_bundle.pydevd_cython_win32_39_64.PyDBFrame.trace_dispatch
  File "_pydevd_bundle\pydevd_cython_win32_39_64.pyx", line 317, in _pydevd_bundle.pydevd_cython_win32_39_64.PyDBFrame.do_wait_suspend
  File "C:\Program Files\JetBrains\PyCharm 2022.1\plugins\python\helpers\pydev\pydevd.py", line 1155, in do_wait_suspend
    self._do_wait_suspend(thread, frame, event, arg, suspend_type, from_this_thread)
  File "C:\Program Files\JetBrains\PyCharm 2022.1\plugins\python\helpers\pydev\pydevd.py", line 1170, in _do_wait_suspend
    time.sleep(0.01)
KeyboardInterrupt

~~~~~~~~~~~~~~~ 2022/07/04 20:52:03 ~~~~~~~~~~~~~~~
Traceback (most recent call last):
  File "C:/Users/admin/PycharmProjects/hanapsalita-data/tagalog-pinoydictionary-scrape.py", line 157, in <module>
    bs = getPage(url)
  File "C:/Users/admin/PycharmProjects/hanapsalita-data/tagalog-pinoydictionary-scrape.py", line 40, in getPage
    req = requests.get(url)
  File "C:\Users\admin\PycharmProjects\hanapsalita-data\venv\lib\site-packages\requests\api.py", line 73, in get
    return request("get", url, params=params, **kwargs)
  File "C:\Users\admin\PycharmProjects\hanapsalita-data\venv\lib\site-packages\requests\api.py", line 59, in request
    return session.request(method=method, url=url, **kwargs)
  File "C:\Users\admin\PycharmProjects\hanapsalita-data\venv\lib\site-packages\requests\sessions.py", line 587, in request
    resp = self.send(prep, **send_kwargs)
  File "C:\Users\admin\PycharmProjects\hanapsalita-data\venv\lib\site-packages\requests\sessions.py", line 701, in send
    r = adapter.send(request, **kwargs)
  File "C:\Users\admin\PycharmProjects\hanapsalita-data\venv\lib\site-packages\requests\adapters.py", line 489, in send
    resp = conn.urlopen(
  File "C:\Users\admin\PycharmProjects\hanapsalita-data\venv\lib\site-packages\urllib3\connectionpool.py", line 703, in urlopen
    httplib_response = self._make_request(
  File "C:\Users\admin\PycharmProjects\hanapsalita-data\venv\lib\site-packages\urllib3\connectionpool.py", line 386, in _make_request
    self._validate_conn(conn)
  File "C:\Users\admin\PycharmProjects\hanapsalita-data\venv\lib\site-packages\urllib3\connectionpool.py", line 1040, in _validate_conn
    conn.connect()
  File "C:\Users\admin\PycharmProjects\hanapsalita-data\venv\lib\site-packages\urllib3\connection.py", line 414, in connect
    self.sock = ssl_wrap_socket(
  File "C:\Users\admin\PycharmProjects\hanapsalita-data\venv\lib\site-packages\urllib3\util\ssl_.py", line 449, in ssl_wrap_socket
    ssl_sock = _ssl_wrap_socket_impl(
  File "C:\Users\admin\PycharmProjects\hanapsalita-data\venv\lib\site-packages\urllib3\util\ssl_.py", line 493, in _ssl_wrap_socket_impl
    return ssl_context.wrap_socket(sock, server_hostname=server_hostname)
  File "C:\Users\admin\AppData\Local\Programs\Python\Python39\lib\ssl.py", line 500, in wrap_socket
    return self.sslsocket_class._create(
  File "C:\Users\admin\AppData\Local\Programs\Python\Python39\lib\ssl.py", line 1040, in _create
    self.do_handshake()
  File "C:\Users\admin\AppData\Local\Programs\Python\Python39\lib\ssl.py", line 1309, in do_handshake
    self._sslobj.do_handshake()
KeyboardInterrupt

~~~~~~~~~~~~~~~ 2022/07/05 08:45:38 ~~~~~~~~~~~~~~~
Traceback (most recent call last):
  File "C:\Users\admin\PycharmProjects\hanapsalita-data\tagalog-pinoydictionary-scrape.py", line 158, in <module>
    lastRowId = getContent(bs, lastRowId)
  File "C:\Users\admin\PycharmProjects\hanapsalita-data\tagalog-pinoydictionary-scrape.py", line 102, in getContent
    lastRowId = pushToDatabases(*variablesToBePushed)
  File "C:\Users\admin\PycharmProjects\hanapsalita-data\scrapeUtils.py", line 174, in pushToDatabases
    lastRowID = pushToMySQL(conn, cur, lastRowId, word, category, wordLength, withDashes, alphaSortedWithoutDashes,
  File "C:\Users\admin\PycharmProjects\hanapsalita-data\scrapeUtils.py", line 146, in pushToMySQL
    cur.execute(tagalogContainSQL, tagalogConstituentsRowValues)
  File "C:\Users\admin\PycharmProjects\hanapsalita-data\venv\lib\site-packages\mysql\connector\cursor_cext.py", line 269, in execute
    result = self._cnx.cmd_query(stmt, raw=self._raw,
  File "C:\Users\admin\PycharmProjects\hanapsalita-data\venv\lib\site-packages\mysql\connector\connection_cext.py", line 535, in cmd_query
    self._cmysql.query(query,
KeyboardInterrupt

~~~~~~~~~~~~~~~ 2022/07/05 08:47:44 ~~~~~~~~~~~~~~~
Traceback (most recent call last):
  File "C:\Users\admin\PycharmProjects\hanapsalita-data\tagalog-pinoydictionary-scrape.py", line 158, in <module>
    lastRowId = getContent(bs, lastRowId)
  File "C:\Users\admin\PycharmProjects\hanapsalita-data\tagalog-pinoydictionary-scrape.py", line 102, in getContent
    lastRowId = pushToDatabases(*variablesToBePushed)
  File "C:\Users\admin\PycharmProjects\hanapsalita-data\scrapeUtils.py", line 174, in pushToDatabases
    lastRowID = pushToMySQL(conn, cur, lastRowId, word, category, wordLength, withDashes, alphaSortedWithoutDashes,
  File "C:\Users\admin\PycharmProjects\hanapsalita-data\scrapeUtils.py", line 133, in pushToMySQL
    cur.execute(tagalogEndSQL, tagalogEndValues)
  File "C:\Users\admin\PycharmProjects\hanapsalita-data\venv\lib\site-packages\mysql\connector\cursor_cext.py", line 269, in execute
    result = self._cnx.cmd_query(stmt, raw=self._raw,
  File "C:\Users\admin\PycharmProjects\hanapsalita-data\venv\lib\site-packages\mysql\connector\connection_cext.py", line 535, in cmd_query
    self._cmysql.query(query,
KeyboardInterrupt

~~~~~~~~~~~~~~~ 2022/07/05 08:49:46 ~~~~~~~~~~~~~~~
Traceback (most recent call last):
  File "C:\Users\admin\PycharmProjects\hanapsalita-data\tagalog-pinoydictionary-scrape.py", line 158, in <module>
    lastRowId = getContent(bs, lastRowId)
  File "C:\Users\admin\PycharmProjects\hanapsalita-data\tagalog-pinoydictionary-scrape.py", line 114, in getContent
    lastRowId = pushToDatabases(*variablesToBePushed)
  File "C:\Users\admin\PycharmProjects\hanapsalita-data\scrapeUtils.py", line 174, in pushToDatabases
    lastRowID = pushToMySQL(conn, cur, lastRowId, word, category, wordLength, withDashes, alphaSortedWithoutDashes,
  File "C:\Users\admin\PycharmProjects\hanapsalita-data\scrapeUtils.py", line 146, in pushToMySQL
    cur.execute(tagalogContainSQL, tagalogConstituentsRowValues)
  File "C:\Users\admin\PycharmProjects\hanapsalita-data\venv\lib\site-packages\mysql\connector\cursor_cext.py", line 269, in execute
    result = self._cnx.cmd_query(stmt, raw=self._raw,
  File "C:\Users\admin\PycharmProjects\hanapsalita-data\venv\lib\site-packages\mysql\connector\connection_cext.py", line 535, in cmd_query
    self._cmysql.query(query,
KeyboardInterrupt

~~~~~~~~~~~~~~~ 2022/07/05 08:50:29 ~~~~~~~~~~~~~~~
Traceback (most recent call last):
  File "C:\Users\admin\PycharmProjects\hanapsalita-data\cebuano-pinoydictionary-scrape.py", line 154, in <module>
    progressJson[letter]["stoppedAt"] = stoppedAt
KeyError: 'a'

~~~~~~~~~~~~~~~ 2022/07/05 09:05:19 ~~~~~~~~~~~~~~~
Traceback (most recent call last):
  File "C:/Users/admin/PycharmProjects/hanapsalita-data/cebuano-pinoydictionary-scrape.py", line 151, in <module>
    getContent(bs)
  File "C:/Users/admin/PycharmProjects/hanapsalita-data/cebuano-pinoydictionary-scrape.py", line 89, in getContent
    word = result.find("h2", class_="word-entry").get_text()
  File "C:/Users/admin/PycharmProjects/hanapsalita-data/cebuano-pinoydictionary-scrape.py", line 89, in getContent
    word = result.find("h2", class_="word-entry").get_text()
  File "_pydevd_bundle\pydevd_cython_win32_39_64.pyx", line 1179, in _pydevd_bundle.pydevd_cython_win32_39_64.SafeCallWrapper.__call__
  File "_pydevd_bundle\pydevd_cython_win32_39_64.pyx", line 620, in _pydevd_bundle.pydevd_cython_win32_39_64.PyDBFrame.trace_dispatch
  File "_pydevd_bundle\pydevd_cython_win32_39_64.pyx", line 1095, in _pydevd_bundle.pydevd_cython_win32_39_64.PyDBFrame.trace_dispatch
  File "_pydevd_bundle\pydevd_cython_win32_39_64.pyx", line 1057, in _pydevd_bundle.pydevd_cython_win32_39_64.PyDBFrame.trace_dispatch
  File "_pydevd_bundle\pydevd_cython_win32_39_64.pyx", line 317, in _pydevd_bundle.pydevd_cython_win32_39_64.PyDBFrame.do_wait_suspend
  File "C:\Program Files\JetBrains\PyCharm 2022.1\plugins\python\helpers\pydev\pydevd.py", line 1155, in do_wait_suspend
    self._do_wait_suspend(thread, frame, event, arg, suspend_type, from_this_thread)
  File "C:\Program Files\JetBrains\PyCharm 2022.1\plugins\python\helpers\pydev\pydevd.py", line 1170, in _do_wait_suspend
    time.sleep(0.01)
KeyboardInterrupt

~~~~~~~~~~~~~~~ 2022/07/05 09:06:44 ~~~~~~~~~~~~~~~
Traceback (most recent call last):
  File "C:\Users\admin\PycharmProjects\hanapsalita-data\cebuano-pinoydictionary-scrape.py", line 150, in <module>
    bs = getPage(url)
  File "C:\Users\admin\PycharmProjects\hanapsalita-data\cebuano-pinoydictionary-scrape.py", line 41, in getPage
    req = requests.get(url)
  File "C:\Users\admin\PycharmProjects\hanapsalita-data\venv\lib\site-packages\requests\api.py", line 73, in get
    return request("get", url, params=params, **kwargs)
  File "C:\Users\admin\PycharmProjects\hanapsalita-data\venv\lib\site-packages\requests\api.py", line 59, in request
    return session.request(method=method, url=url, **kwargs)
  File "C:\Users\admin\PycharmProjects\hanapsalita-data\venv\lib\site-packages\requests\sessions.py", line 587, in request
    resp = self.send(prep, **send_kwargs)
  File "C:\Users\admin\PycharmProjects\hanapsalita-data\venv\lib\site-packages\requests\sessions.py", line 701, in send
    r = adapter.send(request, **kwargs)
  File "C:\Users\admin\PycharmProjects\hanapsalita-data\venv\lib\site-packages\requests\adapters.py", line 489, in send
    resp = conn.urlopen(
  File "C:\Users\admin\PycharmProjects\hanapsalita-data\venv\lib\site-packages\urllib3\connectionpool.py", line 703, in urlopen
    httplib_response = self._make_request(
  File "C:\Users\admin\PycharmProjects\hanapsalita-data\venv\lib\site-packages\urllib3\connectionpool.py", line 449, in _make_request
    six.raise_from(e, None)
  File "<string>", line 3, in raise_from
  File "C:\Users\admin\PycharmProjects\hanapsalita-data\venv\lib\site-packages\urllib3\connectionpool.py", line 444, in _make_request
    httplib_response = conn.getresponse()
  File "C:\Users\admin\AppData\Local\Programs\Python\Python39\lib\http\client.py", line 1347, in getresponse
    response.begin()
  File "C:\Users\admin\AppData\Local\Programs\Python\Python39\lib\http\client.py", line 307, in begin
    version, status, reason = self._read_status()
  File "C:\Users\admin\AppData\Local\Programs\Python\Python39\lib\http\client.py", line 268, in _read_status
    line = str(self.fp.readline(_MAXLINE + 1), "iso-8859-1")
  File "C:\Users\admin\AppData\Local\Programs\Python\Python39\lib\socket.py", line 704, in readinto
    return self._sock.recv_into(b)
  File "C:\Users\admin\AppData\Local\Programs\Python\Python39\lib\ssl.py", line 1241, in recv_into
    return self.read(nbytes, buffer)
  File "C:\Users\admin\AppData\Local\Programs\Python\Python39\lib\ssl.py", line 1099, in read
    return self._sslobj.read(len, buffer)
KeyboardInterrupt

~~~~~~~~~~~~~~~ 2022/07/05 09:07:22 ~~~~~~~~~~~~~~~
Traceback (most recent call last):
  File "C:/Users/admin/PycharmProjects/hanapsalita-data/cebuano-pinoydictionary-scrape.py", line 141, in <module>
    lastPageNumRetrieved = True
  File "C:/Users/admin/PycharmProjects/hanapsalita-data/cebuano-pinoydictionary-scrape.py", line 141, in <module>
    lastPageNumRetrieved = True
  File "_pydevd_bundle\pydevd_cython_win32_39_64.pyx", line 1179, in _pydevd_bundle.pydevd_cython_win32_39_64.SafeCallWrapper.__call__
  File "_pydevd_bundle\pydevd_cython_win32_39_64.pyx", line 620, in _pydevd_bundle.pydevd_cython_win32_39_64.PyDBFrame.trace_dispatch
  File "_pydevd_bundle\pydevd_cython_win32_39_64.pyx", line 1095, in _pydevd_bundle.pydevd_cython_win32_39_64.PyDBFrame.trace_dispatch
  File "_pydevd_bundle\pydevd_cython_win32_39_64.pyx", line 1057, in _pydevd_bundle.pydevd_cython_win32_39_64.PyDBFrame.trace_dispatch
  File "_pydevd_bundle\pydevd_cython_win32_39_64.pyx", line 317, in _pydevd_bundle.pydevd_cython_win32_39_64.PyDBFrame.do_wait_suspend
  File "C:\Program Files\JetBrains\PyCharm 2022.1\plugins\python\helpers\pydev\pydevd.py", line 1155, in do_wait_suspend
    self._do_wait_suspend(thread, frame, event, arg, suspend_type, from_this_thread)
  File "C:\Program Files\JetBrains\PyCharm 2022.1\plugins\python\helpers\pydev\pydevd.py", line 1170, in _do_wait_suspend
    time.sleep(0.01)
KeyboardInterrupt

~~~~~~~~~~~~~~~ 2022/07/05 09:09:38 ~~~~~~~~~~~~~~~
Traceback (most recent call last):
  File "C:/Users/admin/PycharmProjects/hanapsalita-data/cebuano-pinoydictionary-scrape.py", line 150, in <module>
    bs = getPage(url)
  File "C:/Users/admin/PycharmProjects/hanapsalita-data/cebuano-pinoydictionary-scrape.py", line 150, in <module>
    bs = getPage(url)
  File "_pydevd_bundle\pydevd_cython_win32_39_64.pyx", line 1179, in _pydevd_bundle.pydevd_cython_win32_39_64.SafeCallWrapper.__call__
  File "_pydevd_bundle\pydevd_cython_win32_39_64.pyx", line 620, in _pydevd_bundle.pydevd_cython_win32_39_64.PyDBFrame.trace_dispatch
  File "_pydevd_bundle\pydevd_cython_win32_39_64.pyx", line 1095, in _pydevd_bundle.pydevd_cython_win32_39_64.PyDBFrame.trace_dispatch
  File "_pydevd_bundle\pydevd_cython_win32_39_64.pyx", line 1057, in _pydevd_bundle.pydevd_cython_win32_39_64.PyDBFrame.trace_dispatch
  File "_pydevd_bundle\pydevd_cython_win32_39_64.pyx", line 317, in _pydevd_bundle.pydevd_cython_win32_39_64.PyDBFrame.do_wait_suspend
  File "C:\Program Files\JetBrains\PyCharm 2022.1\plugins\python\helpers\pydev\pydevd.py", line 1155, in do_wait_suspend
    self._do_wait_suspend(thread, frame, event, arg, suspend_type, from_this_thread)
  File "C:\Program Files\JetBrains\PyCharm 2022.1\plugins\python\helpers\pydev\pydevd.py", line 1170, in _do_wait_suspend
    time.sleep(0.01)
KeyboardInterrupt

~~~~~~~~~~~~~~~ 2022/07/05 09:11:19 ~~~~~~~~~~~~~~~
Traceback (most recent call last):
  File "C:\Users\admin\PycharmProjects\hanapsalita-data\cebuano-pinoydictionary-scrape.py", line 151, in <module>
    bs = getPage(url)
  File "C:\Users\admin\PycharmProjects\hanapsalita-data\cebuano-pinoydictionary-scrape.py", line 41, in getPage
    req = requests.get(url)
  File "C:\Users\admin\PycharmProjects\hanapsalita-data\venv\lib\site-packages\requests\api.py", line 73, in get
    return request("get", url, params=params, **kwargs)
  File "C:\Users\admin\PycharmProjects\hanapsalita-data\venv\lib\site-packages\requests\api.py", line 59, in request
    return session.request(method=method, url=url, **kwargs)
  File "C:\Users\admin\PycharmProjects\hanapsalita-data\venv\lib\site-packages\requests\sessions.py", line 587, in request
    resp = self.send(prep, **send_kwargs)
  File "C:\Users\admin\PycharmProjects\hanapsalita-data\venv\lib\site-packages\requests\sessions.py", line 701, in send
    r = adapter.send(request, **kwargs)
  File "C:\Users\admin\PycharmProjects\hanapsalita-data\venv\lib\site-packages\requests\adapters.py", line 489, in send
    resp = conn.urlopen(
  File "C:\Users\admin\PycharmProjects\hanapsalita-data\venv\lib\site-packages\urllib3\connectionpool.py", line 703, in urlopen
    httplib_response = self._make_request(
  File "C:\Users\admin\PycharmProjects\hanapsalita-data\venv\lib\site-packages\urllib3\connectionpool.py", line 449, in _make_request
    six.raise_from(e, None)
  File "<string>", line 3, in raise_from
  File "C:\Users\admin\PycharmProjects\hanapsalita-data\venv\lib\site-packages\urllib3\connectionpool.py", line 444, in _make_request
    httplib_response = conn.getresponse()
  File "C:\Users\admin\AppData\Local\Programs\Python\Python39\lib\http\client.py", line 1347, in getresponse
    response.begin()
  File "C:\Users\admin\AppData\Local\Programs\Python\Python39\lib\http\client.py", line 307, in begin
    version, status, reason = self._read_status()
  File "C:\Users\admin\AppData\Local\Programs\Python\Python39\lib\http\client.py", line 268, in _read_status
    line = str(self.fp.readline(_MAXLINE + 1), "iso-8859-1")
  File "C:\Users\admin\AppData\Local\Programs\Python\Python39\lib\socket.py", line 704, in readinto
    return self._sock.recv_into(b)
  File "C:\Users\admin\AppData\Local\Programs\Python\Python39\lib\ssl.py", line 1241, in recv_into
    return self.read(nbytes, buffer)
  File "C:\Users\admin\AppData\Local\Programs\Python\Python39\lib\ssl.py", line 1099, in read
    return self._sslobj.read(len, buffer)
KeyboardInterrupt

~~~~~~~~~~~~~~~ 2022/07/05 09:12:29 ~~~~~~~~~~~~~~~
Traceback (most recent call last):
  File "C:\Users\admin\PycharmProjects\hanapsalita-data\tagalog-pinoydictionary-scrape.py", line 160, in <module>
    lastRowId = getContent(bs, lastRowId)
  File "C:\Users\admin\PycharmProjects\hanapsalita-data\tagalog-pinoydictionary-scrape.py", line 103, in getContent
    lastRowId = pushToDatabases(*variablesToBePushed)
  File "C:\Users\admin\PycharmProjects\hanapsalita-data\scrapeUtils.py", line 174, in pushToDatabases
    lastRowID = pushToMySQL(conn, cur, lastRowId, word, category, wordLength, withDashes, alphaSortedWithoutDashes,
  File "C:\Users\admin\PycharmProjects\hanapsalita-data\scrapeUtils.py", line 133, in pushToMySQL
    cur.execute(tagalogEndSQL, tagalogEndValues)
  File "C:\Users\admin\PycharmProjects\hanapsalita-data\venv\lib\site-packages\mysql\connector\cursor_cext.py", line 269, in execute
    result = self._cnx.cmd_query(stmt, raw=self._raw,
  File "C:\Users\admin\PycharmProjects\hanapsalita-data\venv\lib\site-packages\mysql\connector\connection_cext.py", line 535, in cmd_query
    self._cmysql.query(query,
KeyboardInterrupt

~~~~~~~~~~~~~~~ 2022/07/05 09:30:30 ~~~~~~~~~~~~~~~
Traceback (most recent call last):
  File "C:\Users\admin\PycharmProjects\hanapsalita-data\cebuano-pinoydictionary-scrape.py", line 155, in <module>
    bs = getPage(url)
  File "C:\Users\admin\PycharmProjects\hanapsalita-data\cebuano-pinoydictionary-scrape.py", line 43, in getPage
    req = requests.get(url)
  File "C:\Users\admin\PycharmProjects\hanapsalita-data\venv\lib\site-packages\requests\api.py", line 73, in get
    return request("get", url, params=params, **kwargs)
  File "C:\Users\admin\PycharmProjects\hanapsalita-data\venv\lib\site-packages\requests\api.py", line 59, in request
    return session.request(method=method, url=url, **kwargs)
  File "C:\Users\admin\PycharmProjects\hanapsalita-data\venv\lib\site-packages\requests\sessions.py", line 587, in request
    resp = self.send(prep, **send_kwargs)
  File "C:\Users\admin\PycharmProjects\hanapsalita-data\venv\lib\site-packages\requests\sessions.py", line 701, in send
    r = adapter.send(request, **kwargs)
  File "C:\Users\admin\PycharmProjects\hanapsalita-data\venv\lib\site-packages\requests\adapters.py", line 489, in send
    resp = conn.urlopen(
  File "C:\Users\admin\PycharmProjects\hanapsalita-data\venv\lib\site-packages\urllib3\connectionpool.py", line 703, in urlopen
    httplib_response = self._make_request(
  File "C:\Users\admin\PycharmProjects\hanapsalita-data\venv\lib\site-packages\urllib3\connectionpool.py", line 449, in _make_request
    six.raise_from(e, None)
  File "<string>", line 3, in raise_from
  File "C:\Users\admin\PycharmProjects\hanapsalita-data\venv\lib\site-packages\urllib3\connectionpool.py", line 444, in _make_request
    httplib_response = conn.getresponse()
  File "C:\Users\admin\AppData\Local\Programs\Python\Python39\lib\http\client.py", line 1347, in getresponse
    response.begin()
  File "C:\Users\admin\AppData\Local\Programs\Python\Python39\lib\http\client.py", line 307, in begin
    version, status, reason = self._read_status()
  File "C:\Users\admin\AppData\Local\Programs\Python\Python39\lib\http\client.py", line 268, in _read_status
    line = str(self.fp.readline(_MAXLINE + 1), "iso-8859-1")
  File "C:\Users\admin\AppData\Local\Programs\Python\Python39\lib\socket.py", line 704, in readinto
    return self._sock.recv_into(b)
  File "C:\Users\admin\AppData\Local\Programs\Python\Python39\lib\ssl.py", line 1241, in recv_into
    return self.read(nbytes, buffer)
  File "C:\Users\admin\AppData\Local\Programs\Python\Python39\lib\ssl.py", line 1099, in read
    return self._sslobj.read(len, buffer)
KeyboardInterrupt

~~~~~~~~~~~~~~~ 2022/07/05 11:33:57 ~~~~~~~~~~~~~~~
Traceback (most recent call last):
  File "C:\Users\admin\PycharmProjects\hanapsalita-data\cebuano-pinoydictionary-scrape.py", line 175, in <module>
    getNextLetterPageInfo(startLetters, letter, searchUrl)
  File "C:\Users\admin\PycharmProjects\hanapsalita-data\cebuano-pinoydictionary-scrape.py", line 67, in getNextLetterPageInfo
    nextLetter = startLetters[nextLetterIndex]
IndexError: list index out of range

~~~~~~~~~~~~~~~ 2022/07/05 12:19:28 ~~~~~~~~~~~~~~~
Traceback (most recent call last):
  File "C:/Users/admin/PycharmProjects/hanapsalita-data/cebuano-pinoydictionary-scrape.py", line 175, in <module>
    getNextLetterPageInfo(startLetters, letter, searchUrl)
  File "C:/Users/admin/PycharmProjects/hanapsalita-data/cebuano-pinoydictionary-scrape.py", line 68, in getNextLetterPageInfo
    nextPageSoup = getPage(searchUrl + nextLetter)
  File "C:/Users/admin/PycharmProjects/hanapsalita-data/cebuano-pinoydictionary-scrape.py", line 43, in getPage
    req = requests.get(url)
  File "C:/Users/admin/PycharmProjects/hanapsalita-data/cebuano-pinoydictionary-scrape.py", line 43, in getPage
    req = requests.get(url)
  File "_pydevd_bundle\pydevd_cython_win32_39_64.pyx", line 1179, in _pydevd_bundle.pydevd_cython_win32_39_64.SafeCallWrapper.__call__
  File "_pydevd_bundle\pydevd_cython_win32_39_64.pyx", line 620, in _pydevd_bundle.pydevd_cython_win32_39_64.PyDBFrame.trace_dispatch
  File "_pydevd_bundle\pydevd_cython_win32_39_64.pyx", line 1095, in _pydevd_bundle.pydevd_cython_win32_39_64.PyDBFrame.trace_dispatch
  File "_pydevd_bundle\pydevd_cython_win32_39_64.pyx", line 1057, in _pydevd_bundle.pydevd_cython_win32_39_64.PyDBFrame.trace_dispatch
  File "_pydevd_bundle\pydevd_cython_win32_39_64.pyx", line 317, in _pydevd_bundle.pydevd_cython_win32_39_64.PyDBFrame.do_wait_suspend
  File "C:\Program Files\JetBrains\PyCharm 2022.1\plugins\python\helpers\pydev\pydevd.py", line 1155, in do_wait_suspend
    self._do_wait_suspend(thread, frame, event, arg, suspend_type, from_this_thread)
  File "C:\Program Files\JetBrains\PyCharm 2022.1\plugins\python\helpers\pydev\pydevd.py", line 1170, in _do_wait_suspend
    time.sleep(0.01)
KeyboardInterrupt

~~~~~~~~~~~~~~~ 2022/07/05 13:57:13 ~~~~~~~~~~~~~~~
Traceback (most recent call last):
  File "C:/Users/admin/PycharmProjects/hanapsalita-data/cebuano-pinoydictionary-scrape.py", line 197, in <module>
    # if the first page's soup is already retrieved then uses it for getting the words also
  File "C:/Users/admin/PycharmProjects/hanapsalita-data/cebuano-pinoydictionary-scrape.py", line 197, in <module>
    # if the first page's soup is already retrieved then uses it for getting the words also
  File "_pydevd_bundle\pydevd_cython_win32_39_64.pyx", line 1179, in _pydevd_bundle.pydevd_cython_win32_39_64.SafeCallWrapper.__call__
  File "_pydevd_bundle\pydevd_cython_win32_39_64.pyx", line 620, in _pydevd_bundle.pydevd_cython_win32_39_64.PyDBFrame.trace_dispatch
  File "_pydevd_bundle\pydevd_cython_win32_39_64.pyx", line 1095, in _pydevd_bundle.pydevd_cython_win32_39_64.PyDBFrame.trace_dispatch
  File "_pydevd_bundle\pydevd_cython_win32_39_64.pyx", line 1057, in _pydevd_bundle.pydevd_cython_win32_39_64.PyDBFrame.trace_dispatch
  File "_pydevd_bundle\pydevd_cython_win32_39_64.pyx", line 317, in _pydevd_bundle.pydevd_cython_win32_39_64.PyDBFrame.do_wait_suspend
  File "C:\Program Files\JetBrains\PyCharm 2022.1\plugins\python\helpers\pydev\pydevd.py", line 1155, in do_wait_suspend
    self._do_wait_suspend(thread, frame, event, arg, suspend_type, from_this_thread)
  File "C:\Program Files\JetBrains\PyCharm 2022.1\plugins\python\helpers\pydev\pydevd.py", line 1170, in _do_wait_suspend
    time.sleep(0.01)
KeyboardInterrupt

~~~~~~~~~~~~~~~ 2022/07/05 14:03:02 ~~~~~~~~~~~~~~~
Traceback (most recent call last):
  File "C:/Users/admin/PycharmProjects/hanapsalita-data/cebuano-pinoydictionary-scrape.py", line 184, in <module>
    getContentRecursively(searchUrl, letter, wordGroupSelector, progressJson, progressJsonFilename,
  File "C:/Users/admin/PycharmProjects/hanapsalita-data/cebuano-pinoydictionary-scrape.py", line 127, in getContentRecursively
    succeedingPageSoup = getPage(f'{searchUrl}{letter}/{nextPageNum if nextPageNum > 1 else ""}/')
  File "C:/Users/admin/PycharmProjects/hanapsalita-data/cebuano-pinoydictionary-scrape.py", line 127, in getContentRecursively
    succeedingPageSoup = getPage(f'{searchUrl}{letter}/{nextPageNum if nextPageNum > 1 else ""}/')
  File "C:\Program Files\JetBrains\PyCharm 2022.1\plugins\python\helpers\pydev\_pydevd_bundle\pydevd_trace_dispatch.py", line 56, in trace_dispatch
    def trace_dispatch(py_db, frame, event, arg):
  File "_pydevd_bundle\pydevd_cython_win32_39_64.pyx", line 1329, in _pydevd_bundle.pydevd_cython_win32_39_64.trace_dispatch
  File "_pydevd_bundle\pydevd_cython_win32_39_64.pyx", line 1589, in _pydevd_bundle.pydevd_cython_win32_39_64.ThreadTracer.__call__
  File "_pydevd_bundle\pydevd_cython_win32_39_64.pyx", line 1095, in _pydevd_bundle.pydevd_cython_win32_39_64.PyDBFrame.trace_dispatch
  File "_pydevd_bundle\pydevd_cython_win32_39_64.pyx", line 1057, in _pydevd_bundle.pydevd_cython_win32_39_64.PyDBFrame.trace_dispatch
  File "_pydevd_bundle\pydevd_cython_win32_39_64.pyx", line 317, in _pydevd_bundle.pydevd_cython_win32_39_64.PyDBFrame.do_wait_suspend
  File "C:\Program Files\JetBrains\PyCharm 2022.1\plugins\python\helpers\pydev\pydevd.py", line 1155, in do_wait_suspend
    self._do_wait_suspend(thread, frame, event, arg, suspend_type, from_this_thread)
  File "C:\Program Files\JetBrains\PyCharm 2022.1\plugins\python\helpers\pydev\pydevd.py", line 1170, in _do_wait_suspend
    time.sleep(0.01)
KeyboardInterrupt

~~~~~~~~~~~~~~~ 2022/07/05 14:16:05 ~~~~~~~~~~~~~~~
Traceback (most recent call last):
  File "C:/Users/admin/PycharmProjects/hanapsalita-data/cebuano-pinoydictionary-scrape.py", line 191, in <module>
    lastPageNum, stoppedAt, lastRowId)
  File "C:/Users/admin/PycharmProjects/hanapsalita-data/cebuano-pinoydictionary-scrape.py", line 84, in storeProgressStatusToJson
    file.write(json.dumps(progressJson))
  File "_pydevd_bundle\pydevd_cython_win32_39_64.pyx", line 1179, in _pydevd_bundle.pydevd_cython_win32_39_64.SafeCallWrapper.__call__
  File "_pydevd_bundle\pydevd_cython_win32_39_64.pyx", line 620, in _pydevd_bundle.pydevd_cython_win32_39_64.PyDBFrame.trace_dispatch
  File "_pydevd_bundle\pydevd_cython_win32_39_64.pyx", line 1095, in _pydevd_bundle.pydevd_cython_win32_39_64.PyDBFrame.trace_dispatch
  File "_pydevd_bundle\pydevd_cython_win32_39_64.pyx", line 1088, in _pydevd_bundle.pydevd_cython_win32_39_64.PyDBFrame.trace_dispatch
  File "_pydevd_bundle\pydevd_cython_win32_39_64.pyx", line 317, in _pydevd_bundle.pydevd_cython_win32_39_64.PyDBFrame.do_wait_suspend
  File "C:\Program Files\JetBrains\PyCharm 2022.1\plugins\python\helpers\pydev\pydevd.py", line 1155, in do_wait_suspend
    self._do_wait_suspend(thread, frame, event, arg, suspend_type, from_this_thread)
  File "C:\Program Files\JetBrains\PyCharm 2022.1\plugins\python\helpers\pydev\pydevd.py", line 1170, in _do_wait_suspend
    time.sleep(0.01)
KeyboardInterrupt

~~~~~~~~~~~~~~~ 2022/07/05 14:35:28 ~~~~~~~~~~~~~~~
Traceback (most recent call last):
  File "C:/Users/admin/PycharmProjects/hanapsalita-data/cebuano-pinoydictionary-scrape.py", line 183, in <module>
    getContentRecursively(searchUrl, letter, wordGroupSelector, progressJson, progressJsonFilename,
  File "C:/Users/admin/PycharmProjects/hanapsalita-data/cebuano-pinoydictionary-scrape.py", line 132, in getContentRecursively
    file.write(json.dumps(progressJson))
io.UnsupportedOperation: not writable

~~~~~~~~~~~~~~~ 2022/07/05 14:41:28 ~~~~~~~~~~~~~~~
Traceback (most recent call last):
  File "C:/Users/admin/PycharmProjects/hanapsalita-data/cebuano-pinoydictionary-scrape.py", line 189, in <module>
    getNextLetterPageInfo(startLetters, letter, searchUrl)
  File "C:/Users/admin/PycharmProjects/hanapsalita-data/cebuano-pinoydictionary-scrape.py", line 68, in getNextLetterPageInfo
    nextLetter = startLetters[nextLetterIndex]
IndexError: list index out of range

~~~~~~~~~~~~~~~ 2022/07/05 15:11:46 ~~~~~~~~~~~~~~~
Traceback (most recent call last):
  File "C:\Users\admin\PycharmProjects\hanapsalita-data\tagalog-pinoydictionary-scrape.py", line 212, in <module>
    lastRowId = getContent(bs, progressJson, progressJsonFilename, lastRetrievedLetterIndex, letter,
  File "C:\Users\admin\PycharmProjects\hanapsalita-data\tagalog-pinoydictionary-scrape.py", line 119, in getContent
    lastRowId = pushToDatabases(*variablesToBePushed)
  File "C:\Users\admin\PycharmProjects\hanapsalita-data\scrapeUtils.py", line 174, in pushToDatabases
    lastRowID = pushToMySQL(conn, cur, lastRowId, word, category, wordLength, withDashes, alphaSortedWithoutDashes,
  File "C:\Users\admin\PycharmProjects\hanapsalita-data\scrapeUtils.py", line 147, in pushToMySQL
    conn.commit()
  File "C:\Users\admin\PycharmProjects\hanapsalita-data\venv\lib\site-packages\mysql\connector\connection_cext.py", line 425, in commit
    self._cmysql.commit()
KeyboardInterrupt

~~~~~~~~~~~~~~~ 2022/07/05 15:14:10 ~~~~~~~~~~~~~~~
Traceback (most recent call last):
  File "C:\Users\admin\PycharmProjects\hanapsalita-data\tagalog-pinoydictionary-scrape.py", line 212, in <module>
    lastRowId = getContent(bs, progressJson, progressJsonFilename, lastRetrievedLetterIndex, letter,
  File "C:\Users\admin\PycharmProjects\hanapsalita-data\tagalog-pinoydictionary-scrape.py", line 119, in getContent
    lastRowId = pushToDatabases(*variablesToBePushed)
  File "C:\Users\admin\PycharmProjects\hanapsalita-data\scrapeUtils.py", line 174, in pushToDatabases
    lastRowID = pushToMySQL(conn, cur, lastRowId, word, category, wordLength, withDashes, alphaSortedWithoutDashes,
  File "C:\Users\admin\PycharmProjects\hanapsalita-data\scrapeUtils.py", line 118, in pushToMySQL
    cur.execute(tagalogWordsSQL, tagalogWordsValues)
  File "C:\Users\admin\PycharmProjects\hanapsalita-data\venv\lib\site-packages\mysql\connector\cursor_cext.py", line 269, in execute
    result = self._cnx.cmd_query(stmt, raw=self._raw,
  File "C:\Users\admin\PycharmProjects\hanapsalita-data\venv\lib\site-packages\mysql\connector\connection_cext.py", line 535, in cmd_query
    self._cmysql.query(query,
KeyboardInterrupt

~~~~~~~~~~~~~~~ 2022/07/05 18:39:38 ~~~~~~~~~~~~~~~
Traceback (most recent call last):
  File "C:\Users\admin\PycharmProjects\hanapsalita-data\venv\lib\site-packages\urllib3\util\connection.py", line 85, in create_connection
    sock.connect(sa)
TimeoutError: [WinError 10060] A connection attempt failed because the connected party did not properly respond after a period of time, or established connection failed because connected host has failed to respond

During handling of the above exception, another exception occurred:

Traceback (most recent call last):
  File "C:\Users\admin\PycharmProjects\hanapsalita-data\tagalog-pinoydictionary-scrape.py", line 155, in <module>
    bs = getPage(searchUrl + letter)
  File "C:\Users\admin\PycharmProjects\hanapsalita-data\tagalog-pinoydictionary-scrape.py", line 41, in getPage
    req = requests.get(url)
  File "C:\Users\admin\PycharmProjects\hanapsalita-data\venv\lib\site-packages\requests\api.py", line 73, in get
    return request("get", url, params=params, **kwargs)
  File "C:\Users\admin\PycharmProjects\hanapsalita-data\venv\lib\site-packages\requests\api.py", line 59, in request
    return session.request(method=method, url=url, **kwargs)
  File "C:\Users\admin\PycharmProjects\hanapsalita-data\venv\lib\site-packages\requests\sessions.py", line 587, in request
    resp = self.send(prep, **send_kwargs)
  File "C:\Users\admin\PycharmProjects\hanapsalita-data\venv\lib\site-packages\requests\sessions.py", line 701, in send
    r = adapter.send(request, **kwargs)
  File "C:\Users\admin\PycharmProjects\hanapsalita-data\venv\lib\site-packages\requests\adapters.py", line 489, in send
    resp = conn.urlopen(
  File "C:\Users\admin\PycharmProjects\hanapsalita-data\venv\lib\site-packages\urllib3\connectionpool.py", line 703, in urlopen
    httplib_response = self._make_request(
  File "C:\Users\admin\PycharmProjects\hanapsalita-data\venv\lib\site-packages\urllib3\connectionpool.py", line 386, in _make_request
    self._validate_conn(conn)
  File "C:\Users\admin\PycharmProjects\hanapsalita-data\venv\lib\site-packages\urllib3\connectionpool.py", line 1040, in _validate_conn
    conn.connect()
  File "C:\Users\admin\PycharmProjects\hanapsalita-data\venv\lib\site-packages\urllib3\connection.py", line 358, in connect
    self.sock = conn = self._new_conn()
  File "C:\Users\admin\PycharmProjects\hanapsalita-data\venv\lib\site-packages\urllib3\connection.py", line 174, in _new_conn
    conn = connection.create_connection(
  File "C:\Users\admin\PycharmProjects\hanapsalita-data\venv\lib\site-packages\urllib3\util\connection.py", line 85, in create_connection
    sock.connect(sa)
KeyboardInterrupt

~~~~~~~~~~~~~~~ 2022/07/05 18:39:51 ~~~~~~~~~~~~~~~
Traceback (most recent call last):
  File "C:\Users\admin\PycharmProjects\hanapsalita-data\venv\lib\site-packages\urllib3\connectionpool.py", line 703, in urlopen
    httplib_response = self._make_request(
  File "C:\Users\admin\PycharmProjects\hanapsalita-data\venv\lib\site-packages\urllib3\connectionpool.py", line 386, in _make_request
    self._validate_conn(conn)
  File "C:\Users\admin\PycharmProjects\hanapsalita-data\venv\lib\site-packages\urllib3\connectionpool.py", line 1040, in _validate_conn
    conn.connect()
  File "C:\Users\admin\PycharmProjects\hanapsalita-data\venv\lib\site-packages\urllib3\connection.py", line 414, in connect
    self.sock = ssl_wrap_socket(
  File "C:\Users\admin\PycharmProjects\hanapsalita-data\venv\lib\site-packages\urllib3\util\ssl_.py", line 449, in ssl_wrap_socket
    ssl_sock = _ssl_wrap_socket_impl(
  File "C:\Users\admin\PycharmProjects\hanapsalita-data\venv\lib\site-packages\urllib3\util\ssl_.py", line 493, in _ssl_wrap_socket_impl
    return ssl_context.wrap_socket(sock, server_hostname=server_hostname)
  File "C:\Users\admin\AppData\Local\Programs\Python\Python39\lib\ssl.py", line 500, in wrap_socket
    return self.sslsocket_class._create(
  File "C:\Users\admin\AppData\Local\Programs\Python\Python39\lib\ssl.py", line 1040, in _create
    self.do_handshake()
  File "C:\Users\admin\AppData\Local\Programs\Python\Python39\lib\ssl.py", line 1309, in do_handshake
    self._sslobj.do_handshake()
ConnectionResetError: [WinError 10054] An existing connection was forcibly closed by the remote host

During handling of the above exception, another exception occurred:

Traceback (most recent call last):
  File "C:\Users\admin\PycharmProjects\hanapsalita-data\venv\lib\site-packages\requests\adapters.py", line 489, in send
    resp = conn.urlopen(
  File "C:\Users\admin\PycharmProjects\hanapsalita-data\venv\lib\site-packages\urllib3\connectionpool.py", line 785, in urlopen
    retries = retries.increment(
  File "C:\Users\admin\PycharmProjects\hanapsalita-data\venv\lib\site-packages\urllib3\util\retry.py", line 550, in increment
    raise six.reraise(type(error), error, _stacktrace)
  File "C:\Users\admin\PycharmProjects\hanapsalita-data\venv\lib\site-packages\urllib3\packages\six.py", line 769, in reraise
    raise value.with_traceback(tb)
  File "C:\Users\admin\PycharmProjects\hanapsalita-data\venv\lib\site-packages\urllib3\connectionpool.py", line 703, in urlopen
    httplib_response = self._make_request(
  File "C:\Users\admin\PycharmProjects\hanapsalita-data\venv\lib\site-packages\urllib3\connectionpool.py", line 386, in _make_request
    self._validate_conn(conn)
  File "C:\Users\admin\PycharmProjects\hanapsalita-data\venv\lib\site-packages\urllib3\connectionpool.py", line 1040, in _validate_conn
    conn.connect()
  File "C:\Users\admin\PycharmProjects\hanapsalita-data\venv\lib\site-packages\urllib3\connection.py", line 414, in connect
    self.sock = ssl_wrap_socket(
  File "C:\Users\admin\PycharmProjects\hanapsalita-data\venv\lib\site-packages\urllib3\util\ssl_.py", line 449, in ssl_wrap_socket
    ssl_sock = _ssl_wrap_socket_impl(
  File "C:\Users\admin\PycharmProjects\hanapsalita-data\venv\lib\site-packages\urllib3\util\ssl_.py", line 493, in _ssl_wrap_socket_impl
    return ssl_context.wrap_socket(sock, server_hostname=server_hostname)
  File "C:\Users\admin\AppData\Local\Programs\Python\Python39\lib\ssl.py", line 500, in wrap_socket
    return self.sslsocket_class._create(
  File "C:\Users\admin\AppData\Local\Programs\Python\Python39\lib\ssl.py", line 1040, in _create
    self.do_handshake()
  File "C:\Users\admin\AppData\Local\Programs\Python\Python39\lib\ssl.py", line 1309, in do_handshake
    self._sslobj.do_handshake()
urllib3.exceptions.ProtocolError: ('Connection aborted.', ConnectionResetError(10054, 'An existing connection was forcibly closed by the remote host', None, 10054, None))

During handling of the above exception, another exception occurred:

Traceback (most recent call last):
  File "C:\Users\admin\PycharmProjects\hanapsalita-data\tagalog-pinoydictionary-scrape.py", line 208, in <module>
    bs = getPage(url)
  File "C:\Users\admin\PycharmProjects\hanapsalita-data\tagalog-pinoydictionary-scrape.py", line 41, in getPage
    req = requests.get(url)
  File "C:\Users\admin\PycharmProjects\hanapsalita-data\venv\lib\site-packages\requests\api.py", line 73, in get
    return request("get", url, params=params, **kwargs)
  File "C:\Users\admin\PycharmProjects\hanapsalita-data\venv\lib\site-packages\requests\api.py", line 59, in request
    return session.request(method=method, url=url, **kwargs)
  File "C:\Users\admin\PycharmProjects\hanapsalita-data\venv\lib\site-packages\requests\sessions.py", line 587, in request
    resp = self.send(prep, **send_kwargs)
  File "C:\Users\admin\PycharmProjects\hanapsalita-data\venv\lib\site-packages\requests\sessions.py", line 701, in send
    r = adapter.send(request, **kwargs)
  File "C:\Users\admin\PycharmProjects\hanapsalita-data\venv\lib\site-packages\requests\adapters.py", line 547, in send
    raise ConnectionError(err, request=request)
requests.exceptions.ConnectionError: ('Connection aborted.', ConnectionResetError(10054, 'An existing connection was forcibly closed by the remote host', None, 10054, None))

~~~~~~~~~~~~~~~ 2022/07/05 18:40:53 ~~~~~~~~~~~~~~~
Traceback (most recent call last):
  File "C:\Users\admin\PycharmProjects\hanapsalita-data\venv\lib\site-packages\urllib3\connectionpool.py", line 703, in urlopen
    httplib_response = self._make_request(
  File "C:\Users\admin\PycharmProjects\hanapsalita-data\venv\lib\site-packages\urllib3\connectionpool.py", line 386, in _make_request
    self._validate_conn(conn)
  File "C:\Users\admin\PycharmProjects\hanapsalita-data\venv\lib\site-packages\urllib3\connectionpool.py", line 1040, in _validate_conn
    conn.connect()
  File "C:\Users\admin\PycharmProjects\hanapsalita-data\venv\lib\site-packages\urllib3\connection.py", line 414, in connect
    self.sock = ssl_wrap_socket(
  File "C:\Users\admin\PycharmProjects\hanapsalita-data\venv\lib\site-packages\urllib3\util\ssl_.py", line 449, in ssl_wrap_socket
    ssl_sock = _ssl_wrap_socket_impl(
  File "C:\Users\admin\PycharmProjects\hanapsalita-data\venv\lib\site-packages\urllib3\util\ssl_.py", line 493, in _ssl_wrap_socket_impl
    return ssl_context.wrap_socket(sock, server_hostname=server_hostname)
  File "C:\Users\admin\AppData\Local\Programs\Python\Python39\lib\ssl.py", line 500, in wrap_socket
    return self.sslsocket_class._create(
  File "C:\Users\admin\AppData\Local\Programs\Python\Python39\lib\ssl.py", line 1040, in _create
    self.do_handshake()
  File "C:\Users\admin\AppData\Local\Programs\Python\Python39\lib\ssl.py", line 1309, in do_handshake
    self._sslobj.do_handshake()
ConnectionResetError: [WinError 10054] An existing connection was forcibly closed by the remote host

During handling of the above exception, another exception occurred:

Traceback (most recent call last):
  File "C:\Users\admin\PycharmProjects\hanapsalita-data\venv\lib\site-packages\requests\adapters.py", line 489, in send
    resp = conn.urlopen(
  File "C:\Users\admin\PycharmProjects\hanapsalita-data\venv\lib\site-packages\urllib3\connectionpool.py", line 785, in urlopen
    retries = retries.increment(
  File "C:\Users\admin\PycharmProjects\hanapsalita-data\venv\lib\site-packages\urllib3\util\retry.py", line 550, in increment
    raise six.reraise(type(error), error, _stacktrace)
  File "C:\Users\admin\PycharmProjects\hanapsalita-data\venv\lib\site-packages\urllib3\packages\six.py", line 769, in reraise
    raise value.with_traceback(tb)
  File "C:\Users\admin\PycharmProjects\hanapsalita-data\venv\lib\site-packages\urllib3\connectionpool.py", line 703, in urlopen
    httplib_response = self._make_request(
  File "C:\Users\admin\PycharmProjects\hanapsalita-data\venv\lib\site-packages\urllib3\connectionpool.py", line 386, in _make_request
    self._validate_conn(conn)
  File "C:\Users\admin\PycharmProjects\hanapsalita-data\venv\lib\site-packages\urllib3\connectionpool.py", line 1040, in _validate_conn
    conn.connect()
  File "C:\Users\admin\PycharmProjects\hanapsalita-data\venv\lib\site-packages\urllib3\connection.py", line 414, in connect
    self.sock = ssl_wrap_socket(
  File "C:\Users\admin\PycharmProjects\hanapsalita-data\venv\lib\site-packages\urllib3\util\ssl_.py", line 449, in ssl_wrap_socket
    ssl_sock = _ssl_wrap_socket_impl(
  File "C:\Users\admin\PycharmProjects\hanapsalita-data\venv\lib\site-packages\urllib3\util\ssl_.py", line 493, in _ssl_wrap_socket_impl
    return ssl_context.wrap_socket(sock, server_hostname=server_hostname)
  File "C:\Users\admin\AppData\Local\Programs\Python\Python39\lib\ssl.py", line 500, in wrap_socket
    return self.sslsocket_class._create(
  File "C:\Users\admin\AppData\Local\Programs\Python\Python39\lib\ssl.py", line 1040, in _create
    self.do_handshake()
  File "C:\Users\admin\AppData\Local\Programs\Python\Python39\lib\ssl.py", line 1309, in do_handshake
    self._sslobj.do_handshake()
urllib3.exceptions.ProtocolError: ('Connection aborted.', ConnectionResetError(10054, 'An existing connection was forcibly closed by the remote host', None, 10054, None))

During handling of the above exception, another exception occurred:

Traceback (most recent call last):
  File "C:\Users\admin\PycharmProjects\hanapsalita-data\tagalog-pinoydictionary-scrape.py", line 208, in <module>
    bs = getPage(url)
  File "C:\Users\admin\PycharmProjects\hanapsalita-data\tagalog-pinoydictionary-scrape.py", line 41, in getPage
    req = requests.get(url)
  File "C:\Users\admin\PycharmProjects\hanapsalita-data\venv\lib\site-packages\requests\api.py", line 73, in get
    return request("get", url, params=params, **kwargs)
  File "C:\Users\admin\PycharmProjects\hanapsalita-data\venv\lib\site-packages\requests\api.py", line 59, in request
    return session.request(method=method, url=url, **kwargs)
  File "C:\Users\admin\PycharmProjects\hanapsalita-data\venv\lib\site-packages\requests\sessions.py", line 587, in request
    resp = self.send(prep, **send_kwargs)
  File "C:\Users\admin\PycharmProjects\hanapsalita-data\venv\lib\site-packages\requests\sessions.py", line 701, in send
    r = adapter.send(request, **kwargs)
  File "C:\Users\admin\PycharmProjects\hanapsalita-data\venv\lib\site-packages\requests\adapters.py", line 547, in send
    raise ConnectionError(err, request=request)
requests.exceptions.ConnectionError: ('Connection aborted.', ConnectionResetError(10054, 'An existing connection was forcibly closed by the remote host', None, 10054, None))

~~~~~~~~~~~~~~~ 2022/07/05 18:43:51 ~~~~~~~~~~~~~~~
Traceback (most recent call last):
  File "C:\Users\admin\PycharmProjects\hanapsalita-data\venv\lib\site-packages\urllib3\connectionpool.py", line 703, in urlopen
    httplib_response = self._make_request(
  File "C:\Users\admin\PycharmProjects\hanapsalita-data\venv\lib\site-packages\urllib3\connectionpool.py", line 386, in _make_request
    self._validate_conn(conn)
  File "C:\Users\admin\PycharmProjects\hanapsalita-data\venv\lib\site-packages\urllib3\connectionpool.py", line 1040, in _validate_conn
    conn.connect()
  File "C:\Users\admin\PycharmProjects\hanapsalita-data\venv\lib\site-packages\urllib3\connection.py", line 414, in connect
    self.sock = ssl_wrap_socket(
  File "C:\Users\admin\PycharmProjects\hanapsalita-data\venv\lib\site-packages\urllib3\util\ssl_.py", line 449, in ssl_wrap_socket
    ssl_sock = _ssl_wrap_socket_impl(
  File "C:\Users\admin\PycharmProjects\hanapsalita-data\venv\lib\site-packages\urllib3\util\ssl_.py", line 493, in _ssl_wrap_socket_impl
    return ssl_context.wrap_socket(sock, server_hostname=server_hostname)
  File "C:\Users\admin\AppData\Local\Programs\Python\Python39\lib\ssl.py", line 500, in wrap_socket
    return self.sslsocket_class._create(
  File "C:\Users\admin\AppData\Local\Programs\Python\Python39\lib\ssl.py", line 1040, in _create
    self.do_handshake()
  File "C:\Users\admin\AppData\Local\Programs\Python\Python39\lib\ssl.py", line 1309, in do_handshake
    self._sslobj.do_handshake()
ConnectionResetError: [WinError 10054] An existing connection was forcibly closed by the remote host

During handling of the above exception, another exception occurred:

Traceback (most recent call last):
  File "C:\Users\admin\PycharmProjects\hanapsalita-data\venv\lib\site-packages\requests\adapters.py", line 489, in send
    resp = conn.urlopen(
  File "C:\Users\admin\PycharmProjects\hanapsalita-data\venv\lib\site-packages\urllib3\connectionpool.py", line 785, in urlopen
    retries = retries.increment(
  File "C:\Users\admin\PycharmProjects\hanapsalita-data\venv\lib\site-packages\urllib3\util\retry.py", line 550, in increment
    raise six.reraise(type(error), error, _stacktrace)
  File "C:\Users\admin\PycharmProjects\hanapsalita-data\venv\lib\site-packages\urllib3\packages\six.py", line 769, in reraise
    raise value.with_traceback(tb)
  File "C:\Users\admin\PycharmProjects\hanapsalita-data\venv\lib\site-packages\urllib3\connectionpool.py", line 703, in urlopen
    httplib_response = self._make_request(
  File "C:\Users\admin\PycharmProjects\hanapsalita-data\venv\lib\site-packages\urllib3\connectionpool.py", line 386, in _make_request
    self._validate_conn(conn)
  File "C:\Users\admin\PycharmProjects\hanapsalita-data\venv\lib\site-packages\urllib3\connectionpool.py", line 1040, in _validate_conn
    conn.connect()
  File "C:\Users\admin\PycharmProjects\hanapsalita-data\venv\lib\site-packages\urllib3\connection.py", line 414, in connect
    self.sock = ssl_wrap_socket(
  File "C:\Users\admin\PycharmProjects\hanapsalita-data\venv\lib\site-packages\urllib3\util\ssl_.py", line 449, in ssl_wrap_socket
    ssl_sock = _ssl_wrap_socket_impl(
  File "C:\Users\admin\PycharmProjects\hanapsalita-data\venv\lib\site-packages\urllib3\util\ssl_.py", line 493, in _ssl_wrap_socket_impl
    return ssl_context.wrap_socket(sock, server_hostname=server_hostname)
  File "C:\Users\admin\AppData\Local\Programs\Python\Python39\lib\ssl.py", line 500, in wrap_socket
    return self.sslsocket_class._create(
  File "C:\Users\admin\AppData\Local\Programs\Python\Python39\lib\ssl.py", line 1040, in _create
    self.do_handshake()
  File "C:\Users\admin\AppData\Local\Programs\Python\Python39\lib\ssl.py", line 1309, in do_handshake
    self._sslobj.do_handshake()
urllib3.exceptions.ProtocolError: ('Connection aborted.', ConnectionResetError(10054, 'An existing connection was forcibly closed by the remote host', None, 10054, None))

During handling of the above exception, another exception occurred:

Traceback (most recent call last):
  File "C:\Users\admin\PycharmProjects\hanapsalita-data\tagalog-pinoydictionary-scrape.py", line 208, in <module>
    bs = getPage(url)
  File "C:\Users\admin\PycharmProjects\hanapsalita-data\tagalog-pinoydictionary-scrape.py", line 41, in getPage
    req = requests.get(url)
  File "C:\Users\admin\PycharmProjects\hanapsalita-data\venv\lib\site-packages\requests\api.py", line 73, in get
    return request("get", url, params=params, **kwargs)
  File "C:\Users\admin\PycharmProjects\hanapsalita-data\venv\lib\site-packages\requests\api.py", line 59, in request
    return session.request(method=method, url=url, **kwargs)
  File "C:\Users\admin\PycharmProjects\hanapsalita-data\venv\lib\site-packages\requests\sessions.py", line 587, in request
    resp = self.send(prep, **send_kwargs)
  File "C:\Users\admin\PycharmProjects\hanapsalita-data\venv\lib\site-packages\requests\sessions.py", line 701, in send
    r = adapter.send(request, **kwargs)
  File "C:\Users\admin\PycharmProjects\hanapsalita-data\venv\lib\site-packages\requests\adapters.py", line 547, in send
    raise ConnectionError(err, request=request)
requests.exceptions.ConnectionError: ('Connection aborted.', ConnectionResetError(10054, 'An existing connection was forcibly closed by the remote host', None, 10054, None))

~~~~~~~~~~~~~~~ 2022/07/05 18:44:10 ~~~~~~~~~~~~~~~
Traceback (most recent call last):
  File "C:\Users\admin\PycharmProjects\hanapsalita-data\venv\lib\site-packages\urllib3\connectionpool.py", line 700, in urlopen
    self._prepare_proxy(conn)
  File "C:\Users\admin\PycharmProjects\hanapsalita-data\venv\lib\site-packages\urllib3\connectionpool.py", line 994, in _prepare_proxy
    conn.connect()
  File "C:\Users\admin\PycharmProjects\hanapsalita-data\venv\lib\site-packages\urllib3\connection.py", line 364, in connect
    self.sock = conn = self._connect_tls_proxy(hostname, conn)
  File "C:\Users\admin\PycharmProjects\hanapsalita-data\venv\lib\site-packages\urllib3\connection.py", line 499, in _connect_tls_proxy
    socket = ssl_wrap_socket(
  File "C:\Users\admin\PycharmProjects\hanapsalita-data\venv\lib\site-packages\urllib3\util\ssl_.py", line 453, in ssl_wrap_socket
    ssl_sock = _ssl_wrap_socket_impl(sock, context, tls_in_tls)
  File "C:\Users\admin\PycharmProjects\hanapsalita-data\venv\lib\site-packages\urllib3\util\ssl_.py", line 495, in _ssl_wrap_socket_impl
    return ssl_context.wrap_socket(sock)
  File "C:\Users\admin\AppData\Local\Programs\Python\Python39\lib\ssl.py", line 500, in wrap_socket
    return self.sslsocket_class._create(
  File "C:\Users\admin\AppData\Local\Programs\Python\Python39\lib\ssl.py", line 1040, in _create
    self.do_handshake()
  File "C:\Users\admin\AppData\Local\Programs\Python\Python39\lib\ssl.py", line 1309, in do_handshake
    self._sslobj.do_handshake()
ssl.SSLError: [SSL: WRONG_VERSION_NUMBER] wrong version number (_ssl.c:1123)

During handling of the above exception, another exception occurred:

Traceback (most recent call last):
  File "C:\Users\admin\PycharmProjects\hanapsalita-data\venv\lib\site-packages\requests\adapters.py", line 489, in send
    resp = conn.urlopen(
  File "C:\Users\admin\PycharmProjects\hanapsalita-data\venv\lib\site-packages\urllib3\connectionpool.py", line 785, in urlopen
    retries = retries.increment(
  File "C:\Users\admin\PycharmProjects\hanapsalita-data\venv\lib\site-packages\urllib3\util\retry.py", line 592, in increment
    raise MaxRetryError(_pool, url, error or ResponseError(cause))
urllib3.exceptions.MaxRetryError: HTTPSConnectionPool(host='tagalog.pinoydictionary.com', port=443): Max retries exceeded with url: /list/a// (Caused by ProxyError('Your proxy appears to only use HTTP and not HTTPS, try changing your proxy URL to be HTTP. See: https://urllib3.readthedocs.io/en/1.26.x/advanced-usage.html#https-proxy-error-http-proxy', SSLError(SSLError(1, '[SSL: WRONG_VERSION_NUMBER] wrong version number (_ssl.c:1123)'))))

During handling of the above exception, another exception occurred:

Traceback (most recent call last):
  File "C:\Users\admin\PycharmProjects\hanapsalita-data\tagalog-pinoydictionary-scrape.py", line 208, in <module>
    bs = getPage(url)
  File "C:\Users\admin\PycharmProjects\hanapsalita-data\tagalog-pinoydictionary-scrape.py", line 41, in getPage
    req = requests.get(url)
  File "C:\Users\admin\PycharmProjects\hanapsalita-data\venv\lib\site-packages\requests\api.py", line 73, in get
    return request("get", url, params=params, **kwargs)
  File "C:\Users\admin\PycharmProjects\hanapsalita-data\venv\lib\site-packages\requests\api.py", line 59, in request
    return session.request(method=method, url=url, **kwargs)
  File "C:\Users\admin\PycharmProjects\hanapsalita-data\venv\lib\site-packages\requests\sessions.py", line 587, in request
    resp = self.send(prep, **send_kwargs)
  File "C:\Users\admin\PycharmProjects\hanapsalita-data\venv\lib\site-packages\requests\sessions.py", line 701, in send
    r = adapter.send(request, **kwargs)
  File "C:\Users\admin\PycharmProjects\hanapsalita-data\venv\lib\site-packages\requests\adapters.py", line 559, in send
    raise ProxyError(e, request=request)
requests.exceptions.ProxyError: HTTPSConnectionPool(host='tagalog.pinoydictionary.com', port=443): Max retries exceeded with url: /list/a// (Caused by ProxyError('Your proxy appears to only use HTTP and not HTTPS, try changing your proxy URL to be HTTP. See: https://urllib3.readthedocs.io/en/1.26.x/advanced-usage.html#https-proxy-error-http-proxy', SSLError(SSLError(1, '[SSL: WRONG_VERSION_NUMBER] wrong version number (_ssl.c:1123)'))))

~~~~~~~~~~~~~~~ 2022/07/05 18:44:40 ~~~~~~~~~~~~~~~
Traceback (most recent call last):
  File "C:\Users\admin\PycharmProjects\hanapsalita-data\venv\lib\site-packages\urllib3\connectionpool.py", line 700, in urlopen
    self._prepare_proxy(conn)
  File "C:\Users\admin\PycharmProjects\hanapsalita-data\venv\lib\site-packages\urllib3\connectionpool.py", line 994, in _prepare_proxy
    conn.connect()
  File "C:\Users\admin\PycharmProjects\hanapsalita-data\venv\lib\site-packages\urllib3\connection.py", line 364, in connect
    self.sock = conn = self._connect_tls_proxy(hostname, conn)
  File "C:\Users\admin\PycharmProjects\hanapsalita-data\venv\lib\site-packages\urllib3\connection.py", line 499, in _connect_tls_proxy
    socket = ssl_wrap_socket(
  File "C:\Users\admin\PycharmProjects\hanapsalita-data\venv\lib\site-packages\urllib3\util\ssl_.py", line 453, in ssl_wrap_socket
    ssl_sock = _ssl_wrap_socket_impl(sock, context, tls_in_tls)
  File "C:\Users\admin\PycharmProjects\hanapsalita-data\venv\lib\site-packages\urllib3\util\ssl_.py", line 495, in _ssl_wrap_socket_impl
    return ssl_context.wrap_socket(sock)
  File "C:\Users\admin\AppData\Local\Programs\Python\Python39\lib\ssl.py", line 500, in wrap_socket
    return self.sslsocket_class._create(
  File "C:\Users\admin\AppData\Local\Programs\Python\Python39\lib\ssl.py", line 1040, in _create
    self.do_handshake()
  File "C:\Users\admin\AppData\Local\Programs\Python\Python39\lib\ssl.py", line 1309, in do_handshake
    self._sslobj.do_handshake()
ssl.SSLError: [SSL: WRONG_VERSION_NUMBER] wrong version number (_ssl.c:1123)

During handling of the above exception, another exception occurred:

Traceback (most recent call last):
  File "C:\Users\admin\PycharmProjects\hanapsalita-data\venv\lib\site-packages\requests\adapters.py", line 489, in send
    resp = conn.urlopen(
  File "C:\Users\admin\PycharmProjects\hanapsalita-data\venv\lib\site-packages\urllib3\connectionpool.py", line 785, in urlopen
    retries = retries.increment(
  File "C:\Users\admin\PycharmProjects\hanapsalita-data\venv\lib\site-packages\urllib3\util\retry.py", line 592, in increment
    raise MaxRetryError(_pool, url, error or ResponseError(cause))
urllib3.exceptions.MaxRetryError: HTTPSConnectionPool(host='tagalog.pinoydictionary.com', port=443): Max retries exceeded with url: /list/a// (Caused by ProxyError('Your proxy appears to only use HTTP and not HTTPS, try changing your proxy URL to be HTTP. See: https://urllib3.readthedocs.io/en/1.26.x/advanced-usage.html#https-proxy-error-http-proxy', SSLError(SSLError(1, '[SSL: WRONG_VERSION_NUMBER] wrong version number (_ssl.c:1123)'))))

During handling of the above exception, another exception occurred:

Traceback (most recent call last):
  File "C:\Users\admin\PycharmProjects\hanapsalita-data\tagalog-pinoydictionary-scrape.py", line 208, in <module>
    bs = getPage(url)
  File "C:\Users\admin\PycharmProjects\hanapsalita-data\tagalog-pinoydictionary-scrape.py", line 41, in getPage
    req = requests.get(url)
  File "C:\Users\admin\PycharmProjects\hanapsalita-data\venv\lib\site-packages\requests\api.py", line 73, in get
    return request("get", url, params=params, **kwargs)
  File "C:\Users\admin\PycharmProjects\hanapsalita-data\venv\lib\site-packages\requests\api.py", line 59, in request
    return session.request(method=method, url=url, **kwargs)
  File "C:\Users\admin\PycharmProjects\hanapsalita-data\venv\lib\site-packages\requests\sessions.py", line 587, in request
    resp = self.send(prep, **send_kwargs)
  File "C:\Users\admin\PycharmProjects\hanapsalita-data\venv\lib\site-packages\requests\sessions.py", line 701, in send
    r = adapter.send(request, **kwargs)
  File "C:\Users\admin\PycharmProjects\hanapsalita-data\venv\lib\site-packages\requests\adapters.py", line 559, in send
    raise ProxyError(e, request=request)
requests.exceptions.ProxyError: HTTPSConnectionPool(host='tagalog.pinoydictionary.com', port=443): Max retries exceeded with url: /list/a// (Caused by ProxyError('Your proxy appears to only use HTTP and not HTTPS, try changing your proxy URL to be HTTP. See: https://urllib3.readthedocs.io/en/1.26.x/advanced-usage.html#https-proxy-error-http-proxy', SSLError(SSLError(1, '[SSL: WRONG_VERSION_NUMBER] wrong version number (_ssl.c:1123)'))))

~~~~~~~~~~~~~~~ 2022/07/05 18:45:17 ~~~~~~~~~~~~~~~
Traceback (most recent call last):
  File "C:\Users\admin\PycharmProjects\hanapsalita-data\venv\lib\site-packages\urllib3\connectionpool.py", line 703, in urlopen
    httplib_response = self._make_request(
  File "C:\Users\admin\PycharmProjects\hanapsalita-data\venv\lib\site-packages\urllib3\connectionpool.py", line 386, in _make_request
    self._validate_conn(conn)
  File "C:\Users\admin\PycharmProjects\hanapsalita-data\venv\lib\site-packages\urllib3\connectionpool.py", line 1040, in _validate_conn
    conn.connect()
  File "C:\Users\admin\PycharmProjects\hanapsalita-data\venv\lib\site-packages\urllib3\connection.py", line 414, in connect
    self.sock = ssl_wrap_socket(
  File "C:\Users\admin\PycharmProjects\hanapsalita-data\venv\lib\site-packages\urllib3\util\ssl_.py", line 449, in ssl_wrap_socket
    ssl_sock = _ssl_wrap_socket_impl(
  File "C:\Users\admin\PycharmProjects\hanapsalita-data\venv\lib\site-packages\urllib3\util\ssl_.py", line 493, in _ssl_wrap_socket_impl
    return ssl_context.wrap_socket(sock, server_hostname=server_hostname)
  File "C:\Users\admin\AppData\Local\Programs\Python\Python39\lib\ssl.py", line 500, in wrap_socket
    return self.sslsocket_class._create(
  File "C:\Users\admin\AppData\Local\Programs\Python\Python39\lib\ssl.py", line 1040, in _create
    self.do_handshake()
  File "C:\Users\admin\AppData\Local\Programs\Python\Python39\lib\ssl.py", line 1309, in do_handshake
    self._sslobj.do_handshake()
ConnectionResetError: [WinError 10054] An existing connection was forcibly closed by the remote host

During handling of the above exception, another exception occurred:

Traceback (most recent call last):
  File "C:\Users\admin\PycharmProjects\hanapsalita-data\venv\lib\site-packages\requests\adapters.py", line 489, in send
    resp = conn.urlopen(
  File "C:\Users\admin\PycharmProjects\hanapsalita-data\venv\lib\site-packages\urllib3\connectionpool.py", line 785, in urlopen
    retries = retries.increment(
  File "C:\Users\admin\PycharmProjects\hanapsalita-data\venv\lib\site-packages\urllib3\util\retry.py", line 550, in increment
    raise six.reraise(type(error), error, _stacktrace)
  File "C:\Users\admin\PycharmProjects\hanapsalita-data\venv\lib\site-packages\urllib3\packages\six.py", line 769, in reraise
    raise value.with_traceback(tb)
  File "C:\Users\admin\PycharmProjects\hanapsalita-data\venv\lib\site-packages\urllib3\connectionpool.py", line 703, in urlopen
    httplib_response = self._make_request(
  File "C:\Users\admin\PycharmProjects\hanapsalita-data\venv\lib\site-packages\urllib3\connectionpool.py", line 386, in _make_request
    self._validate_conn(conn)
  File "C:\Users\admin\PycharmProjects\hanapsalita-data\venv\lib\site-packages\urllib3\connectionpool.py", line 1040, in _validate_conn
    conn.connect()
  File "C:\Users\admin\PycharmProjects\hanapsalita-data\venv\lib\site-packages\urllib3\connection.py", line 414, in connect
    self.sock = ssl_wrap_socket(
  File "C:\Users\admin\PycharmProjects\hanapsalita-data\venv\lib\site-packages\urllib3\util\ssl_.py", line 449, in ssl_wrap_socket
    ssl_sock = _ssl_wrap_socket_impl(
  File "C:\Users\admin\PycharmProjects\hanapsalita-data\venv\lib\site-packages\urllib3\util\ssl_.py", line 493, in _ssl_wrap_socket_impl
    return ssl_context.wrap_socket(sock, server_hostname=server_hostname)
  File "C:\Users\admin\AppData\Local\Programs\Python\Python39\lib\ssl.py", line 500, in wrap_socket
    return self.sslsocket_class._create(
  File "C:\Users\admin\AppData\Local\Programs\Python\Python39\lib\ssl.py", line 1040, in _create
    self.do_handshake()
  File "C:\Users\admin\AppData\Local\Programs\Python\Python39\lib\ssl.py", line 1309, in do_handshake
    self._sslobj.do_handshake()
urllib3.exceptions.ProtocolError: ('Connection aborted.', ConnectionResetError(10054, 'An existing connection was forcibly closed by the remote host', None, 10054, None))

During handling of the above exception, another exception occurred:

Traceback (most recent call last):
  File "C:\Users\admin\PycharmProjects\hanapsalita-data\tagalog-pinoydictionary-scrape.py", line 217, in <module>
    getNextLetterPageInfo(startLetters, letter, searchUrl)
  File "C:\Users\admin\PycharmProjects\hanapsalita-data\tagalog-pinoydictionary-scrape.py", line 68, in getNextLetterPageInfo
    nextPageSoup = getPage(searchUrl + nextLetter)
  File "C:\Users\admin\PycharmProjects\hanapsalita-data\tagalog-pinoydictionary-scrape.py", line 41, in getPage
    req = requests.get(url)
  File "C:\Users\admin\PycharmProjects\hanapsalita-data\venv\lib\site-packages\requests\api.py", line 73, in get
    return request("get", url, params=params, **kwargs)
  File "C:\Users\admin\PycharmProjects\hanapsalita-data\venv\lib\site-packages\requests\api.py", line 59, in request
    return session.request(method=method, url=url, **kwargs)
  File "C:\Users\admin\PycharmProjects\hanapsalita-data\venv\lib\site-packages\requests\sessions.py", line 587, in request
    resp = self.send(prep, **send_kwargs)
  File "C:\Users\admin\PycharmProjects\hanapsalita-data\venv\lib\site-packages\requests\sessions.py", line 701, in send
    r = adapter.send(request, **kwargs)
  File "C:\Users\admin\PycharmProjects\hanapsalita-data\venv\lib\site-packages\requests\adapters.py", line 547, in send
    raise ConnectionError(err, request=request)
requests.exceptions.ConnectionError: ('Connection aborted.', ConnectionResetError(10054, 'An existing connection was forcibly closed by the remote host', None, 10054, None))

~~~~~~~~~~~~~~~ 2022/07/06 13:11:20 ~~~~~~~~~~~~~~~
Traceback (most recent call last):
  File "C:\Users\admin\PycharmProjects\hanapsalita-data\venv\lib\site-packages\urllib3\connectionpool.py", line 700, in urlopen
    self._prepare_proxy(conn)
  File "C:\Users\admin\PycharmProjects\hanapsalita-data\venv\lib\site-packages\urllib3\connectionpool.py", line 994, in _prepare_proxy
    conn.connect()
  File "C:\Users\admin\PycharmProjects\hanapsalita-data\venv\lib\site-packages\urllib3\connection.py", line 364, in connect
    self.sock = conn = self._connect_tls_proxy(hostname, conn)
  File "C:\Users\admin\PycharmProjects\hanapsalita-data\venv\lib\site-packages\urllib3\connection.py", line 499, in _connect_tls_proxy
    socket = ssl_wrap_socket(
  File "C:\Users\admin\PycharmProjects\hanapsalita-data\venv\lib\site-packages\urllib3\util\ssl_.py", line 453, in ssl_wrap_socket
    ssl_sock = _ssl_wrap_socket_impl(sock, context, tls_in_tls)
  File "C:\Users\admin\PycharmProjects\hanapsalita-data\venv\lib\site-packages\urllib3\util\ssl_.py", line 495, in _ssl_wrap_socket_impl
    return ssl_context.wrap_socket(sock)
  File "C:\Users\admin\AppData\Local\Programs\Python\Python39\lib\ssl.py", line 500, in wrap_socket
    return self.sslsocket_class._create(
  File "C:\Users\admin\AppData\Local\Programs\Python\Python39\lib\ssl.py", line 1040, in _create
    self.do_handshake()
  File "C:\Users\admin\AppData\Local\Programs\Python\Python39\lib\ssl.py", line 1309, in do_handshake
    self._sslobj.do_handshake()
ssl.SSLError: [SSL: WRONG_VERSION_NUMBER] wrong version number (_ssl.c:1123)

During handling of the above exception, another exception occurred:

Traceback (most recent call last):
  File "C:\Users\admin\PycharmProjects\hanapsalita-data\venv\lib\site-packages\requests\adapters.py", line 489, in send
    resp = conn.urlopen(
  File "C:\Users\admin\PycharmProjects\hanapsalita-data\venv\lib\site-packages\urllib3\connectionpool.py", line 785, in urlopen
    retries = retries.increment(
  File "C:\Users\admin\PycharmProjects\hanapsalita-data\venv\lib\site-packages\urllib3\util\retry.py", line 592, in increment
    raise MaxRetryError(_pool, url, error or ResponseError(cause))
urllib3.exceptions.MaxRetryError: HTTPSConnectionPool(host='tagalog.pinoydictionary.com', port=443): Max retries exceeded with url: /list/a (Caused by ProxyError('Your proxy appears to only use HTTP and not HTTPS, try changing your proxy URL to be HTTP. See: https://urllib3.readthedocs.io/en/1.26.x/advanced-usage.html#https-proxy-error-http-proxy', SSLError(SSLError(1, '[SSL: WRONG_VERSION_NUMBER] wrong version number (_ssl.c:1123)'))))

During handling of the above exception, another exception occurred:

Traceback (most recent call last):
  File "C:\Users\admin\PycharmProjects\hanapsalita-data\tagalog-pinoydictionary-scrape.py", line 174, in <module>
    bs = getPage(searchUrl + letter)
  File "C:\Users\admin\PycharmProjects\hanapsalita-data\tagalog-pinoydictionary-scrape.py", line 42, in getPage
    req = requests.get(url)
  File "C:\Users\admin\PycharmProjects\hanapsalita-data\venv\lib\site-packages\requests\api.py", line 73, in get
    return request("get", url, params=params, **kwargs)
  File "C:\Users\admin\PycharmProjects\hanapsalita-data\venv\lib\site-packages\requests\api.py", line 59, in request
    return session.request(method=method, url=url, **kwargs)
  File "C:\Users\admin\PycharmProjects\hanapsalita-data\venv\lib\site-packages\requests\sessions.py", line 587, in request
    resp = self.send(prep, **send_kwargs)
  File "C:\Users\admin\PycharmProjects\hanapsalita-data\venv\lib\site-packages\requests\sessions.py", line 701, in send
    r = adapter.send(request, **kwargs)
  File "C:\Users\admin\PycharmProjects\hanapsalita-data\venv\lib\site-packages\requests\adapters.py", line 559, in send
    raise ProxyError(e, request=request)
requests.exceptions.ProxyError: HTTPSConnectionPool(host='tagalog.pinoydictionary.com', port=443): Max retries exceeded with url: /list/a (Caused by ProxyError('Your proxy appears to only use HTTP and not HTTPS, try changing your proxy URL to be HTTP. See: https://urllib3.readthedocs.io/en/1.26.x/advanced-usage.html#https-proxy-error-http-proxy', SSLError(SSLError(1, '[SSL: WRONG_VERSION_NUMBER] wrong version number (_ssl.c:1123)'))))

~~~~~~~~~~~~~~~ 2022/07/06 13:12:26 ~~~~~~~~~~~~~~~
Traceback (most recent call last):
  File "C:\Users\admin\PycharmProjects\hanapsalita-data\venv\lib\site-packages\mysql\connector\connection_cext.py", line 535, in cmd_query
    self._cmysql.query(query,
_mysql_connector.MySQLInterfaceError: Unknown column '1c' in 'field list'

During handling of the above exception, another exception occurred:

Traceback (most recent call last):
  File "C:\Users\admin\PycharmProjects\hanapsalita-data\tagalog-pinoydictionary-scrape.py", line 231, in <module>
    lastRowId = getContent(bs, progressJson, progressJsonFilename, lastRetrievedLetterIndex, letter,
  File "C:\Users\admin\PycharmProjects\hanapsalita-data\tagalog-pinoydictionary-scrape.py", line 127, in getContent
    lastRowID = processWord(word, conn, cur, jsonDatabase, wordsJsonFilename, lastRowID, category,
  File "C:\Users\admin\PycharmProjects\hanapsalita-data\scrapeUtils.py", line 295, in processWord
    lastRowID = pushToDatabases(*variablesToBePushed)
  File "C:\Users\admin\PycharmProjects\hanapsalita-data\scrapeUtils.py", line 251, in pushToDatabases
    lastRowID = pushToMySQL(conn, cur, lastRowId, word, category, verbBaseForm, wordLength, withPunctuations,
  File "C:\Users\admin\PycharmProjects\hanapsalita-data\scrapeUtils.py", line 201, in pushToMySQL
    cur.execute(tagalogContainSQL, tagalogConstituentsRowValues)
  File "C:\Users\admin\PycharmProjects\hanapsalita-data\venv\lib\site-packages\mysql\connector\cursor_cext.py", line 269, in execute
    result = self._cnx.cmd_query(stmt, raw=self._raw,
  File "C:\Users\admin\PycharmProjects\hanapsalita-data\venv\lib\site-packages\mysql\connector\connection_cext.py", line 540, in cmd_query
    raise errors.get_mysql_exception(exc.errno, msg=exc.msg,
mysql.connector.errors.ProgrammingError: 1054 (42S22): Unknown column '1c' in 'field list'

~~~~~~~~~~~~~~~ 2022/07/06 13:32:57 ~~~~~~~~~~~~~~~
Traceback (most recent call last):
  File "C:\Users\admin\PycharmProjects\hanapsalita-data\venv\lib\site-packages\mysql\connector\connection_cext.py", line 535, in cmd_query
    self._cmysql.query(query,
_mysql_connector.MySQLInterfaceError: Column count doesn't match value count at row 1

During handling of the above exception, another exception occurred:

Traceback (most recent call last):
  File "C:\Users\admin\PycharmProjects\hanapsalita-data\tagalog-pinoydictionary-scrape.py", line 231, in <module>
    lastRowId = getContent(bs, progressJson, progressJsonFilename, lastRetrievedLetterIndex, letter,
  File "C:\Users\admin\PycharmProjects\hanapsalita-data\tagalog-pinoydictionary-scrape.py", line 127, in getContent
    lastRowID = processWord(word, conn, cur, jsonDatabase, wordsJsonFilename, lastRowID, category,
  File "C:\Users\admin\PycharmProjects\hanapsalita-data\scrapeUtils.py", line 324, in processWord
    lastRowID = pushToDatabases(*variablesToBePushed)
  File "C:\Users\admin\PycharmProjects\hanapsalita-data\scrapeUtils.py", line 280, in pushToDatabases
    lastRowID = pushToMySQL(conn, cur, lastRowId, word, category, verbBaseForm, wordLength, withPunctuations,
  File "C:\Users\admin\PycharmProjects\hanapsalita-data\scrapeUtils.py", line 183, in pushToMySQL
    cur.execute(tagalogStartNotStrictSQL, tagalogStartNotStrictValues)
  File "C:\Users\admin\PycharmProjects\hanapsalita-data\venv\lib\site-packages\mysql\connector\cursor_cext.py", line 269, in execute
    result = self._cnx.cmd_query(stmt, raw=self._raw,
  File "C:\Users\admin\PycharmProjects\hanapsalita-data\venv\lib\site-packages\mysql\connector\connection_cext.py", line 540, in cmd_query
    raise errors.get_mysql_exception(exc.errno, msg=exc.msg,
mysql.connector.errors.DataError: 1136 (21S01): Column count doesn't match value count at row 1

~~~~~~~~~~~~~~~ 2022/07/06 13:45:24 ~~~~~~~~~~~~~~~
Traceback (most recent call last):
  File "C:\Users\admin\PycharmProjects\hanapsalita-data\venv\lib\site-packages\mysql\connector\connection_cext.py", line 535, in cmd_query
    self._cmysql.query(query,
_mysql_connector.MySQLInterfaceError: Duplicate entry '1' for key 'PRIMARY'

During handling of the above exception, another exception occurred:

Traceback (most recent call last):
  File "C:\Users\admin\PycharmProjects\hanapsalita-data\tagalog-pinoydictionary-scrape.py", line 231, in <module>
    lastRowId = getContent(bs, progressJson, progressJsonFilename, lastRetrievedLetterIndex, letter,
  File "C:\Users\admin\PycharmProjects\hanapsalita-data\tagalog-pinoydictionary-scrape.py", line 127, in getContent
    lastRowID = processWord(word, conn, cur, jsonDatabase, wordsJsonFilename, lastRowID, category,
  File "C:\Users\admin\PycharmProjects\hanapsalita-data\scrapeUtils.py", line 324, in processWord
    lastRowID = pushToDatabases(*variablesToBePushed)
  File "C:\Users\admin\PycharmProjects\hanapsalita-data\scrapeUtils.py", line 280, in pushToDatabases
    lastRowID = pushToMySQL(conn, cur, lastRowId, word, category, verbBaseForm, wordLength, withPunctuations,
  File "C:\Users\admin\PycharmProjects\hanapsalita-data\scrapeUtils.py", line 229, in pushToMySQL
    cur.execute(tagalogContainStrictSQL, tagalogConstituentsRowValuesStrict)
  File "C:\Users\admin\PycharmProjects\hanapsalita-data\venv\lib\site-packages\mysql\connector\cursor_cext.py", line 269, in execute
    result = self._cnx.cmd_query(stmt, raw=self._raw,
  File "C:\Users\admin\PycharmProjects\hanapsalita-data\venv\lib\site-packages\mysql\connector\connection_cext.py", line 540, in cmd_query
    raise errors.get_mysql_exception(exc.errno, msg=exc.msg,
mysql.connector.errors.IntegrityError: 1062 (23000): Duplicate entry '1' for key 'PRIMARY'

~~~~~~~~~~~~~~~ 2022/07/06 13:48:49 ~~~~~~~~~~~~~~~
Traceback (most recent call last):
  File "C:\Users\admin\PycharmProjects\hanapsalita-data\venv\lib\site-packages\mysql\connector\connection_cext.py", line 535, in cmd_query
    self._cmysql.query(query,
_mysql_connector.MySQLInterfaceError: Duplicate entry 'abahin' for key 'word'

During handling of the above exception, another exception occurred:

Traceback (most recent call last):
  File "C:\Users\admin\PycharmProjects\hanapsalita-data\tagalog-pinoydictionary-scrape.py", line 231, in <module>
    lastRowId = getContent(bs, progressJson, progressJsonFilename, lastRetrievedLetterIndex, letter,
  File "C:\Users\admin\PycharmProjects\hanapsalita-data\tagalog-pinoydictionary-scrape.py", line 137, in getContent
    lastRowID = processWord(word, conn, cur, jsonDatabase, wordsJsonFilename, lastRowID, category,
  File "C:\Users\admin\PycharmProjects\hanapsalita-data\scrapeUtils.py", line 324, in processWord
    lastRowID = pushToDatabases(*variablesToBePushed)
  File "C:\Users\admin\PycharmProjects\hanapsalita-data\scrapeUtils.py", line 280, in pushToDatabases
    lastRowID = pushToMySQL(conn, cur, lastRowId, word, category, verbBaseForm, wordLength, withPunctuations,
  File "C:\Users\admin\PycharmProjects\hanapsalita-data\scrapeUtils.py", line 173, in pushToMySQL
    cur.execute(tagalogWordsSQL, tagalogWordsValues)
  File "C:\Users\admin\PycharmProjects\hanapsalita-data\venv\lib\site-packages\mysql\connector\cursor_cext.py", line 269, in execute
    result = self._cnx.cmd_query(stmt, raw=self._raw,
  File "C:\Users\admin\PycharmProjects\hanapsalita-data\venv\lib\site-packages\mysql\connector\connection_cext.py", line 540, in cmd_query
    raise errors.get_mysql_exception(exc.errno, msg=exc.msg,
mysql.connector.errors.IntegrityError: 1062 (23000): Duplicate entry 'abahin' for key 'word'

~~~~~~~~~~~~~~~ 2022/07/06 13:57:49 ~~~~~~~~~~~~~~~
Traceback (most recent call last):
  File "C:\Users\admin\PycharmProjects\hanapsalita-data\venv\lib\site-packages\mysql\connector\connection_cext.py", line 535, in cmd_query
    self._cmysql.query(query,
_mysql_connector.MySQLInterfaceError: Duplicate entry 'abahin' for key 'word'

During handling of the above exception, another exception occurred:

Traceback (most recent call last):
  File "C:\Users\admin\PycharmProjects\hanapsalita-data\tagalog-pinoydictionary-scrape.py", line 233, in <module>
    lastRowId = getContent(bs, progressJson, progressJsonFilename, lastRetrievedLetterIndex, letter,
  File "C:\Users\admin\PycharmProjects\hanapsalita-data\tagalog-pinoydictionary-scrape.py", line 139, in getContent
    lastRowID = processWord(word, conn, cur, jsonDatabase, wordsJsonFilename, lastRowID, category,
  File "C:\Users\admin\PycharmProjects\hanapsalita-data\scrapeUtils.py", line 323, in processWord
    lastRowID = pushToDatabases(*variablesToBePushed)
  File "C:\Users\admin\PycharmProjects\hanapsalita-data\scrapeUtils.py", line 279, in pushToDatabases
    lastRowID = pushToMySQL(conn, cur, lastRowId, word, category, verbBaseForm, wordLength, withPunctuations,
  File "C:\Users\admin\PycharmProjects\hanapsalita-data\scrapeUtils.py", line 173, in pushToMySQL
    cur.execute(tagalogWordsSQL, tagalogWordsValues)
  File "C:\Users\admin\PycharmProjects\hanapsalita-data\venv\lib\site-packages\mysql\connector\cursor_cext.py", line 269, in execute
    result = self._cnx.cmd_query(stmt, raw=self._raw,
  File "C:\Users\admin\PycharmProjects\hanapsalita-data\venv\lib\site-packages\mysql\connector\connection_cext.py", line 540, in cmd_query
    raise errors.get_mysql_exception(exc.errno, msg=exc.msg,
mysql.connector.errors.IntegrityError: 1062 (23000): Duplicate entry 'abahin' for key 'word'

~~~~~~~~~~~~~~~ 2022/07/06 14:25:48 ~~~~~~~~~~~~~~~
Traceback (most recent call last):
  File "C:/Users/admin/PycharmProjects/hanapsalita-data/tagalog-pinoydictionary-scrape.py", line 233, in <module>
    lastRowId = getContent(bs, progressJson, progressJsonFilename, lastRetrievedLetterIndex, letter,
  File "C:/Users/admin/PycharmProjects/hanapsalita-data/tagalog-pinoydictionary-scrape.py", line 129, in getContent
    lastRowID = processWord(word, conn, cur, jsonDatabase, wordsJsonFilename, lastRowID, category,
  File "C:\Users\admin\PycharmProjects\hanapsalita-data\scrapeUtils.py", line 323, in processWord
    variablesToBePushed.extend(wordInfo)
  File "C:\Users\admin\PycharmProjects\hanapsalita-data\scrapeUtils.py", line 285, in pushToDatabases
    constituentsRowsWithPunctuations)
  File "C:\Users\admin\PycharmProjects\hanapsalita-data\scrapeUtils.py", line 241, in pushToJSON
    jsonDatabase["data"].setdefault(word, {})
  File "C:\Users\admin\PycharmProjects\hanapsalita-data\scrapeUtils.py", line 241, in pushToJSON
    jsonDatabase["data"].setdefault(word, {})
  File "_pydevd_bundle\pydevd_cython_win32_39_64.pyx", line 1179, in _pydevd_bundle.pydevd_cython_win32_39_64.SafeCallWrapper.__call__
  File "_pydevd_bundle\pydevd_cython_win32_39_64.pyx", line 620, in _pydevd_bundle.pydevd_cython_win32_39_64.PyDBFrame.trace_dispatch
  File "_pydevd_bundle\pydevd_cython_win32_39_64.pyx", line 1095, in _pydevd_bundle.pydevd_cython_win32_39_64.PyDBFrame.trace_dispatch
  File "_pydevd_bundle\pydevd_cython_win32_39_64.pyx", line 1057, in _pydevd_bundle.pydevd_cython_win32_39_64.PyDBFrame.trace_dispatch
  File "_pydevd_bundle\pydevd_cython_win32_39_64.pyx", line 317, in _pydevd_bundle.pydevd_cython_win32_39_64.PyDBFrame.do_wait_suspend
  File "C:\Program Files\JetBrains\PyCharm Community Edition 2022.1.3\plugins\python-ce\helpers\pydev\pydevd.py", line 1155, in do_wait_suspend
    self._do_wait_suspend(thread, frame, event, arg, suspend_type, from_this_thread)
  File "C:\Program Files\JetBrains\PyCharm Community Edition 2022.1.3\plugins\python-ce\helpers\pydev\pydevd.py", line 1170, in _do_wait_suspend
    time.sleep(0.01)
KeyboardInterrupt

~~~~~~~~~~~~~~~ 2022/07/06 14:25:59 ~~~~~~~~~~~~~~~
Traceback (most recent call last):
  File "C:\Users\admin\PycharmProjects\hanapsalita-data\tagalog-pinoydictionary-scrape.py", line 233, in <module>
    lastRowId = getContent(bs, progressJson, progressJsonFilename, lastRetrievedLetterIndex, letter,
  File "C:\Users\admin\PycharmProjects\hanapsalita-data\tagalog-pinoydictionary-scrape.py", line 128, in getContent
    if not wordAlreadyStored(cur, "tagalog_words", word):
  File "C:\Users\admin\PycharmProjects\hanapsalita-data\scrapeUtils.py", line 137, in wordAlreadyStored
    cur.execute("SELECT * FROM " + table + " WHERE word=%s", (word,))
  File "C:\Users\admin\PycharmProjects\hanapsalita-data\venv\lib\site-packages\mysql\connector\cursor_cext.py", line 269, in execute
    result = self._cnx.cmd_query(stmt, raw=self._raw,
  File "C:\Users\admin\PycharmProjects\hanapsalita-data\venv\lib\site-packages\mysql\connector\connection_cext.py", line 535, in cmd_query
    self._cmysql.query(query,
KeyboardInterrupt

~~~~~~~~~~~~~~~ 2022/07/06 14:37:40 ~~~~~~~~~~~~~~~
Traceback (most recent call last):
  File "C:\Users\admin\PycharmProjects\hanapsalita-data\tagalog-pinoydictionary-scrape.py", line 233, in <module>
    lastRowId = getContent(bs, progressJson, progressJsonFilename, lastRetrievedLetterIndex, letter,
  File "C:\Users\admin\PycharmProjects\hanapsalita-data\tagalog-pinoydictionary-scrape.py", line 129, in getContent
    lastRowID = processWord(word, conn, cur, jsonDatabase, wordsJsonFilename, lastRowID, category,
  File "C:\Users\admin\PycharmProjects\hanapsalita-data\scrapeUtils.py", line 324, in processWord
    lastRowID = pushToDatabases(*variablesToBePushed)
  File "C:\Users\admin\PycharmProjects\hanapsalita-data\scrapeUtils.py", line 280, in pushToDatabases
    lastRowID = pushToMySQL(conn, cur, lastRowId, word, category, verbBaseForm, wordLength, withPunctuations,
  File "C:\Users\admin\PycharmProjects\hanapsalita-data\scrapeUtils.py", line 230, in pushToMySQL
    conn.commit()
  File "C:\Users\admin\PycharmProjects\hanapsalita-data\venv\lib\site-packages\mysql\connector\connection_cext.py", line 425, in commit
    self._cmysql.commit()
KeyboardInterrupt

~~~~~~~~~~~~~~~ 2022/07/06 14:55:11 ~~~~~~~~~~~~~~~
Traceback (most recent call last):
  File "C:\Users\admin\PycharmProjects\hanapsalita-data\cebuano-pinoydictionary-scrape.py", line 207, in <module>
    bs = getPage(url)
  File "C:\Users\admin\PycharmProjects\hanapsalita-data\cebuano-pinoydictionary-scrape.py", line 44, in getPage
    req = requests.get(url)
  File "C:\Users\admin\PycharmProjects\hanapsalita-data\venv\lib\site-packages\requests\api.py", line 73, in get
    return request("get", url, params=params, **kwargs)
  File "C:\Users\admin\PycharmProjects\hanapsalita-data\venv\lib\site-packages\requests\api.py", line 59, in request
    return session.request(method=method, url=url, **kwargs)
  File "C:\Users\admin\PycharmProjects\hanapsalita-data\venv\lib\site-packages\requests\sessions.py", line 587, in request
    resp = self.send(prep, **send_kwargs)
  File "C:\Users\admin\PycharmProjects\hanapsalita-data\venv\lib\site-packages\requests\sessions.py", line 701, in send
    r = adapter.send(request, **kwargs)
  File "C:\Users\admin\PycharmProjects\hanapsalita-data\venv\lib\site-packages\requests\adapters.py", line 489, in send
    resp = conn.urlopen(
  File "C:\Users\admin\PycharmProjects\hanapsalita-data\venv\lib\site-packages\urllib3\connectionpool.py", line 703, in urlopen
    httplib_response = self._make_request(
  File "C:\Users\admin\PycharmProjects\hanapsalita-data\venv\lib\site-packages\urllib3\connectionpool.py", line 449, in _make_request
    six.raise_from(e, None)
  File "<string>", line 3, in raise_from
  File "C:\Users\admin\PycharmProjects\hanapsalita-data\venv\lib\site-packages\urllib3\connectionpool.py", line 444, in _make_request
    httplib_response = conn.getresponse()
  File "C:\Users\admin\AppData\Local\Programs\Python\Python39\lib\http\client.py", line 1347, in getresponse
    response.begin()
  File "C:\Users\admin\AppData\Local\Programs\Python\Python39\lib\http\client.py", line 307, in begin
    version, status, reason = self._read_status()
  File "C:\Users\admin\AppData\Local\Programs\Python\Python39\lib\http\client.py", line 268, in _read_status
    line = str(self.fp.readline(_MAXLINE + 1), "iso-8859-1")
  File "C:\Users\admin\AppData\Local\Programs\Python\Python39\lib\socket.py", line 704, in readinto
    return self._sock.recv_into(b)
  File "C:\Users\admin\AppData\Local\Programs\Python\Python39\lib\ssl.py", line 1241, in recv_into
    return self.read(nbytes, buffer)
  File "C:\Users\admin\AppData\Local\Programs\Python\Python39\lib\ssl.py", line 1099, in read
    return self._sslobj.read(len, buffer)
KeyboardInterrupt

~~~~~~~~~~~~~~~ 2022/07/06 20:16:12 ~~~~~~~~~~~~~~~
Traceback (most recent call last):
  File "C:\Users\admin\PycharmProjects\hanapsalita-data\tagalog-pinoydictionary-scrape.py", line 258, in <module>
    lastRowId = getContent(bs, progressJson, progressJsonFilename, lastRetrievedLetterIndex, letter,
  File "C:\Users\admin\PycharmProjects\hanapsalita-data\tagalog-pinoydictionary-scrape.py", line 137, in getContent
    pushToExceptionWordsTable(conn, cur, word, category, verbBaseForm)
  File "C:\Users\admin\PycharmProjects\hanapsalita-data\scrapeUtils.py", line 271, in pushToExceptionWordsTable
    cur.execute(tagalogExceptionWordsValues, tagalogExceptionWordsSQL)
  File "C:\Users\admin\PycharmProjects\hanapsalita-data\venv\lib\site-packages\mysql\connector\cursor_cext.py", line 257, in execute
    prepared = self._cnx.prepare_for_mysql(params)
  File "C:\Users\admin\PycharmProjects\hanapsalita-data\venv\lib\site-packages\mysql\connector\connection_cext.py", line 698, in prepare_for_mysql
    raise errors.ProgrammingError(
mysql.connector.errors.ProgrammingError: Could not process parameters: str(INSERT INTO tagalog_exception_words (word, category) VALUES (%s, %s)), it must be of type list, tuple or dict

~~~~~~~~~~~~~~~ 2022/07/06 20:28:37 ~~~~~~~~~~~~~~~
Traceback (most recent call last):
  File "C:\Users\admin\PycharmProjects\hanapsalita-data\tagalog-pinoydictionary-scrape.py", line 259, in <module>
    lastRowId = getContent(bs, progressJson, progressJsonFilename, lastRetrievedLetterIndex, letter,
  File "C:\Users\admin\PycharmProjects\hanapsalita-data\tagalog-pinoydictionary-scrape.py", line 165, in getContent
    lastRowID = processWord(conjugation, conn, cur, jsonDatabase, wordsJsonFilename, lastRowID,
  File "C:\Users\admin\PycharmProjects\hanapsalita-data\scrapeUtils.py", line 325, in processWord
    lastRowID = pushToDatabases(*variablesToBePushed)
  File "C:\Users\admin\PycharmProjects\hanapsalita-data\scrapeUtils.py", line 281, in pushToDatabases
    lastRowID = pushToMySQL(conn, cur, lastRowId, word, category, verbBaseForm, wordLength, withPunctuations,
  File "C:\Users\admin\PycharmProjects\hanapsalita-data\scrapeUtils.py", line 230, in pushToMySQL
    conn.commit()
  File "C:\Users\admin\PycharmProjects\hanapsalita-data\venv\lib\site-packages\mysql\connector\connection_cext.py", line 425, in commit
    self._cmysql.commit()
KeyboardInterrupt

~~~~~~~~~~~~~~~ 2022/07/06 20:43:12 ~~~~~~~~~~~~~~~
Traceback (most recent call last):
  File "C:\Users\admin\PycharmProjects\hanapsalita-data\tagalog-pinoydictionary-scrape.py", line 259, in <module>
    lastRowId = getContent(bs, progressJson, progressJsonFilename, lastRetrievedLetterIndex, letter,
  File "C:\Users\admin\PycharmProjects\hanapsalita-data\tagalog-pinoydictionary-scrape.py", line 155, in getContent
    lastRowID = processWord(word, conn, cur, jsonDatabase, wordsJsonFilename, lastRowID, category,
  File "C:\Users\admin\PycharmProjects\hanapsalita-data\scrapeUtils.py", line 325, in processWord
    lastRowID = pushToDatabases(*variablesToBePushed)
  File "C:\Users\admin\PycharmProjects\hanapsalita-data\scrapeUtils.py", line 281, in pushToDatabases
    lastRowID = pushToMySQL(conn, cur, lastRowId, word, category, verbBaseForm, wordLength, withPunctuations,
  File "C:\Users\admin\PycharmProjects\hanapsalita-data\scrapeUtils.py", line 189, in pushToMySQL
    cur.execute(tagalogStartStrictSQL, tagalogStartStrictValues)
  File "C:\Users\admin\PycharmProjects\hanapsalita-data\venv\lib\site-packages\mysql\connector\cursor_cext.py", line 269, in execute
    result = self._cnx.cmd_query(stmt, raw=self._raw,
  File "C:\Users\admin\PycharmProjects\hanapsalita-data\venv\lib\site-packages\mysql\connector\connection_cext.py", line 535, in cmd_query
    self._cmysql.query(query,
KeyboardInterrupt

~~~~~~~~~~~~~~~ 2022/07/06 20:46:58 ~~~~~~~~~~~~~~~
Traceback (most recent call last):
  File "C:\Users\admin\PycharmProjects\hanapsalita-data\tagalog-pinoydictionary-scrape.py", line 260, in <module>
    lastRowId = getContent(bs, progressJson, progressJsonFilename, lastRetrievedLetterIndex, letter,
  File "C:\Users\admin\PycharmProjects\hanapsalita-data\tagalog-pinoydictionary-scrape.py", line 156, in getContent
    lastRowID = processWord(word, conn, cur, jsonDatabase, wordsJsonFilename, lastRowID, category,
  File "C:\Users\admin\PycharmProjects\hanapsalita-data\scrapeUtils.py", line 325, in processWord
    lastRowID = pushToDatabases(*variablesToBePushed)
  File "C:\Users\admin\PycharmProjects\hanapsalita-data\scrapeUtils.py", line 281, in pushToDatabases
    lastRowID = pushToMySQL(conn, cur, lastRowId, word, category, verbBaseForm, wordLength, withPunctuations,
  File "C:\Users\admin\PycharmProjects\hanapsalita-data\scrapeUtils.py", line 229, in pushToMySQL
    cur.execute(tagalogContainStrictSQL, tagalogConstituentsRowValuesStrict)
  File "C:\Users\admin\PycharmProjects\hanapsalita-data\venv\lib\site-packages\mysql\connector\cursor_cext.py", line 269, in execute
    result = self._cnx.cmd_query(stmt, raw=self._raw,
  File "C:\Users\admin\PycharmProjects\hanapsalita-data\venv\lib\site-packages\mysql\connector\connection_cext.py", line 535, in cmd_query
    self._cmysql.query(query,
KeyboardInterrupt

~~~~~~~~~~~~~~~ 2022/07/06 21:17:25 ~~~~~~~~~~~~~~~
Traceback (most recent call last):
  File "C:\Users\admin\PycharmProjects\hanapsalita-data\tagalog-pinoydictionary-scrape.py", line 260, in <module>
    lastRowId = getContent(bs, progressJson, progressJsonFilename, lastRetrievedLetterIndex, letter,
  File "C:\Users\admin\PycharmProjects\hanapsalita-data\tagalog-pinoydictionary-scrape.py", line 156, in getContent
    lastRowID = processWord(word, conn, cur, jsonDatabase, wordsJsonFilename, lastRowID, category,
  File "C:\Users\admin\PycharmProjects\hanapsalita-data\scrapeUtils.py", line 325, in processWord
    lastRowID = pushToDatabases(*variablesToBePushed)
  File "C:\Users\admin\PycharmProjects\hanapsalita-data\scrapeUtils.py", line 281, in pushToDatabases
    lastRowID = pushToMySQL(conn, cur, lastRowId, word, category, verbBaseForm, wordLength, withPunctuations,
  File "C:\Users\admin\PycharmProjects\hanapsalita-data\scrapeUtils.py", line 183, in pushToMySQL
    cur.execute(tagalogStartNotStrictSQL, tagalogStartNotStrictValues)
  File "C:\Users\admin\PycharmProjects\hanapsalita-data\venv\lib\site-packages\mysql\connector\cursor_cext.py", line 269, in execute
    result = self._cnx.cmd_query(stmt, raw=self._raw,
  File "C:\Users\admin\PycharmProjects\hanapsalita-data\venv\lib\site-packages\mysql\connector\connection_cext.py", line 535, in cmd_query
    self._cmysql.query(query,
KeyboardInterrupt

~~~~~~~~~~~~~~~ 2022/07/06 21:18:42 ~~~~~~~~~~~~~~~
Traceback (most recent call last):
  File "C:\Users\admin\PycharmProjects\hanapsalita-data\tagalog-pinoydictionary-scrape.py", line 260, in <module>
    lastRowId = getContent(bs, progressJson, progressJsonFilename, lastRetrievedLetterIndex, letter,
  File "C:\Users\admin\PycharmProjects\hanapsalita-data\tagalog-pinoydictionary-scrape.py", line 156, in getContent
    lastRowID = processWord(word, conn, cur, jsonDatabase, wordsJsonFilename, lastRowID, category,
  File "C:\Users\admin\PycharmProjects\hanapsalita-data\scrapeUtils.py", line 325, in processWord
    lastRowID = pushToDatabases(*variablesToBePushed)
  File "C:\Users\admin\PycharmProjects\hanapsalita-data\scrapeUtils.py", line 281, in pushToDatabases
    lastRowID = pushToMySQL(conn, cur, lastRowId, word, category, verbBaseForm, wordLength, withPunctuations,
  File "C:\Users\admin\PycharmProjects\hanapsalita-data\scrapeUtils.py", line 202, in pushToMySQL
    cur.execute(tagalogEndStrictSQL, tagalogEndStrictValues)
  File "C:\Users\admin\PycharmProjects\hanapsalita-data\venv\lib\site-packages\mysql\connector\cursor_cext.py", line 269, in execute
    result = self._cnx.cmd_query(stmt, raw=self._raw,
  File "C:\Users\admin\PycharmProjects\hanapsalita-data\venv\lib\site-packages\mysql\connector\connection_cext.py", line 535, in cmd_query
    self._cmysql.query(query,
KeyboardInterrupt
